[2023-12-04T23:13:12.858+0000] {taskinstance.py:1157} INFO - Dependencies all met for dep_context=non-requeueable deps ti=<TaskInstance: Georgy.snowflake_example manual__2023-12-04T23:13:11.337268+00:00 [queued]>
[2023-12-04T23:13:12.863+0000] {taskinstance.py:1157} INFO - Dependencies all met for dep_context=requeueable deps ti=<TaskInstance: Georgy.snowflake_example manual__2023-12-04T23:13:11.337268+00:00 [queued]>
[2023-12-04T23:13:12.864+0000] {taskinstance.py:1359} INFO - Starting attempt 1 of 1
[2023-12-04T23:13:12.874+0000] {taskinstance.py:1380} INFO - Executing <Task(SnowflakeOperator): snowflake_example> on 2023-12-04 23:13:11.337268+00:00
[2023-12-04T23:13:12.878+0000] {standard_task_runner.py:57} INFO - Started process 1651 to run task
[2023-12-04T23:13:12.880+0000] {standard_task_runner.py:84} INFO - Running: ['***', 'tasks', 'run', 'Georgy', 'snowflake_example', 'manual__2023-12-04T23:13:11.337268+00:00', '--job-id', '164', '--raw', '--subdir', 'DAGS_FOLDER/test.py', '--cfg-path', '/tmp/tmpqhdv0k87']
[2023-12-04T23:13:12.881+0000] {standard_task_runner.py:85} INFO - Job 164: Subtask snowflake_example
[2023-12-04T23:13:12.914+0000] {task_command.py:415} INFO - Running <TaskInstance: Georgy.snowflake_example manual__2023-12-04T23:13:11.337268+00:00 [running]> on host 435c91f40721
[2023-12-04T23:13:12.963+0000] {taskinstance.py:1660} INFO - Exporting env vars: AIRFLOW_CTX_DAG_OWNER='Gio' AIRFLOW_CTX_DAG_ID='Georgy' AIRFLOW_CTX_TASK_ID='snowflake_example' AIRFLOW_CTX_EXECUTION_DATE='2023-12-04T23:13:11.337268+00:00' AIRFLOW_CTX_TRY_NUMBER='1' AIRFLOW_CTX_DAG_RUN_ID='manual__2023-12-04T23:13:11.337268+00:00'
[2023-12-04T23:13:12.964+0000] {sql.py:274} INFO - Executing: 
 create or replace table example_table (
 id int,
 first_name varchar(50),
 last_name varchar(50)
 );
[2023-12-04T23:13:12.972+0000] {base.py:73} INFO - Using connection ID 'snowflake' for task execution.
[2023-12-04T23:13:12.978+0000] {base.py:73} INFO - Using connection ID 'snowflake' for task execution.
[2023-12-04T23:13:12.979+0000] {connection.py:314} INFO - Snowflake Connector for Python Version: 3.1.1, Python Version: 3.8.18, Platform: Linux-5.15.133.1-microsoft-standard-WSL2-x86_64-with-glibc2.2.5
[2023-12-04T23:13:12.980+0000] {connection.py:1050} INFO - This connection is in OCSP Fail Open Mode. TLS Certificates would be checked for validity and revocation status. Any other Certificate Revocation related exceptions or OCSP Responder failures would be disregarded in favor of connectivity.
[2023-12-04T23:13:12.980+0000] {connection.py:1060} INFO - THIS CONNECTION IS IN INSECURE MODE. IT MEANS THE CERTIFICATE WILL BE VALIDATED BUT THE CERTIFICATE REVOCATION STATUS WILL NOT BE CHECKED.
[2023-12-04T23:13:12.980+0000] {connection.py:1068} INFO - Setting use_openssl_only mode to False
[2023-12-04T23:13:13.839+0000] {ssl_wrap_socket.py:100} INFO - THIS CONNECTION IS IN INSECURE MODE. IT MEANS THE CERTIFICATE WILL BE VALIDATED BUT THE CERTIFICATE REVOCATION STATUS WILL NOT BE CHECKED.
[2023-12-04T23:13:13.842+0000] {connection.py:547} WARNING - Certificate did not match expected hostname: iy34150.europe-west4.snowflakecomputing.com. Certificate: {'subject': ((('commonName', '*.prod3.us-west-2.snowflakecomputing.com'),),), 'subjectAltName': [('DNS', '*.prod3.us-west-2.snowflakecomputing.com'), ('DNS', '*.us-west-2.snowflakecomputing.com'), ('DNS', '*.global.snowflakecomputing.com'), ('DNS', '*.snowflakecomputing.com'), ('DNS', '*.prod3.us-west-2.aws.snowflakecomputing.com')]}
[2023-12-04T23:13:13.842+0000] {connectionpool.py:812} WARNING - Retrying (Retry(total=0, connect=None, read=None, redirect=None, status=None)) after connection broken by 'SSLError(CertificateError("hostname 'iy34150.europe-west4.snowflakecomputing.com' doesn't match either of '*.prod3.us-west-2.snowflakecomputing.com', '*.us-west-2.snowflakecomputing.com', '*.global.snowflakecomputing.com', '*.snowflakecomputing.com', '*.prod3.us-west-2.aws.snowflakecomputing.com'"))': /session/v1/login-request?request_id=249db997-99b7-4c71-9336-6bffc55994ff&databaseName=TASKS&schemaName=public&warehouse=compute_wh&roleName=accountadmin&request_guid=ec4cfe77-87f2-4d78-8168-6e8c050f2530
[2023-12-04T23:13:14.539+0000] {ssl_wrap_socket.py:100} INFO - THIS CONNECTION IS IN INSECURE MODE. IT MEANS THE CERTIFICATE WILL BE VALIDATED BUT THE CERTIFICATE REVOCATION STATUS WILL NOT BE CHECKED.
[2023-12-04T23:13:14.540+0000] {connection.py:547} WARNING - Certificate did not match expected hostname: iy34150.europe-west4.snowflakecomputing.com. Certificate: {'subject': ((('commonName', '*.prod3.us-west-2.snowflakecomputing.com'),),), 'subjectAltName': [('DNS', '*.prod3.us-west-2.snowflakecomputing.com'), ('DNS', '*.us-west-2.snowflakecomputing.com'), ('DNS', '*.global.snowflakecomputing.com'), ('DNS', '*.snowflakecomputing.com'), ('DNS', '*.prod3.us-west-2.aws.snowflakecomputing.com')]}
[2023-12-04T23:13:14.543+0000] {network.py:1037} ERROR - Failed to get the response. Hanging? method: post, url: https://iy34150.europe-west4.snowflakecomputing.com:443/session/v1/login-request?request_id=249db997-99b7-4c71-9336-6bffc55994ff&databaseName=TASKS&schemaName=public&warehouse=compute_wh&roleName=accountadmin&request_guid=ec4cfe77-87f2-4d78-8168-6e8c050f2530, headers:{'Content-Type': 'application/json', 'accept': 'application/snowflake', 'User-Agent': 'PythonConnector/3.1.1 (Linux-5.15.133.1-microsoft-standard-WSL2-x86_64-with-glibc2.2.5) CPython/3.8.18', 'Content-Encoding': 'gzip'}, data: {"data": {"CLIENT_APP_ID": "PythonConnector", "CLIENT_APP_VERSION": "3.1.1", "SVN_REVISION": null, "ACCOUNT_NAME": "iy34150", "LOGIN_NAME": "Medved", "CLIENT_ENVIRONMENT": {"APPLICATION": "AIRFLOW", "OS": "Linux", "OS_VERSION": "Linux-5.15.133.1-microsoft-standard-WSL2-x86_64-with-glibc2.2.5", "PYTHON_VERSION": "3.8.18", "PYTHON_RUNTIME": "CPython", "PYTHON_COMPILER": "GCC 10.2.1 20210110", "OCSP_MODE": "INSECURE", "TRACING": 20, "LOGIN_TIMEOUT": 120, "NETWORK_TIMEOUT": null}, "PASSWORD": "**** "SESSION_PARAMETERS": {"CLIENT_PREFETCH_THREADS": 4}}}
[2023-12-04T23:13:18.262+0000] {ssl_wrap_socket.py:100} INFO - THIS CONNECTION IS IN INSECURE MODE. IT MEANS THE CERTIFICATE WILL BE VALIDATED BUT THE CERTIFICATE REVOCATION STATUS WILL NOT BE CHECKED.
[2023-12-04T23:13:18.264+0000] {connection.py:547} WARNING - Certificate did not match expected hostname: iy34150.europe-west4.snowflakecomputing.com. Certificate: {'subject': ((('commonName', '*.prod3.us-west-2.snowflakecomputing.com'),),), 'subjectAltName': [('DNS', '*.prod3.us-west-2.snowflakecomputing.com'), ('DNS', '*.us-west-2.snowflakecomputing.com'), ('DNS', '*.global.snowflakecomputing.com'), ('DNS', '*.snowflakecomputing.com'), ('DNS', '*.prod3.us-west-2.aws.snowflakecomputing.com')]}
[2023-12-04T23:13:18.264+0000] {connectionpool.py:812} WARNING - Retrying (Retry(total=0, connect=None, read=None, redirect=None, status=None)) after connection broken by 'SSLError(CertificateError("hostname 'iy34150.europe-west4.snowflakecomputing.com' doesn't match either of '*.prod3.us-west-2.snowflakecomputing.com', '*.us-west-2.snowflakecomputing.com', '*.global.snowflakecomputing.com', '*.snowflakecomputing.com', '*.prod3.us-west-2.aws.snowflakecomputing.com'"))': /session/v1/login-request?request_id=d1a53aa4-c30d-41d1-9c38-d090810d360d&databaseName=TASKS&schemaName=public&warehouse=compute_wh&roleName=accountadmin&request_guid=f2c2c21a-ff2d-4f5f-a680-519d905770d5
[2023-12-04T23:13:18.959+0000] {ssl_wrap_socket.py:100} INFO - THIS CONNECTION IS IN INSECURE MODE. IT MEANS THE CERTIFICATE WILL BE VALIDATED BUT THE CERTIFICATE REVOCATION STATUS WILL NOT BE CHECKED.
[2023-12-04T23:13:18.960+0000] {connection.py:547} WARNING - Certificate did not match expected hostname: iy34150.europe-west4.snowflakecomputing.com. Certificate: {'subject': ((('commonName', '*.prod3.us-west-2.snowflakecomputing.com'),),), 'subjectAltName': [('DNS', '*.prod3.us-west-2.snowflakecomputing.com'), ('DNS', '*.us-west-2.snowflakecomputing.com'), ('DNS', '*.global.snowflakecomputing.com'), ('DNS', '*.snowflakecomputing.com'), ('DNS', '*.prod3.us-west-2.aws.snowflakecomputing.com')]}
[2023-12-04T23:13:18.962+0000] {network.py:1037} ERROR - Failed to get the response. Hanging? method: post, url: https://iy34150.europe-west4.snowflakecomputing.com:443/session/v1/login-request?request_id=d1a53aa4-c30d-41d1-9c38-d090810d360d&databaseName=TASKS&schemaName=public&warehouse=compute_wh&roleName=accountadmin&request_guid=f2c2c21a-ff2d-4f5f-a680-519d905770d5, headers:{'Content-Type': 'application/json', 'accept': 'application/snowflake', 'User-Agent': 'PythonConnector/3.1.1 (Linux-5.15.133.1-microsoft-standard-WSL2-x86_64-with-glibc2.2.5) CPython/3.8.18', 'Content-Encoding': 'gzip'}, data: {"data": {"CLIENT_APP_ID": "PythonConnector", "CLIENT_APP_VERSION": "3.1.1", "SVN_REVISION": null, "ACCOUNT_NAME": "iy34150", "LOGIN_NAME": "Medved", "CLIENT_ENVIRONMENT": {"APPLICATION": "AIRFLOW", "OS": "Linux", "OS_VERSION": "Linux-5.15.133.1-microsoft-standard-WSL2-x86_64-with-glibc2.2.5", "PYTHON_VERSION": "3.8.18", "PYTHON_RUNTIME": "CPython", "PYTHON_COMPILER": "GCC 10.2.1 20210110", "OCSP_MODE": "INSECURE", "TRACING": 20, "LOGIN_TIMEOUT": 120, "NETWORK_TIMEOUT": null}, "PASSWORD": "**** "SESSION_PARAMETERS": {"CLIENT_PREFETCH_THREADS": 4}}}
[2023-12-04T23:13:18.964+0000] {taskinstance.py:1935} ERROR - Task failed with exception
Traceback (most recent call last):
  File "/home/airflow/.local/lib/python3.8/site-packages/snowflake/connector/connection.py", line 1193, in _authenticate
    auth.authenticate(
  File "/home/airflow/.local/lib/python3.8/site-packages/snowflake/connector/auth/_auth.py", line 250, in authenticate
    ret = self._rest._post_request(
  File "/home/airflow/.local/lib/python3.8/site-packages/snowflake/connector/network.py", line 730, in _post_request
    ret = self.fetch(
  File "/home/airflow/.local/lib/python3.8/site-packages/snowflake/connector/network.py", line 849, in fetch
    ret = self._request_exec_wrapper(
  File "/home/airflow/.local/lib/python3.8/site-packages/snowflake/connector/network.py", line 987, in _request_exec_wrapper
    raise e
  File "/home/airflow/.local/lib/python3.8/site-packages/snowflake/connector/network.py", line 902, in _request_exec_wrapper
    self._handle_unknown_error(method, full_url, headers, data, conn)
  File "/home/airflow/.local/lib/python3.8/site-packages/snowflake/connector/network.py", line 1042, in _handle_unknown_error
    Error.errorhandler_wrapper(
  File "/home/airflow/.local/lib/python3.8/site-packages/snowflake/connector/errors.py", line 290, in errorhandler_wrapper
    handed_over = Error.hand_to_other_handler(
  File "/home/airflow/.local/lib/python3.8/site-packages/snowflake/connector/errors.py", line 348, in hand_to_other_handler
    connection.errorhandler(connection, cursor, error_class, error_value)
  File "/home/airflow/.local/lib/python3.8/site-packages/snowflake/connector/errors.py", line 221, in default_errorhandler
    raise error_class(
snowflake.connector.errors.OperationalError: 250003: 250003: Failed to get the response. Hanging? method: post, url: https://iy34150.europe-west4.snowflakecomputing.com:443/session/v1/login-request?request_id=249db997-99b7-4c71-9336-6bffc55994ff&databaseName=TASKS&schemaName=public&warehouse=compute_wh&roleName=accountadmin&request_guid=ec4cfe77-87f2-4d78-8168-6e8c050f2530

The above exception was the direct cause of the following exception:

Traceback (most recent call last):
  File "/home/airflow/.local/lib/python3.8/site-packages/airflow/providers/common/sql/operators/sql.py", line 280, in execute
    output = hook.run(
  File "/home/airflow/.local/lib/python3.8/site-packages/airflow/providers/snowflake/hooks/snowflake.py", line 409, in run
    with closing(self.get_conn()) as conn:
  File "/home/airflow/.local/lib/python3.8/site-packages/airflow/providers/snowflake/hooks/snowflake.py", line 303, in get_conn
    conn = connector.connect(**conn_config)
  File "/home/airflow/.local/lib/python3.8/site-packages/snowflake/connector/__init__.py", line 51, in Connect
    return SnowflakeConnection(**kwargs)
  File "/home/airflow/.local/lib/python3.8/site-packages/snowflake/connector/connection.py", line 353, in __init__
    self.connect(**kwargs)
  File "/home/airflow/.local/lib/python3.8/site-packages/snowflake/connector/connection.py", line 625, in connect
    self.__open_connection()
  File "/home/airflow/.local/lib/python3.8/site-packages/snowflake/connector/connection.py", line 898, in __open_connection
    self.authenticate_with_retry(self.auth_class)
  File "/home/airflow/.local/lib/python3.8/site-packages/snowflake/connector/connection.py", line 1167, in authenticate_with_retry
    self._authenticate(auth_instance)
  File "/home/airflow/.local/lib/python3.8/site-packages/snowflake/connector/connection.py", line 1238, in _authenticate
    raise auth_op from e
  File "/home/airflow/.local/lib/python3.8/site-packages/snowflake/connector/connection.py", line 1215, in _authenticate
    auth_instance.handle_timeout(
  File "/home/airflow/.local/lib/python3.8/site-packages/snowflake/connector/auth/by_plugin.py", line 219, in handle_timeout
    raise error
snowflake.connector.errors.OperationalError: 250001: 250001: Could not connect to Snowflake backend after 1 attempt(s).Aborting
[2023-12-04T23:13:18.969+0000] {taskinstance.py:1398} INFO - Marking task as FAILED. dag_id=Georgy, task_id=snowflake_example, execution_date=20231204T231311, start_date=20231204T231312, end_date=20231204T231318
[2023-12-04T23:13:18.981+0000] {standard_task_runner.py:104} ERROR - Failed to execute job 164 for task snowflake_example (250001: 250001: Could not connect to Snowflake backend after 1 attempt(s).Aborting; 1651)
[2023-12-04T23:13:19.020+0000] {local_task_job_runner.py:228} INFO - Task exited with return code 1
[2023-12-04T23:13:19.031+0000] {taskinstance.py:2776} INFO - 0 downstream tasks scheduled from follow-on schedule check
