[2023-11-27T14:36:02.645+0000] {taskinstance.py:1157} INFO - Dependencies all met for dep_context=non-requeueable deps ti=<TaskInstance: Georgy.postgres scheduled__2023-11-25T21:10:00+00:00 [queued]>
[2023-11-27T14:36:02.652+0000] {taskinstance.py:1157} INFO - Dependencies all met for dep_context=requeueable deps ti=<TaskInstance: Georgy.postgres scheduled__2023-11-25T21:10:00+00:00 [queued]>
[2023-11-27T14:36:02.653+0000] {taskinstance.py:1359} INFO - Starting attempt 2 of 4
[2023-11-27T14:36:02.664+0000] {taskinstance.py:1380} INFO - Executing <Task(PythonOperator): postgres> on 2023-11-25 21:10:00+00:00
[2023-11-27T14:36:02.667+0000] {standard_task_runner.py:57} INFO - Started process 1997 to run task
[2023-11-27T14:36:02.670+0000] {standard_task_runner.py:84} INFO - Running: ['***', 'tasks', 'run', 'Georgy', 'postgres', 'scheduled__2023-11-25T21:10:00+00:00', '--job-id', '9', '--raw', '--subdir', 'DAGS_FOLDER/test.py', '--cfg-path', '/tmp/tmpkqaexej7']
[2023-11-27T14:36:02.672+0000] {standard_task_runner.py:85} INFO - Job 9: Subtask postgres
[2023-11-27T14:36:02.705+0000] {task_command.py:415} INFO - Running <TaskInstance: Georgy.postgres scheduled__2023-11-25T21:10:00+00:00 [running]> on host 77fb4e42fc75
[2023-11-27T14:36:02.761+0000] {taskinstance.py:1660} INFO - Exporting env vars: AIRFLOW_CTX_DAG_OWNER='Gio' AIRFLOW_CTX_DAG_ID='Georgy' AIRFLOW_CTX_TASK_ID='postgres' AIRFLOW_CTX_EXECUTION_DATE='2023-11-25T21:10:00+00:00' AIRFLOW_CTX_TRY_NUMBER='2' AIRFLOW_CTX_DAG_RUN_ID='scheduled__2023-11-25T21:10:00+00:00'
[2023-11-27T14:36:02.767+0000] {base.py:73} INFO - Using connection ID 'fofanov' for task execution.
[2023-11-27T14:36:02.768+0000] {taskinstance.py:1935} ERROR - Task failed with exception
Traceback (most recent call last):
  File "/home/airflow/.local/lib/python3.8/site-packages/airflow/operators/python.py", line 192, in execute
    return_value = self.execute_callable()
  File "/home/airflow/.local/lib/python3.8/site-packages/airflow/operators/python.py", line 209, in execute_callable
    return self.python_callable(*self.op_args, **self.op_kwargs)
  File "/opt/airflow/dags/test.py", line 23, in postgres
    conn = hook.get_conn()
  File "/home/airflow/.local/lib/python3.8/site-packages/airflow/providers/postgres/hooks/postgres.py", line 154, in get_conn
    self.conn = psycopg2.connect(**conn_args)
  File "/home/airflow/.local/lib/python3.8/site-packages/psycopg2/__init__.py", line 122, in connect
    conn = _connect(dsn, connection_factory=connection_factory, **kwasync)
psycopg2.OperationalError: connection to server at "127.0.0.1", port 5432 failed: Connection refused
	Is the server running on that host and accepting TCP/IP connections?

[2023-11-27T14:36:02.775+0000] {taskinstance.py:1398} INFO - Marking task as UP_FOR_RETRY. dag_id=Georgy, task_id=postgres, execution_date=20231125T211000, start_date=20231127T143602, end_date=20231127T143602
[2023-11-27T14:36:02.783+0000] {standard_task_runner.py:104} ERROR - Failed to execute job 9 for task postgres (connection to server at "127.0.0.1", port 5432 failed: Connection refused
	Is the server running on that host and accepting TCP/IP connections?
; 1997)
[2023-11-27T14:36:02.802+0000] {local_task_job_runner.py:228} INFO - Task exited with return code 1
[2023-11-27T14:36:02.819+0000] {taskinstance.py:2776} INFO - 0 downstream tasks scheduled from follow-on schedule check
