[2023-12-01T14:00:37.946+0000] {taskinstance.py:1157} INFO - Dependencies all met for dep_context=non-requeueable deps ti=<TaskInstance: Georgy.postgres scheduled__2023-11-25T21:10:00+00:00 [queued]>
[2023-12-01T14:00:37.954+0000] {taskinstance.py:1157} INFO - Dependencies all met for dep_context=requeueable deps ti=<TaskInstance: Georgy.postgres scheduled__2023-11-25T21:10:00+00:00 [queued]>
[2023-12-01T14:00:37.954+0000] {taskinstance.py:1359} INFO - Starting attempt 3 of 4
[2023-12-01T14:00:37.964+0000] {taskinstance.py:1380} INFO - Executing <Task(PythonOperator): postgres> on 2023-11-25 21:10:00+00:00
[2023-12-01T14:00:37.969+0000] {standard_task_runner.py:57} INFO - Started process 57 to run task
[2023-12-01T14:00:37.972+0000] {standard_task_runner.py:84} INFO - Running: ['***', 'tasks', 'run', 'Georgy', 'postgres', 'scheduled__2023-11-25T21:10:00+00:00', '--job-id', '12', '--raw', '--subdir', 'DAGS_FOLDER/test.py', '--cfg-path', '/tmp/tmpuphohbab']
[2023-12-01T14:00:37.974+0000] {standard_task_runner.py:85} INFO - Job 12: Subtask postgres
[2023-12-01T14:00:38.008+0000] {task_command.py:415} INFO - Running <TaskInstance: Georgy.postgres scheduled__2023-11-25T21:10:00+00:00 [running]> on host bbc1b9980561
[2023-12-01T14:00:38.073+0000] {taskinstance.py:1660} INFO - Exporting env vars: AIRFLOW_CTX_DAG_OWNER='Gio' AIRFLOW_CTX_DAG_ID='Georgy' AIRFLOW_CTX_TASK_ID='postgres' AIRFLOW_CTX_EXECUTION_DATE='2023-11-25T21:10:00+00:00' AIRFLOW_CTX_TRY_NUMBER='3' AIRFLOW_CTX_DAG_RUN_ID='scheduled__2023-11-25T21:10:00+00:00'
[2023-12-01T14:00:38.081+0000] {base.py:73} INFO - Using connection ID 'fofanov' for task execution.
[2023-12-01T14:00:38.083+0000] {taskinstance.py:1935} ERROR - Task failed with exception
Traceback (most recent call last):
  File "/home/airflow/.local/lib/python3.8/site-packages/airflow/operators/python.py", line 192, in execute
    return_value = self.execute_callable()
  File "/home/airflow/.local/lib/python3.8/site-packages/airflow/operators/python.py", line 209, in execute_callable
    return self.python_callable(*self.op_args, **self.op_kwargs)
  File "/opt/airflow/dags/test.py", line 23, in postgres
    conn = hook.get_conn()
  File "/home/airflow/.local/lib/python3.8/site-packages/airflow/providers/postgres/hooks/postgres.py", line 154, in get_conn
    self.conn = psycopg2.connect(**conn_args)
  File "/home/airflow/.local/lib/python3.8/site-packages/psycopg2/__init__.py", line 122, in connect
    conn = _connect(dsn, connection_factory=connection_factory, **kwasync)
psycopg2.OperationalError: connection to server at "127.0.0.1", port 5432 failed: Connection refused
	Is the server running on that host and accepting TCP/IP connections?

[2023-12-01T14:00:38.091+0000] {taskinstance.py:1398} INFO - Marking task as UP_FOR_RETRY. dag_id=Georgy, task_id=postgres, execution_date=20231125T211000, start_date=20231201T140037, end_date=20231201T140038
[2023-12-01T14:00:38.103+0000] {standard_task_runner.py:104} ERROR - Failed to execute job 12 for task postgres (connection to server at "127.0.0.1", port 5432 failed: Connection refused
	Is the server running on that host and accepting TCP/IP connections?
; 57)
[2023-12-01T14:00:38.144+0000] {local_task_job_runner.py:228} INFO - Task exited with return code 1
[2023-12-01T14:00:38.162+0000] {taskinstance.py:2776} INFO - 0 downstream tasks scheduled from follow-on schedule check
