[2023-12-04T16:18:27.574+0000] {taskinstance.py:1157} INFO - Dependencies all met for dep_context=non-requeueable deps ti=<TaskInstance: Georgy.query1 scheduled__2023-11-30T21:10:00+00:00 [queued]>
[2023-12-04T16:18:27.582+0000] {taskinstance.py:1157} INFO - Dependencies all met for dep_context=requeueable deps ti=<TaskInstance: Georgy.query1 scheduled__2023-11-30T21:10:00+00:00 [queued]>
[2023-12-04T16:18:27.582+0000] {taskinstance.py:1359} INFO - Starting attempt 1 of 4
[2023-12-04T16:18:27.592+0000] {taskinstance.py:1380} INFO - Executing <Task(SQLExecuteQueryOperator): query1> on 2023-11-30 21:10:00+00:00
[2023-12-04T16:18:27.597+0000] {standard_task_runner.py:57} INFO - Started process 448 to run task
[2023-12-04T16:18:27.600+0000] {standard_task_runner.py:84} INFO - Running: ['***', 'tasks', 'run', 'Georgy', 'query1', 'scheduled__2023-11-30T21:10:00+00:00', '--job-id', '106', '--raw', '--subdir', 'DAGS_FOLDER/test.py', '--cfg-path', '/tmp/tmps_rcghud']
[2023-12-04T16:18:27.601+0000] {standard_task_runner.py:85} INFO - Job 106: Subtask query1
[2023-12-04T16:18:27.636+0000] {task_command.py:415} INFO - Running <TaskInstance: Georgy.query1 scheduled__2023-11-30T21:10:00+00:00 [running]> on host 435c91f40721
[2023-12-04T16:18:27.691+0000] {taskinstance.py:1660} INFO - Exporting env vars: AIRFLOW_CTX_DAG_OWNER='Gio' AIRFLOW_CTX_DAG_ID='Georgy' AIRFLOW_CTX_TASK_ID='query1' AIRFLOW_CTX_EXECUTION_DATE='2023-11-30T21:10:00+00:00' AIRFLOW_CTX_TRY_NUMBER='1' AIRFLOW_CTX_DAG_RUN_ID='scheduled__2023-11-30T21:10:00+00:00'
[2023-12-04T16:18:27.692+0000] {sql.py:274} INFO - Executing: CREATE TABLE test (col INT);
[2023-12-04T16:18:27.700+0000] {base.py:73} INFO - Using connection ID 'snowflake_default' for task execution.
[2023-12-04T16:18:27.713+0000] {base.py:73} INFO - Using connection ID 'snowflake_default' for task execution.
[2023-12-04T16:18:27.714+0000] {connection.py:314} INFO - Snowflake Connector for Python Version: 3.1.1, Python Version: 3.8.18, Platform: Linux-5.15.133.1-microsoft-standard-WSL2-x86_64-with-glibc2.2.5
[2023-12-04T16:18:27.715+0000] {connection.py:1050} INFO - This connection is in OCSP Fail Open Mode. TLS Certificates would be checked for validity and revocation status. Any other Certificate Revocation related exceptions or OCSP Responder failures would be disregarded in favor of connectivity.
[2023-12-04T16:18:27.715+0000] {connection.py:1068} INFO - Setting use_openssl_only mode to False
[2023-12-04T16:18:35.722+0000] {connectionpool.py:812} WARNING - Retrying (Retry(total=0, connect=None, read=None, redirect=None, status=None)) after connection broken by 'NewConnectionError('<snowflake.connector.vendored.urllib3.connection.HTTPSConnection object at 0x7f41680ae670>: Failed to establish a new connection: [Errno -3] Temporary failure in name resolution')': //iy34150.europe-west4.snowflakecomputing.com:443/session/v1/login-request?request_id=c79958d4-2c37-4d8a-b87d-8d66627fb985&databaseName=TASKS&schemaName=PUBLIC&warehouse=COMPUTE_WH&roleName=ACCOUNTADMIN
[2023-12-04T16:18:54.739+0000] {connectionpool.py:812} WARNING - Retrying (Retry(total=0, connect=None, read=None, redirect=None, status=None)) after connection broken by 'NewConnectionError('<snowflake.connector.vendored.urllib3.connection.HTTPSConnection object at 0x7f416805f400>: Failed to establish a new connection: [Errno -3] Temporary failure in name resolution')': //iy34150.europe-west4.snowflakecomputing.com:443/session/v1/login-request?request_id=77873427-8a65-4d33-97fc-33686bed1021&databaseName=TASKS&schemaName=PUBLIC&warehouse=COMPUTE_WH&roleName=ACCOUNTADMIN
[2023-12-04T16:19:02.743+0000] {taskinstance.py:1935} ERROR - Task failed with exception
Traceback (most recent call last):
  File "/home/airflow/.local/lib/python3.8/site-packages/snowflake/connector/vendored/urllib3/connection.py", line 174, in _new_conn
    conn = connection.create_connection(
  File "/home/airflow/.local/lib/python3.8/site-packages/snowflake/connector/vendored/urllib3/util/connection.py", line 72, in create_connection
    for res in socket.getaddrinfo(host, port, family, socket.SOCK_STREAM):
  File "/usr/local/lib/python3.8/socket.py", line 918, in getaddrinfo
    for res in _socket.getaddrinfo(host, port, family, type, proto, flags):
socket.gaierror: [Errno -3] Temporary failure in name resolution

During handling of the above exception, another exception occurred:

Traceback (most recent call last):
  File "/home/airflow/.local/lib/python3.8/site-packages/snowflake/connector/vendored/urllib3/connectionpool.py", line 703, in urlopen
    httplib_response = self._make_request(
  File "/home/airflow/.local/lib/python3.8/site-packages/snowflake/connector/vendored/urllib3/connectionpool.py", line 386, in _make_request
    self._validate_conn(conn)
  File "/home/airflow/.local/lib/python3.8/site-packages/snowflake/connector/vendored/urllib3/connectionpool.py", line 1042, in _validate_conn
    conn.connect()
  File "/home/airflow/.local/lib/python3.8/site-packages/snowflake/connector/vendored/urllib3/connection.py", line 363, in connect
    self.sock = conn = self._new_conn()
  File "/home/airflow/.local/lib/python3.8/site-packages/snowflake/connector/vendored/urllib3/connection.py", line 186, in _new_conn
    raise NewConnectionError(
snowflake.connector.vendored.urllib3.exceptions.NewConnectionError: <snowflake.connector.vendored.urllib3.connection.HTTPSConnection object at 0x7f41680ae760>: Failed to establish a new connection: [Errno -3] Temporary failure in name resolution

During handling of the above exception, another exception occurred:

Traceback (most recent call last):
  File "/home/airflow/.local/lib/python3.8/site-packages/snowflake/connector/vendored/requests/adapters.py", line 487, in send
    resp = conn.urlopen(
  File "/home/airflow/.local/lib/python3.8/site-packages/snowflake/connector/vendored/urllib3/connectionpool.py", line 815, in urlopen
    return self.urlopen(
  File "/home/airflow/.local/lib/python3.8/site-packages/snowflake/connector/vendored/urllib3/connectionpool.py", line 787, in urlopen
    retries = retries.increment(
  File "/home/airflow/.local/lib/python3.8/site-packages/snowflake/connector/vendored/urllib3/util/retry.py", line 592, in increment
    raise MaxRetryError(_pool, url, error or ResponseError(cause))
snowflake.connector.vendored.urllib3.exceptions.MaxRetryError: HTTPSConnectionPool(host='https', port=443): Max retries exceeded with url: //iy34150.europe-west4.snowflakecomputing.com:443/session/v1/login-request?request_id=c79958d4-2c37-4d8a-b87d-8d66627fb985&databaseName=TASKS&schemaName=PUBLIC&warehouse=COMPUTE_WH&roleName=ACCOUNTADMIN (Caused by NewConnectionError('<snowflake.connector.vendored.urllib3.connection.HTTPSConnection object at 0x7f41680ae760>: Failed to establish a new connection: [Errno -3] Temporary failure in name resolution'))

During handling of the above exception, another exception occurred:

Traceback (most recent call last):
  File "/home/airflow/.local/lib/python3.8/site-packages/snowflake/connector/network.py", line 1084, in _request_exec
    raw_ret = session.request(
  File "/home/airflow/.local/lib/python3.8/site-packages/snowflake/connector/vendored/requests/sessions.py", line 587, in request
    resp = self.send(prep, **send_kwargs)
  File "/home/airflow/.local/lib/python3.8/site-packages/snowflake/connector/vendored/requests/sessions.py", line 701, in send
    r = adapter.send(request, **kwargs)
  File "/home/airflow/.local/lib/python3.8/site-packages/snowflake/connector/vendored/requests/adapters.py", line 520, in send
    raise ConnectionError(e, request=request)
snowflake.connector.vendored.requests.exceptions.ConnectionError: HTTPSConnectionPool(host='https', port=443): Max retries exceeded with url: //iy34150.europe-west4.snowflakecomputing.com:443/session/v1/login-request?request_id=c79958d4-2c37-4d8a-b87d-8d66627fb985&databaseName=TASKS&schemaName=PUBLIC&warehouse=COMPUTE_WH&roleName=ACCOUNTADMIN (Caused by NewConnectionError('<snowflake.connector.vendored.urllib3.connection.HTTPSConnection object at 0x7f41680ae760>: Failed to establish a new connection: [Errno -3] Temporary failure in name resolution'))

During handling of the above exception, another exception occurred:

Traceback (most recent call last):
  File "/home/airflow/.local/lib/python3.8/site-packages/snowflake/connector/connection.py", line 1193, in _authenticate
    auth.authenticate(
  File "/home/airflow/.local/lib/python3.8/site-packages/snowflake/connector/auth/_auth.py", line 250, in authenticate
    ret = self._rest._post_request(
  File "/home/airflow/.local/lib/python3.8/site-packages/snowflake/connector/network.py", line 730, in _post_request
    ret = self.fetch(
  File "/home/airflow/.local/lib/python3.8/site-packages/snowflake/connector/network.py", line 849, in fetch
    ret = self._request_exec_wrapper(
  File "/home/airflow/.local/lib/python3.8/site-packages/snowflake/connector/network.py", line 987, in _request_exec_wrapper
    raise e
  File "/home/airflow/.local/lib/python3.8/site-packages/snowflake/connector/network.py", line 891, in _request_exec_wrapper
    return_object = self._request_exec(
  File "/home/airflow/.local/lib/python3.8/site-packages/snowflake/connector/network.py", line 1168, in _request_exec
    raise OperationalError(
snowflake.connector.errors.OperationalError: 251011: 251011: ConnectionTimeout occurred. Will be handled by authenticator

The above exception was the direct cause of the following exception:

Traceback (most recent call last):
  File "/home/airflow/.local/lib/python3.8/site-packages/airflow/providers/common/sql/operators/sql.py", line 280, in execute
    output = hook.run(
  File "/home/airflow/.local/lib/python3.8/site-packages/airflow/providers/snowflake/hooks/snowflake.py", line 409, in run
    with closing(self.get_conn()) as conn:
  File "/home/airflow/.local/lib/python3.8/site-packages/airflow/providers/snowflake/hooks/snowflake.py", line 303, in get_conn
    conn = connector.connect(**conn_config)
  File "/home/airflow/.local/lib/python3.8/site-packages/snowflake/connector/__init__.py", line 51, in Connect
    return SnowflakeConnection(**kwargs)
  File "/home/airflow/.local/lib/python3.8/site-packages/snowflake/connector/connection.py", line 353, in __init__
    self.connect(**kwargs)
  File "/home/airflow/.local/lib/python3.8/site-packages/snowflake/connector/connection.py", line 625, in connect
    self.__open_connection()
  File "/home/airflow/.local/lib/python3.8/site-packages/snowflake/connector/connection.py", line 898, in __open_connection
    self.authenticate_with_retry(self.auth_class)
  File "/home/airflow/.local/lib/python3.8/site-packages/snowflake/connector/connection.py", line 1167, in authenticate_with_retry
    self._authenticate(auth_instance)
  File "/home/airflow/.local/lib/python3.8/site-packages/snowflake/connector/connection.py", line 1238, in _authenticate
    raise auth_op from e
  File "/home/airflow/.local/lib/python3.8/site-packages/snowflake/connector/connection.py", line 1215, in _authenticate
    auth_instance.handle_timeout(
  File "/home/airflow/.local/lib/python3.8/site-packages/snowflake/connector/auth/by_plugin.py", line 219, in handle_timeout
    raise error
snowflake.connector.errors.OperationalError: 250001: 250001: Could not connect to Snowflake backend after 1 attempt(s).Aborting
[2023-12-04T16:19:02.751+0000] {taskinstance.py:1398} INFO - Marking task as UP_FOR_RETRY. dag_id=Georgy, task_id=query1, execution_date=20231130T211000, start_date=20231204T161827, end_date=20231204T161902
[2023-12-04T16:19:02.762+0000] {standard_task_runner.py:104} ERROR - Failed to execute job 106 for task query1 (250001: 250001: Could not connect to Snowflake backend after 1 attempt(s).Aborting; 448)
[2023-12-04T16:19:02.791+0000] {local_task_job_runner.py:228} INFO - Task exited with return code 1
[2023-12-04T16:19:02.813+0000] {taskinstance.py:2776} INFO - 0 downstream tasks scheduled from follow-on schedule check
[2023-12-04T16:35:08.045+0000] {taskinstance.py:1157} INFO - Dependencies all met for dep_context=non-requeueable deps ti=<TaskInstance: Georgy.query1 scheduled__2023-11-30T21:10:00+00:00 [queued]>
[2023-12-04T16:35:08.051+0000] {taskinstance.py:1157} INFO - Dependencies all met for dep_context=requeueable deps ti=<TaskInstance: Georgy.query1 scheduled__2023-11-30T21:10:00+00:00 [queued]>
[2023-12-04T16:35:08.051+0000] {taskinstance.py:1359} INFO - Starting attempt 1 of 4
[2023-12-04T16:35:08.063+0000] {taskinstance.py:1380} INFO - Executing <Task(SnowflakeOperator): query1> on 2023-11-30 21:10:00+00:00
[2023-12-04T16:35:08.067+0000] {standard_task_runner.py:57} INFO - Started process 711 to run task
[2023-12-04T16:35:08.071+0000] {standard_task_runner.py:84} INFO - Running: ['***', 'tasks', 'run', 'Georgy', 'query1', 'scheduled__2023-11-30T21:10:00+00:00', '--job-id', '107', '--raw', '--subdir', 'DAGS_FOLDER/test.py', '--cfg-path', '/tmp/tmp7cieyfb_']
[2023-12-04T16:35:08.072+0000] {standard_task_runner.py:85} INFO - Job 107: Subtask query1
[2023-12-04T16:35:08.110+0000] {task_command.py:415} INFO - Running <TaskInstance: Georgy.query1 scheduled__2023-11-30T21:10:00+00:00 [running]> on host 435c91f40721
[2023-12-04T16:35:08.165+0000] {taskinstance.py:1660} INFO - Exporting env vars: AIRFLOW_CTX_DAG_OWNER='Gio' AIRFLOW_CTX_DAG_ID='Georgy' AIRFLOW_CTX_TASK_ID='query1' AIRFLOW_CTX_EXECUTION_DATE='2023-11-30T21:10:00+00:00' AIRFLOW_CTX_TRY_NUMBER='1' AIRFLOW_CTX_DAG_RUN_ID='scheduled__2023-11-30T21:10:00+00:00'
[2023-12-04T16:35:08.166+0000] {sql.py:274} INFO - Executing: CREATE TABLE test (col INT);
[2023-12-04T16:35:08.176+0000] {base.py:73} INFO - Using connection ID 'snowflake_default' for task execution.
[2023-12-04T16:35:08.182+0000] {base.py:73} INFO - Using connection ID 'snowflake_default' for task execution.
[2023-12-04T16:35:08.183+0000] {connection.py:314} INFO - Snowflake Connector for Python Version: 3.1.1, Python Version: 3.8.18, Platform: Linux-5.15.133.1-microsoft-standard-WSL2-x86_64-with-glibc2.2.5
[2023-12-04T16:35:08.183+0000] {connection.py:1050} INFO - This connection is in OCSP Fail Open Mode. TLS Certificates would be checked for validity and revocation status. Any other Certificate Revocation related exceptions or OCSP Responder failures would be disregarded in favor of connectivity.
[2023-12-04T16:35:08.184+0000] {connection.py:1068} INFO - Setting use_openssl_only mode to False
[2023-12-04T16:35:16.191+0000] {connectionpool.py:812} WARNING - Retrying (Retry(total=0, connect=None, read=None, redirect=None, status=None)) after connection broken by 'NewConnectionError('<snowflake.connector.vendored.urllib3.connection.HTTPSConnection object at 0x7f4168046c40>: Failed to establish a new connection: [Errno -3] Temporary failure in name resolution')': //iy34150.europe-west4.snowflakecomputing.com:443/session/v1/login-request?request_id=ae423188-dcf6-4a37-a274-091c0e0b7216&databaseName=TASKS&schemaName=PUBLIC&warehouse=COMPUTE_WH&roleName=ACCOUNTADMIN
[2023-12-04T16:35:35.205+0000] {connectionpool.py:812} WARNING - Retrying (Retry(total=0, connect=None, read=None, redirect=None, status=None)) after connection broken by 'NewConnectionError('<snowflake.connector.vendored.urllib3.connection.HTTPSConnection object at 0x7f4168067a00>: Failed to establish a new connection: [Errno -3] Temporary failure in name resolution')': //iy34150.europe-west4.snowflakecomputing.com:443/session/v1/login-request?request_id=65cb2e57-c524-4a85-94c0-1e093a4b8259&databaseName=TASKS&schemaName=PUBLIC&warehouse=COMPUTE_WH&roleName=ACCOUNTADMIN
[2023-12-04T16:35:43.213+0000] {taskinstance.py:1935} ERROR - Task failed with exception
Traceback (most recent call last):
  File "/home/airflow/.local/lib/python3.8/site-packages/snowflake/connector/vendored/urllib3/connection.py", line 174, in _new_conn
    conn = connection.create_connection(
  File "/home/airflow/.local/lib/python3.8/site-packages/snowflake/connector/vendored/urllib3/util/connection.py", line 72, in create_connection
    for res in socket.getaddrinfo(host, port, family, socket.SOCK_STREAM):
  File "/usr/local/lib/python3.8/socket.py", line 918, in getaddrinfo
    for res in _socket.getaddrinfo(host, port, family, type, proto, flags):
socket.gaierror: [Errno -3] Temporary failure in name resolution

During handling of the above exception, another exception occurred:

Traceback (most recent call last):
  File "/home/airflow/.local/lib/python3.8/site-packages/snowflake/connector/vendored/urllib3/connectionpool.py", line 703, in urlopen
    httplib_response = self._make_request(
  File "/home/airflow/.local/lib/python3.8/site-packages/snowflake/connector/vendored/urllib3/connectionpool.py", line 386, in _make_request
    self._validate_conn(conn)
  File "/home/airflow/.local/lib/python3.8/site-packages/snowflake/connector/vendored/urllib3/connectionpool.py", line 1042, in _validate_conn
    conn.connect()
  File "/home/airflow/.local/lib/python3.8/site-packages/snowflake/connector/vendored/urllib3/connection.py", line 363, in connect
    self.sock = conn = self._new_conn()
  File "/home/airflow/.local/lib/python3.8/site-packages/snowflake/connector/vendored/urllib3/connection.py", line 186, in _new_conn
    raise NewConnectionError(
snowflake.connector.vendored.urllib3.exceptions.NewConnectionError: <snowflake.connector.vendored.urllib3.connection.HTTPSConnection object at 0x7f4168046d30>: Failed to establish a new connection: [Errno -3] Temporary failure in name resolution

During handling of the above exception, another exception occurred:

Traceback (most recent call last):
  File "/home/airflow/.local/lib/python3.8/site-packages/snowflake/connector/vendored/requests/adapters.py", line 487, in send
    resp = conn.urlopen(
  File "/home/airflow/.local/lib/python3.8/site-packages/snowflake/connector/vendored/urllib3/connectionpool.py", line 815, in urlopen
    return self.urlopen(
  File "/home/airflow/.local/lib/python3.8/site-packages/snowflake/connector/vendored/urllib3/connectionpool.py", line 787, in urlopen
    retries = retries.increment(
  File "/home/airflow/.local/lib/python3.8/site-packages/snowflake/connector/vendored/urllib3/util/retry.py", line 592, in increment
    raise MaxRetryError(_pool, url, error or ResponseError(cause))
snowflake.connector.vendored.urllib3.exceptions.MaxRetryError: HTTPSConnectionPool(host='https', port=443): Max retries exceeded with url: //iy34150.europe-west4.snowflakecomputing.com:443/session/v1/login-request?request_id=ae423188-dcf6-4a37-a274-091c0e0b7216&databaseName=TASKS&schemaName=PUBLIC&warehouse=COMPUTE_WH&roleName=ACCOUNTADMIN (Caused by NewConnectionError('<snowflake.connector.vendored.urllib3.connection.HTTPSConnection object at 0x7f4168046d30>: Failed to establish a new connection: [Errno -3] Temporary failure in name resolution'))

During handling of the above exception, another exception occurred:

Traceback (most recent call last):
  File "/home/airflow/.local/lib/python3.8/site-packages/snowflake/connector/network.py", line 1084, in _request_exec
    raw_ret = session.request(
  File "/home/airflow/.local/lib/python3.8/site-packages/snowflake/connector/vendored/requests/sessions.py", line 587, in request
    resp = self.send(prep, **send_kwargs)
  File "/home/airflow/.local/lib/python3.8/site-packages/snowflake/connector/vendored/requests/sessions.py", line 701, in send
    r = adapter.send(request, **kwargs)
  File "/home/airflow/.local/lib/python3.8/site-packages/snowflake/connector/vendored/requests/adapters.py", line 520, in send
    raise ConnectionError(e, request=request)
snowflake.connector.vendored.requests.exceptions.ConnectionError: HTTPSConnectionPool(host='https', port=443): Max retries exceeded with url: //iy34150.europe-west4.snowflakecomputing.com:443/session/v1/login-request?request_id=ae423188-dcf6-4a37-a274-091c0e0b7216&databaseName=TASKS&schemaName=PUBLIC&warehouse=COMPUTE_WH&roleName=ACCOUNTADMIN (Caused by NewConnectionError('<snowflake.connector.vendored.urllib3.connection.HTTPSConnection object at 0x7f4168046d30>: Failed to establish a new connection: [Errno -3] Temporary failure in name resolution'))

During handling of the above exception, another exception occurred:

Traceback (most recent call last):
  File "/home/airflow/.local/lib/python3.8/site-packages/snowflake/connector/connection.py", line 1193, in _authenticate
    auth.authenticate(
  File "/home/airflow/.local/lib/python3.8/site-packages/snowflake/connector/auth/_auth.py", line 250, in authenticate
    ret = self._rest._post_request(
  File "/home/airflow/.local/lib/python3.8/site-packages/snowflake/connector/network.py", line 730, in _post_request
    ret = self.fetch(
  File "/home/airflow/.local/lib/python3.8/site-packages/snowflake/connector/network.py", line 849, in fetch
    ret = self._request_exec_wrapper(
  File "/home/airflow/.local/lib/python3.8/site-packages/snowflake/connector/network.py", line 987, in _request_exec_wrapper
    raise e
  File "/home/airflow/.local/lib/python3.8/site-packages/snowflake/connector/network.py", line 891, in _request_exec_wrapper
    return_object = self._request_exec(
  File "/home/airflow/.local/lib/python3.8/site-packages/snowflake/connector/network.py", line 1168, in _request_exec
    raise OperationalError(
snowflake.connector.errors.OperationalError: 251011: 251011: ConnectionTimeout occurred. Will be handled by authenticator

The above exception was the direct cause of the following exception:

Traceback (most recent call last):
  File "/home/airflow/.local/lib/python3.8/site-packages/airflow/providers/common/sql/operators/sql.py", line 280, in execute
    output = hook.run(
  File "/home/airflow/.local/lib/python3.8/site-packages/airflow/providers/snowflake/hooks/snowflake.py", line 409, in run
    with closing(self.get_conn()) as conn:
  File "/home/airflow/.local/lib/python3.8/site-packages/airflow/providers/snowflake/hooks/snowflake.py", line 303, in get_conn
    conn = connector.connect(**conn_config)
  File "/home/airflow/.local/lib/python3.8/site-packages/snowflake/connector/__init__.py", line 51, in Connect
    return SnowflakeConnection(**kwargs)
  File "/home/airflow/.local/lib/python3.8/site-packages/snowflake/connector/connection.py", line 353, in __init__
    self.connect(**kwargs)
  File "/home/airflow/.local/lib/python3.8/site-packages/snowflake/connector/connection.py", line 625, in connect
    self.__open_connection()
  File "/home/airflow/.local/lib/python3.8/site-packages/snowflake/connector/connection.py", line 898, in __open_connection
    self.authenticate_with_retry(self.auth_class)
  File "/home/airflow/.local/lib/python3.8/site-packages/snowflake/connector/connection.py", line 1167, in authenticate_with_retry
    self._authenticate(auth_instance)
  File "/home/airflow/.local/lib/python3.8/site-packages/snowflake/connector/connection.py", line 1238, in _authenticate
    raise auth_op from e
  File "/home/airflow/.local/lib/python3.8/site-packages/snowflake/connector/connection.py", line 1215, in _authenticate
    auth_instance.handle_timeout(
  File "/home/airflow/.local/lib/python3.8/site-packages/snowflake/connector/auth/by_plugin.py", line 219, in handle_timeout
    raise error
snowflake.connector.errors.OperationalError: 250001: 250001: Could not connect to Snowflake backend after 1 attempt(s).Aborting
[2023-12-04T16:35:43.221+0000] {taskinstance.py:1398} INFO - Marking task as UP_FOR_RETRY. dag_id=Georgy, task_id=query1, execution_date=20231130T211000, start_date=20231204T163508, end_date=20231204T163543
[2023-12-04T16:35:43.231+0000] {standard_task_runner.py:104} ERROR - Failed to execute job 107 for task query1 (250001: 250001: Could not connect to Snowflake backend after 1 attempt(s).Aborting; 711)
[2023-12-04T16:35:43.271+0000] {local_task_job_runner.py:228} INFO - Task exited with return code 1
[2023-12-04T16:35:43.288+0000] {taskinstance.py:2776} INFO - 0 downstream tasks scheduled from follow-on schedule check
[2023-12-04T16:40:12.422+0000] {taskinstance.py:1157} INFO - Dependencies all met for dep_context=non-requeueable deps ti=<TaskInstance: Georgy.query1 scheduled__2023-11-30T21:10:00+00:00 [queued]>
[2023-12-04T16:40:12.427+0000] {taskinstance.py:1157} INFO - Dependencies all met for dep_context=requeueable deps ti=<TaskInstance: Georgy.query1 scheduled__2023-11-30T21:10:00+00:00 [queued]>
[2023-12-04T16:40:12.428+0000] {taskinstance.py:1359} INFO - Starting attempt 1 of 4
[2023-12-04T16:40:12.439+0000] {taskinstance.py:1380} INFO - Executing <Task(SnowflakeOperator): query1> on 2023-11-30 21:10:00+00:00
[2023-12-04T16:40:12.443+0000] {standard_task_runner.py:57} INFO - Started process 795 to run task
[2023-12-04T16:40:12.446+0000] {standard_task_runner.py:84} INFO - Running: ['***', 'tasks', 'run', 'Georgy', 'query1', 'scheduled__2023-11-30T21:10:00+00:00', '--job-id', '108', '--raw', '--subdir', 'DAGS_FOLDER/test.py', '--cfg-path', '/tmp/tmpk3emnfmn']
[2023-12-04T16:40:12.447+0000] {standard_task_runner.py:85} INFO - Job 108: Subtask query1
[2023-12-04T16:40:12.482+0000] {task_command.py:415} INFO - Running <TaskInstance: Georgy.query1 scheduled__2023-11-30T21:10:00+00:00 [running]> on host 435c91f40721
[2023-12-04T16:40:12.535+0000] {taskinstance.py:1660} INFO - Exporting env vars: AIRFLOW_CTX_DAG_OWNER='Gio' AIRFLOW_CTX_DAG_ID='Georgy' AIRFLOW_CTX_TASK_ID='query1' AIRFLOW_CTX_EXECUTION_DATE='2023-11-30T21:10:00+00:00' AIRFLOW_CTX_TRY_NUMBER='1' AIRFLOW_CTX_DAG_RUN_ID='scheduled__2023-11-30T21:10:00+00:00'
[2023-12-04T16:40:12.536+0000] {sql.py:274} INFO - Executing: CREATE TABLE test (col INT);
[2023-12-04T16:40:12.544+0000] {base.py:73} INFO - Using connection ID 'snowflake_default' for task execution.
[2023-12-04T16:40:12.551+0000] {base.py:73} INFO - Using connection ID 'snowflake_default' for task execution.
[2023-12-04T16:40:12.551+0000] {connection.py:314} INFO - Snowflake Connector for Python Version: 3.1.1, Python Version: 3.8.18, Platform: Linux-5.15.133.1-microsoft-standard-WSL2-x86_64-with-glibc2.2.5
[2023-12-04T16:40:12.552+0000] {connection.py:1050} INFO - This connection is in OCSP Fail Open Mode. TLS Certificates would be checked for validity and revocation status. Any other Certificate Revocation related exceptions or OCSP Responder failures would be disregarded in favor of connectivity.
[2023-12-04T16:40:12.552+0000] {connection.py:1068} INFO - Setting use_openssl_only mode to False
[2023-12-04T16:40:20.559+0000] {connectionpool.py:812} WARNING - Retrying (Retry(total=0, connect=None, read=None, redirect=None, status=None)) after connection broken by 'NewConnectionError('<snowflake.connector.vendored.urllib3.connection.HTTPSConnection object at 0x7f4168085b50>: Failed to establish a new connection: [Errno -3] Temporary failure in name resolution')': //iy34150.europe-west4.snowflakecomputing.com:443/session/v1/login-request?request_id=e5adfc74-3764-405d-a00e-1cc8a806bafb&databaseName=TASKS&schemaName=PUBLIC&warehouse=COMPUTE_WH&roleName=ACCOUNTADMIN
[2023-12-04T16:40:39.575+0000] {connectionpool.py:812} WARNING - Retrying (Retry(total=0, connect=None, read=None, redirect=None, status=None)) after connection broken by 'NewConnectionError('<snowflake.connector.vendored.urllib3.connection.HTTPSConnection object at 0x7f41680a8910>: Failed to establish a new connection: [Errno -3] Temporary failure in name resolution')': //iy34150.europe-west4.snowflakecomputing.com:443/session/v1/login-request?request_id=c1e4109c-36ba-48d0-be8b-bcda0a484d4f&databaseName=TASKS&schemaName=PUBLIC&warehouse=COMPUTE_WH&roleName=ACCOUNTADMIN
[2023-12-04T16:40:47.581+0000] {taskinstance.py:1935} ERROR - Task failed with exception
Traceback (most recent call last):
  File "/home/airflow/.local/lib/python3.8/site-packages/snowflake/connector/vendored/urllib3/connection.py", line 174, in _new_conn
    conn = connection.create_connection(
  File "/home/airflow/.local/lib/python3.8/site-packages/snowflake/connector/vendored/urllib3/util/connection.py", line 72, in create_connection
    for res in socket.getaddrinfo(host, port, family, socket.SOCK_STREAM):
  File "/usr/local/lib/python3.8/socket.py", line 918, in getaddrinfo
    for res in _socket.getaddrinfo(host, port, family, type, proto, flags):
socket.gaierror: [Errno -3] Temporary failure in name resolution

During handling of the above exception, another exception occurred:

Traceback (most recent call last):
  File "/home/airflow/.local/lib/python3.8/site-packages/snowflake/connector/vendored/urllib3/connectionpool.py", line 703, in urlopen
    httplib_response = self._make_request(
  File "/home/airflow/.local/lib/python3.8/site-packages/snowflake/connector/vendored/urllib3/connectionpool.py", line 386, in _make_request
    self._validate_conn(conn)
  File "/home/airflow/.local/lib/python3.8/site-packages/snowflake/connector/vendored/urllib3/connectionpool.py", line 1042, in _validate_conn
    conn.connect()
  File "/home/airflow/.local/lib/python3.8/site-packages/snowflake/connector/vendored/urllib3/connection.py", line 363, in connect
    self.sock = conn = self._new_conn()
  File "/home/airflow/.local/lib/python3.8/site-packages/snowflake/connector/vendored/urllib3/connection.py", line 186, in _new_conn
    raise NewConnectionError(
snowflake.connector.vendored.urllib3.exceptions.NewConnectionError: <snowflake.connector.vendored.urllib3.connection.HTTPSConnection object at 0x7f4168085c40>: Failed to establish a new connection: [Errno -3] Temporary failure in name resolution

During handling of the above exception, another exception occurred:

Traceback (most recent call last):
  File "/home/airflow/.local/lib/python3.8/site-packages/snowflake/connector/vendored/requests/adapters.py", line 487, in send
    resp = conn.urlopen(
  File "/home/airflow/.local/lib/python3.8/site-packages/snowflake/connector/vendored/urllib3/connectionpool.py", line 815, in urlopen
    return self.urlopen(
  File "/home/airflow/.local/lib/python3.8/site-packages/snowflake/connector/vendored/urllib3/connectionpool.py", line 787, in urlopen
    retries = retries.increment(
  File "/home/airflow/.local/lib/python3.8/site-packages/snowflake/connector/vendored/urllib3/util/retry.py", line 592, in increment
    raise MaxRetryError(_pool, url, error or ResponseError(cause))
snowflake.connector.vendored.urllib3.exceptions.MaxRetryError: HTTPSConnectionPool(host='https', port=443): Max retries exceeded with url: //iy34150.europe-west4.snowflakecomputing.com:443/session/v1/login-request?request_id=e5adfc74-3764-405d-a00e-1cc8a806bafb&databaseName=TASKS&schemaName=PUBLIC&warehouse=COMPUTE_WH&roleName=ACCOUNTADMIN (Caused by NewConnectionError('<snowflake.connector.vendored.urllib3.connection.HTTPSConnection object at 0x7f4168085c40>: Failed to establish a new connection: [Errno -3] Temporary failure in name resolution'))

During handling of the above exception, another exception occurred:

Traceback (most recent call last):
  File "/home/airflow/.local/lib/python3.8/site-packages/snowflake/connector/network.py", line 1084, in _request_exec
    raw_ret = session.request(
  File "/home/airflow/.local/lib/python3.8/site-packages/snowflake/connector/vendored/requests/sessions.py", line 587, in request
    resp = self.send(prep, **send_kwargs)
  File "/home/airflow/.local/lib/python3.8/site-packages/snowflake/connector/vendored/requests/sessions.py", line 701, in send
    r = adapter.send(request, **kwargs)
  File "/home/airflow/.local/lib/python3.8/site-packages/snowflake/connector/vendored/requests/adapters.py", line 520, in send
    raise ConnectionError(e, request=request)
snowflake.connector.vendored.requests.exceptions.ConnectionError: HTTPSConnectionPool(host='https', port=443): Max retries exceeded with url: //iy34150.europe-west4.snowflakecomputing.com:443/session/v1/login-request?request_id=e5adfc74-3764-405d-a00e-1cc8a806bafb&databaseName=TASKS&schemaName=PUBLIC&warehouse=COMPUTE_WH&roleName=ACCOUNTADMIN (Caused by NewConnectionError('<snowflake.connector.vendored.urllib3.connection.HTTPSConnection object at 0x7f4168085c40>: Failed to establish a new connection: [Errno -3] Temporary failure in name resolution'))

During handling of the above exception, another exception occurred:

Traceback (most recent call last):
  File "/home/airflow/.local/lib/python3.8/site-packages/snowflake/connector/connection.py", line 1193, in _authenticate
    auth.authenticate(
  File "/home/airflow/.local/lib/python3.8/site-packages/snowflake/connector/auth/_auth.py", line 250, in authenticate
    ret = self._rest._post_request(
  File "/home/airflow/.local/lib/python3.8/site-packages/snowflake/connector/network.py", line 730, in _post_request
    ret = self.fetch(
  File "/home/airflow/.local/lib/python3.8/site-packages/snowflake/connector/network.py", line 849, in fetch
    ret = self._request_exec_wrapper(
  File "/home/airflow/.local/lib/python3.8/site-packages/snowflake/connector/network.py", line 987, in _request_exec_wrapper
    raise e
  File "/home/airflow/.local/lib/python3.8/site-packages/snowflake/connector/network.py", line 891, in _request_exec_wrapper
    return_object = self._request_exec(
  File "/home/airflow/.local/lib/python3.8/site-packages/snowflake/connector/network.py", line 1168, in _request_exec
    raise OperationalError(
snowflake.connector.errors.OperationalError: 251011: 251011: ConnectionTimeout occurred. Will be handled by authenticator

The above exception was the direct cause of the following exception:

Traceback (most recent call last):
  File "/home/airflow/.local/lib/python3.8/site-packages/airflow/providers/common/sql/operators/sql.py", line 280, in execute
    output = hook.run(
  File "/home/airflow/.local/lib/python3.8/site-packages/airflow/providers/snowflake/hooks/snowflake.py", line 409, in run
    with closing(self.get_conn()) as conn:
  File "/home/airflow/.local/lib/python3.8/site-packages/airflow/providers/snowflake/hooks/snowflake.py", line 303, in get_conn
    conn = connector.connect(**conn_config)
  File "/home/airflow/.local/lib/python3.8/site-packages/snowflake/connector/__init__.py", line 51, in Connect
    return SnowflakeConnection(**kwargs)
  File "/home/airflow/.local/lib/python3.8/site-packages/snowflake/connector/connection.py", line 353, in __init__
    self.connect(**kwargs)
  File "/home/airflow/.local/lib/python3.8/site-packages/snowflake/connector/connection.py", line 625, in connect
    self.__open_connection()
  File "/home/airflow/.local/lib/python3.8/site-packages/snowflake/connector/connection.py", line 898, in __open_connection
    self.authenticate_with_retry(self.auth_class)
  File "/home/airflow/.local/lib/python3.8/site-packages/snowflake/connector/connection.py", line 1167, in authenticate_with_retry
    self._authenticate(auth_instance)
  File "/home/airflow/.local/lib/python3.8/site-packages/snowflake/connector/connection.py", line 1238, in _authenticate
    raise auth_op from e
  File "/home/airflow/.local/lib/python3.8/site-packages/snowflake/connector/connection.py", line 1215, in _authenticate
    auth_instance.handle_timeout(
  File "/home/airflow/.local/lib/python3.8/site-packages/snowflake/connector/auth/by_plugin.py", line 219, in handle_timeout
    raise error
snowflake.connector.errors.OperationalError: 250001: 250001: Could not connect to Snowflake backend after 1 attempt(s).Aborting
[2023-12-04T16:40:47.588+0000] {taskinstance.py:1398} INFO - Marking task as UP_FOR_RETRY. dag_id=Georgy, task_id=query1, execution_date=20231130T211000, start_date=20231204T164012, end_date=20231204T164047
[2023-12-04T16:40:47.601+0000] {standard_task_runner.py:104} ERROR - Failed to execute job 108 for task query1 (250001: 250001: Could not connect to Snowflake backend after 1 attempt(s).Aborting; 795)
[2023-12-04T16:40:47.643+0000] {local_task_job_runner.py:228} INFO - Task exited with return code 1
[2023-12-04T16:40:47.660+0000] {taskinstance.py:2776} INFO - 0 downstream tasks scheduled from follow-on schedule check
[2023-12-04T16:52:41.211+0000] {taskinstance.py:1157} INFO - Dependencies all met for dep_context=non-requeueable deps ti=<TaskInstance: Georgy.query1 scheduled__2023-11-30T21:10:00+00:00 [queued]>
[2023-12-04T16:52:41.216+0000] {taskinstance.py:1157} INFO - Dependencies all met for dep_context=requeueable deps ti=<TaskInstance: Georgy.query1 scheduled__2023-11-30T21:10:00+00:00 [queued]>
[2023-12-04T16:52:41.217+0000] {taskinstance.py:1359} INFO - Starting attempt 1 of 4
[2023-12-04T16:52:41.227+0000] {taskinstance.py:1380} INFO - Executing <Task(SnowflakeOperator): query1> on 2023-11-30 21:10:00+00:00
[2023-12-04T16:52:41.231+0000] {standard_task_runner.py:57} INFO - Started process 993 to run task
[2023-12-04T16:52:41.234+0000] {standard_task_runner.py:84} INFO - Running: ['***', 'tasks', 'run', 'Georgy', 'query1', 'scheduled__2023-11-30T21:10:00+00:00', '--job-id', '109', '--raw', '--subdir', 'DAGS_FOLDER/test.py', '--cfg-path', '/tmp/tmpzyoo1fkf']
[2023-12-04T16:52:41.235+0000] {standard_task_runner.py:85} INFO - Job 109: Subtask query1
[2023-12-04T16:52:41.271+0000] {task_command.py:415} INFO - Running <TaskInstance: Georgy.query1 scheduled__2023-11-30T21:10:00+00:00 [running]> on host 435c91f40721
[2023-12-04T16:52:41.323+0000] {taskinstance.py:1660} INFO - Exporting env vars: AIRFLOW_CTX_DAG_OWNER='Gio' AIRFLOW_CTX_DAG_ID='Georgy' AIRFLOW_CTX_TASK_ID='query1' AIRFLOW_CTX_EXECUTION_DATE='2023-11-30T21:10:00+00:00' AIRFLOW_CTX_TRY_NUMBER='1' AIRFLOW_CTX_DAG_RUN_ID='scheduled__2023-11-30T21:10:00+00:00'
[2023-12-04T16:52:41.324+0000] {sql.py:274} INFO - Executing: CREATE TABLE test (col INT);
[2023-12-04T16:52:41.331+0000] {base.py:73} INFO - Using connection ID 'snowflake_default' for task execution.
[2023-12-04T16:52:41.338+0000] {base.py:73} INFO - Using connection ID 'snowflake_default' for task execution.
[2023-12-04T16:52:41.339+0000] {connection.py:314} INFO - Snowflake Connector for Python Version: 3.1.1, Python Version: 3.8.18, Platform: Linux-5.15.133.1-microsoft-standard-WSL2-x86_64-with-glibc2.2.5
[2023-12-04T16:52:41.340+0000] {connection.py:1050} INFO - This connection is in OCSP Fail Open Mode. TLS Certificates would be checked for validity and revocation status. Any other Certificate Revocation related exceptions or OCSP Responder failures would be disregarded in favor of connectivity.
[2023-12-04T16:52:41.340+0000] {connection.py:1068} INFO - Setting use_openssl_only mode to False
[2023-12-04T16:52:43.173+0000] {connection.py:547} WARNING - Certificate did not match expected hostname: yfgbvax-if99134.europe-west4.snowflakecomputing.com. Certificate: {'subject': ((('commonName', '*.prod3.us-west-2.snowflakecomputing.com'),),), 'subjectAltName': [('DNS', '*.prod3.us-west-2.snowflakecomputing.com'), ('DNS', '*.us-west-2.snowflakecomputing.com'), ('DNS', '*.global.snowflakecomputing.com'), ('DNS', '*.snowflakecomputing.com'), ('DNS', '*.prod3.us-west-2.aws.snowflakecomputing.com')]}
[2023-12-04T16:52:43.175+0000] {connectionpool.py:812} WARNING - Retrying (Retry(total=0, connect=None, read=None, redirect=None, status=None)) after connection broken by 'SSLError(CertificateError("hostname 'yfgbvax-if99134.europe-west4.snowflakecomputing.com' doesn't match either of '*.prod3.us-west-2.snowflakecomputing.com', '*.us-west-2.snowflakecomputing.com', '*.global.snowflakecomputing.com', '*.snowflakecomputing.com', '*.prod3.us-west-2.aws.snowflakecomputing.com'"))': /session/v1/login-request?request_id=fa3b5a67-8790-4468-90a4-5092995db0bb&databaseName=TASKS&schemaName=PUBLIC&warehouse=COMPUTE_WH&roleName=ACCOUNTADMIN&request_guid=4f089e6a-2f63-4392-8beb-2f7053671478
[2023-12-04T16:52:43.914+0000] {connection.py:547} WARNING - Certificate did not match expected hostname: yfgbvax-if99134.europe-west4.snowflakecomputing.com. Certificate: {'subject': ((('commonName', '*.prod3.us-west-2.snowflakecomputing.com'),),), 'subjectAltName': [('DNS', '*.prod3.us-west-2.snowflakecomputing.com'), ('DNS', '*.us-west-2.snowflakecomputing.com'), ('DNS', '*.global.snowflakecomputing.com'), ('DNS', '*.snowflakecomputing.com'), ('DNS', '*.prod3.us-west-2.aws.snowflakecomputing.com')]}
[2023-12-04T16:52:43.919+0000] {network.py:1037} ERROR - Failed to get the response. Hanging? method: post, url: https://yfgbvax-if99134.europe-west4.snowflakecomputing.com:443/session/v1/login-request?request_id=fa3b5a67-8790-4468-90a4-5092995db0bb&databaseName=TASKS&schemaName=PUBLIC&warehouse=COMPUTE_WH&roleName=ACCOUNTADMIN&request_guid=4f089e6a-2f63-4392-8beb-2f7053671478, headers:{'Content-Type': 'application/json', 'accept': 'application/snowflake', 'User-Agent': 'PythonConnector/3.1.1 (Linux-5.15.133.1-microsoft-standard-WSL2-x86_64-with-glibc2.2.5) CPython/3.8.18', 'Content-Encoding': 'gzip'}, data: {"data": {"CLIENT_APP_ID": "PythonConnector", "CLIENT_APP_VERSION": "3.1.1", "SVN_REVISION": null, "ACCOUNT_NAME": "yfgbvax-if99134", "LOGIN_NAME": "Medved", "CLIENT_ENVIRONMENT": {"APPLICATION": "AIRFLOW", "OS": "Linux", "OS_VERSION": "Linux-5.15.133.1-microsoft-standard-WSL2-x86_64-with-glibc2.2.5", "PYTHON_VERSION": "3.8.18", "PYTHON_RUNTIME": "CPython", "PYTHON_COMPILER": "GCC 10.2.1 20210110", "OCSP_MODE": "FAIL_OPEN", "TRACING": 20, "LOGIN_TIMEOUT": 120, "NETWORK_TIMEOUT": null}, "PASSWORD": "**** "SESSION_PARAMETERS": {"CLIENT_PREFETCH_THREADS": 4}}}
[2023-12-04T16:52:45.670+0000] {connection.py:547} WARNING - Certificate did not match expected hostname: yfgbvax-if99134.europe-west4.snowflakecomputing.com. Certificate: {'subject': ((('commonName', '*.prod3.us-west-2.snowflakecomputing.com'),),), 'subjectAltName': [('DNS', '*.prod3.us-west-2.snowflakecomputing.com'), ('DNS', '*.us-west-2.snowflakecomputing.com'), ('DNS', '*.global.snowflakecomputing.com'), ('DNS', '*.snowflakecomputing.com'), ('DNS', '*.prod3.us-west-2.aws.snowflakecomputing.com')]}
[2023-12-04T16:52:45.671+0000] {connectionpool.py:812} WARNING - Retrying (Retry(total=0, connect=None, read=None, redirect=None, status=None)) after connection broken by 'SSLError(CertificateError("hostname 'yfgbvax-if99134.europe-west4.snowflakecomputing.com' doesn't match either of '*.prod3.us-west-2.snowflakecomputing.com', '*.us-west-2.snowflakecomputing.com', '*.global.snowflakecomputing.com', '*.snowflakecomputing.com', '*.prod3.us-west-2.aws.snowflakecomputing.com'"))': /session/v1/login-request?request_id=1b12ed16-2d07-4ed0-a551-a58e7298055f&databaseName=TASKS&schemaName=PUBLIC&warehouse=COMPUTE_WH&roleName=ACCOUNTADMIN&request_guid=d207f947-3cbd-4a84-aa66-daaa49198300
[2023-12-04T16:52:46.415+0000] {connection.py:547} WARNING - Certificate did not match expected hostname: yfgbvax-if99134.europe-west4.snowflakecomputing.com. Certificate: {'subject': ((('commonName', '*.prod3.us-west-2.snowflakecomputing.com'),),), 'subjectAltName': [('DNS', '*.prod3.us-west-2.snowflakecomputing.com'), ('DNS', '*.us-west-2.snowflakecomputing.com'), ('DNS', '*.global.snowflakecomputing.com'), ('DNS', '*.snowflakecomputing.com'), ('DNS', '*.prod3.us-west-2.aws.snowflakecomputing.com')]}
[2023-12-04T16:52:46.418+0000] {network.py:1037} ERROR - Failed to get the response. Hanging? method: post, url: https://yfgbvax-if99134.europe-west4.snowflakecomputing.com:443/session/v1/login-request?request_id=1b12ed16-2d07-4ed0-a551-a58e7298055f&databaseName=TASKS&schemaName=PUBLIC&warehouse=COMPUTE_WH&roleName=ACCOUNTADMIN&request_guid=d207f947-3cbd-4a84-aa66-daaa49198300, headers:{'Content-Type': 'application/json', 'accept': 'application/snowflake', 'User-Agent': 'PythonConnector/3.1.1 (Linux-5.15.133.1-microsoft-standard-WSL2-x86_64-with-glibc2.2.5) CPython/3.8.18', 'Content-Encoding': 'gzip'}, data: {"data": {"CLIENT_APP_ID": "PythonConnector", "CLIENT_APP_VERSION": "3.1.1", "SVN_REVISION": null, "ACCOUNT_NAME": "yfgbvax-if99134", "LOGIN_NAME": "Medved", "CLIENT_ENVIRONMENT": {"APPLICATION": "AIRFLOW", "OS": "Linux", "OS_VERSION": "Linux-5.15.133.1-microsoft-standard-WSL2-x86_64-with-glibc2.2.5", "PYTHON_VERSION": "3.8.18", "PYTHON_RUNTIME": "CPython", "PYTHON_COMPILER": "GCC 10.2.1 20210110", "OCSP_MODE": "FAIL_OPEN", "TRACING": 20, "LOGIN_TIMEOUT": 120, "NETWORK_TIMEOUT": null}, "PASSWORD": "**** "SESSION_PARAMETERS": {"CLIENT_PREFETCH_THREADS": 4}}}
[2023-12-04T16:52:46.419+0000] {taskinstance.py:1935} ERROR - Task failed with exception
Traceback (most recent call last):
  File "/home/airflow/.local/lib/python3.8/site-packages/snowflake/connector/connection.py", line 1193, in _authenticate
    auth.authenticate(
  File "/home/airflow/.local/lib/python3.8/site-packages/snowflake/connector/auth/_auth.py", line 250, in authenticate
    ret = self._rest._post_request(
  File "/home/airflow/.local/lib/python3.8/site-packages/snowflake/connector/network.py", line 730, in _post_request
    ret = self.fetch(
  File "/home/airflow/.local/lib/python3.8/site-packages/snowflake/connector/network.py", line 849, in fetch
    ret = self._request_exec_wrapper(
  File "/home/airflow/.local/lib/python3.8/site-packages/snowflake/connector/network.py", line 987, in _request_exec_wrapper
    raise e
  File "/home/airflow/.local/lib/python3.8/site-packages/snowflake/connector/network.py", line 902, in _request_exec_wrapper
    self._handle_unknown_error(method, full_url, headers, data, conn)
  File "/home/airflow/.local/lib/python3.8/site-packages/snowflake/connector/network.py", line 1042, in _handle_unknown_error
    Error.errorhandler_wrapper(
  File "/home/airflow/.local/lib/python3.8/site-packages/snowflake/connector/errors.py", line 290, in errorhandler_wrapper
    handed_over = Error.hand_to_other_handler(
  File "/home/airflow/.local/lib/python3.8/site-packages/snowflake/connector/errors.py", line 348, in hand_to_other_handler
    connection.errorhandler(connection, cursor, error_class, error_value)
  File "/home/airflow/.local/lib/python3.8/site-packages/snowflake/connector/errors.py", line 221, in default_errorhandler
    raise error_class(
snowflake.connector.errors.OperationalError: 250003: 250003: Failed to get the response. Hanging? method: post, url: https://yfgbvax-if99134.europe-west4.snowflakecomputing.com:443/session/v1/login-request?request_id=fa3b5a67-8790-4468-90a4-5092995db0bb&databaseName=TASKS&schemaName=PUBLIC&warehouse=COMPUTE_WH&roleName=ACCOUNTADMIN&request_guid=4f089e6a-2f63-4392-8beb-2f7053671478

The above exception was the direct cause of the following exception:

Traceback (most recent call last):
  File "/home/airflow/.local/lib/python3.8/site-packages/airflow/providers/common/sql/operators/sql.py", line 280, in execute
    output = hook.run(
  File "/home/airflow/.local/lib/python3.8/site-packages/airflow/providers/snowflake/hooks/snowflake.py", line 409, in run
    with closing(self.get_conn()) as conn:
  File "/home/airflow/.local/lib/python3.8/site-packages/airflow/providers/snowflake/hooks/snowflake.py", line 303, in get_conn
    conn = connector.connect(**conn_config)
  File "/home/airflow/.local/lib/python3.8/site-packages/snowflake/connector/__init__.py", line 51, in Connect
    return SnowflakeConnection(**kwargs)
  File "/home/airflow/.local/lib/python3.8/site-packages/snowflake/connector/connection.py", line 353, in __init__
    self.connect(**kwargs)
  File "/home/airflow/.local/lib/python3.8/site-packages/snowflake/connector/connection.py", line 625, in connect
    self.__open_connection()
  File "/home/airflow/.local/lib/python3.8/site-packages/snowflake/connector/connection.py", line 898, in __open_connection
    self.authenticate_with_retry(self.auth_class)
  File "/home/airflow/.local/lib/python3.8/site-packages/snowflake/connector/connection.py", line 1167, in authenticate_with_retry
    self._authenticate(auth_instance)
  File "/home/airflow/.local/lib/python3.8/site-packages/snowflake/connector/connection.py", line 1238, in _authenticate
    raise auth_op from e
  File "/home/airflow/.local/lib/python3.8/site-packages/snowflake/connector/connection.py", line 1215, in _authenticate
    auth_instance.handle_timeout(
  File "/home/airflow/.local/lib/python3.8/site-packages/snowflake/connector/auth/by_plugin.py", line 219, in handle_timeout
    raise error
snowflake.connector.errors.OperationalError: 250001: 250001: Could not connect to Snowflake backend after 1 attempt(s).Aborting
[2023-12-04T16:52:46.426+0000] {taskinstance.py:1398} INFO - Marking task as UP_FOR_RETRY. dag_id=Georgy, task_id=query1, execution_date=20231130T211000, start_date=20231204T165241, end_date=20231204T165246
[2023-12-04T16:52:46.437+0000] {standard_task_runner.py:104} ERROR - Failed to execute job 109 for task query1 (250001: 250001: Could not connect to Snowflake backend after 1 attempt(s).Aborting; 993)
[2023-12-04T16:52:46.447+0000] {local_task_job_runner.py:228} INFO - Task exited with return code 1
[2023-12-04T16:52:46.465+0000] {taskinstance.py:2776} INFO - 0 downstream tasks scheduled from follow-on schedule check
[2023-12-04T16:57:51.137+0000] {taskinstance.py:1157} INFO - Dependencies all met for dep_context=non-requeueable deps ti=<TaskInstance: Georgy.query1 scheduled__2023-11-30T21:10:00+00:00 [queued]>
[2023-12-04T16:57:51.143+0000] {taskinstance.py:1157} INFO - Dependencies all met for dep_context=requeueable deps ti=<TaskInstance: Georgy.query1 scheduled__2023-11-30T21:10:00+00:00 [queued]>
[2023-12-04T16:57:51.144+0000] {taskinstance.py:1359} INFO - Starting attempt 1 of 4
[2023-12-04T16:57:51.156+0000] {taskinstance.py:1380} INFO - Executing <Task(SnowflakeOperator): query1> on 2023-11-30 21:10:00+00:00
[2023-12-04T16:57:51.160+0000] {standard_task_runner.py:57} INFO - Started process 1079 to run task
[2023-12-04T16:57:51.163+0000] {standard_task_runner.py:84} INFO - Running: ['***', 'tasks', 'run', 'Georgy', 'query1', 'scheduled__2023-11-30T21:10:00+00:00', '--job-id', '110', '--raw', '--subdir', 'DAGS_FOLDER/test.py', '--cfg-path', '/tmp/tmpgymlv9av']
[2023-12-04T16:57:51.164+0000] {standard_task_runner.py:85} INFO - Job 110: Subtask query1
[2023-12-04T16:57:51.201+0000] {task_command.py:415} INFO - Running <TaskInstance: Georgy.query1 scheduled__2023-11-30T21:10:00+00:00 [running]> on host 435c91f40721
[2023-12-04T16:57:51.253+0000] {taskinstance.py:1660} INFO - Exporting env vars: AIRFLOW_CTX_DAG_OWNER='Gio' AIRFLOW_CTX_DAG_ID='Georgy' AIRFLOW_CTX_TASK_ID='query1' AIRFLOW_CTX_EXECUTION_DATE='2023-11-30T21:10:00+00:00' AIRFLOW_CTX_TRY_NUMBER='1' AIRFLOW_CTX_DAG_RUN_ID='scheduled__2023-11-30T21:10:00+00:00'
[2023-12-04T16:57:51.254+0000] {sql.py:274} INFO - Executing: CREATE TABLE test (col INT);
[2023-12-04T16:57:51.262+0000] {base.py:73} INFO - Using connection ID 'snowflake_default' for task execution.
[2023-12-04T16:57:51.268+0000] {base.py:73} INFO - Using connection ID 'snowflake_default' for task execution.
[2023-12-04T16:57:51.269+0000] {connection.py:314} INFO - Snowflake Connector for Python Version: 3.1.1, Python Version: 3.8.18, Platform: Linux-5.15.133.1-microsoft-standard-WSL2-x86_64-with-glibc2.2.5
[2023-12-04T16:57:51.270+0000] {connection.py:1050} INFO - This connection is in OCSP Fail Open Mode. TLS Certificates would be checked for validity and revocation status. Any other Certificate Revocation related exceptions or OCSP Responder failures would be disregarded in favor of connectivity.
[2023-12-04T16:57:51.270+0000] {connection.py:1068} INFO - Setting use_openssl_only mode to False
[2023-12-04T16:57:52.280+0000] {connection.py:547} WARNING - Certificate did not match expected hostname: iy34150.europe-west4.snowflakecomputing.com. Certificate: {'subject': ((('commonName', '*.prod3.us-west-2.snowflakecomputing.com'),),), 'subjectAltName': [('DNS', '*.prod3.us-west-2.snowflakecomputing.com'), ('DNS', '*.us-west-2.snowflakecomputing.com'), ('DNS', '*.global.snowflakecomputing.com'), ('DNS', '*.snowflakecomputing.com'), ('DNS', '*.prod3.us-west-2.aws.snowflakecomputing.com')]}
[2023-12-04T16:57:52.282+0000] {connectionpool.py:812} WARNING - Retrying (Retry(total=0, connect=None, read=None, redirect=None, status=None)) after connection broken by 'SSLError(CertificateError("hostname 'iy34150.europe-west4.snowflakecomputing.com' doesn't match either of '*.prod3.us-west-2.snowflakecomputing.com', '*.us-west-2.snowflakecomputing.com', '*.global.snowflakecomputing.com', '*.snowflakecomputing.com', '*.prod3.us-west-2.aws.snowflakecomputing.com'"))': /session/v1/login-request?request_id=a9c383d3-2c08-4324-8fc0-a343b7b7dec3&databaseName=TASKS&schemaName=PUBLIC&warehouse=COMPUTE_WH&roleName=ACCOUNTADMIN&request_guid=503a82d3-f784-4a7f-b0e3-49c88ad6e65d
[2023-12-04T16:57:53.021+0000] {connection.py:547} WARNING - Certificate did not match expected hostname: iy34150.europe-west4.snowflakecomputing.com. Certificate: {'subject': ((('commonName', '*.prod3.us-west-2.snowflakecomputing.com'),),), 'subjectAltName': [('DNS', '*.prod3.us-west-2.snowflakecomputing.com'), ('DNS', '*.us-west-2.snowflakecomputing.com'), ('DNS', '*.global.snowflakecomputing.com'), ('DNS', '*.snowflakecomputing.com'), ('DNS', '*.prod3.us-west-2.aws.snowflakecomputing.com')]}
[2023-12-04T16:57:53.024+0000] {network.py:1037} ERROR - Failed to get the response. Hanging? method: post, url: https://iy34150.europe-west4.snowflakecomputing.com:443/session/v1/login-request?request_id=a9c383d3-2c08-4324-8fc0-a343b7b7dec3&databaseName=TASKS&schemaName=PUBLIC&warehouse=COMPUTE_WH&roleName=ACCOUNTADMIN&request_guid=503a82d3-f784-4a7f-b0e3-49c88ad6e65d, headers:{'Content-Type': 'application/json', 'accept': 'application/snowflake', 'User-Agent': 'PythonConnector/3.1.1 (Linux-5.15.133.1-microsoft-standard-WSL2-x86_64-with-glibc2.2.5) CPython/3.8.18', 'Content-Encoding': 'gzip'}, data: {"data": {"CLIENT_APP_ID": "PythonConnector", "CLIENT_APP_VERSION": "3.1.1", "SVN_REVISION": null, "ACCOUNT_NAME": "iy34150", "LOGIN_NAME": "Medved", "CLIENT_ENVIRONMENT": {"APPLICATION": "AIRFLOW", "OS": "Linux", "OS_VERSION": "Linux-5.15.133.1-microsoft-standard-WSL2-x86_64-with-glibc2.2.5", "PYTHON_VERSION": "3.8.18", "PYTHON_RUNTIME": "CPython", "PYTHON_COMPILER": "GCC 10.2.1 20210110", "OCSP_MODE": "FAIL_OPEN", "TRACING": 20, "LOGIN_TIMEOUT": 120, "NETWORK_TIMEOUT": null}, "PASSWORD": "**** "SESSION_PARAMETERS": {"CLIENT_PREFETCH_THREADS": 4}}}
[2023-12-04T16:57:54.783+0000] {connection.py:547} WARNING - Certificate did not match expected hostname: iy34150.europe-west4.snowflakecomputing.com. Certificate: {'subject': ((('commonName', '*.prod3.us-west-2.snowflakecomputing.com'),),), 'subjectAltName': [('DNS', '*.prod3.us-west-2.snowflakecomputing.com'), ('DNS', '*.us-west-2.snowflakecomputing.com'), ('DNS', '*.global.snowflakecomputing.com'), ('DNS', '*.snowflakecomputing.com'), ('DNS', '*.prod3.us-west-2.aws.snowflakecomputing.com')]}
[2023-12-04T16:57:54.784+0000] {connectionpool.py:812} WARNING - Retrying (Retry(total=0, connect=None, read=None, redirect=None, status=None)) after connection broken by 'SSLError(CertificateError("hostname 'iy34150.europe-west4.snowflakecomputing.com' doesn't match either of '*.prod3.us-west-2.snowflakecomputing.com', '*.us-west-2.snowflakecomputing.com', '*.global.snowflakecomputing.com', '*.snowflakecomputing.com', '*.prod3.us-west-2.aws.snowflakecomputing.com'"))': /session/v1/login-request?request_id=ff9ae168-2740-4f85-9866-218035b38f76&databaseName=TASKS&schemaName=PUBLIC&warehouse=COMPUTE_WH&roleName=ACCOUNTADMIN&request_guid=7c33c61e-91c3-4664-98c0-8c1ae05e2bcc
[2023-12-04T16:57:55.525+0000] {connection.py:547} WARNING - Certificate did not match expected hostname: iy34150.europe-west4.snowflakecomputing.com. Certificate: {'subject': ((('commonName', '*.prod3.us-west-2.snowflakecomputing.com'),),), 'subjectAltName': [('DNS', '*.prod3.us-west-2.snowflakecomputing.com'), ('DNS', '*.us-west-2.snowflakecomputing.com'), ('DNS', '*.global.snowflakecomputing.com'), ('DNS', '*.snowflakecomputing.com'), ('DNS', '*.prod3.us-west-2.aws.snowflakecomputing.com')]}
[2023-12-04T16:57:55.528+0000] {network.py:1037} ERROR - Failed to get the response. Hanging? method: post, url: https://iy34150.europe-west4.snowflakecomputing.com:443/session/v1/login-request?request_id=ff9ae168-2740-4f85-9866-218035b38f76&databaseName=TASKS&schemaName=PUBLIC&warehouse=COMPUTE_WH&roleName=ACCOUNTADMIN&request_guid=7c33c61e-91c3-4664-98c0-8c1ae05e2bcc, headers:{'Content-Type': 'application/json', 'accept': 'application/snowflake', 'User-Agent': 'PythonConnector/3.1.1 (Linux-5.15.133.1-microsoft-standard-WSL2-x86_64-with-glibc2.2.5) CPython/3.8.18', 'Content-Encoding': 'gzip'}, data: {"data": {"CLIENT_APP_ID": "PythonConnector", "CLIENT_APP_VERSION": "3.1.1", "SVN_REVISION": null, "ACCOUNT_NAME": "iy34150", "LOGIN_NAME": "Medved", "CLIENT_ENVIRONMENT": {"APPLICATION": "AIRFLOW", "OS": "Linux", "OS_VERSION": "Linux-5.15.133.1-microsoft-standard-WSL2-x86_64-with-glibc2.2.5", "PYTHON_VERSION": "3.8.18", "PYTHON_RUNTIME": "CPython", "PYTHON_COMPILER": "GCC 10.2.1 20210110", "OCSP_MODE": "FAIL_OPEN", "TRACING": 20, "LOGIN_TIMEOUT": 120, "NETWORK_TIMEOUT": null}, "PASSWORD": "**** "SESSION_PARAMETERS": {"CLIENT_PREFETCH_THREADS": 4}}}
[2023-12-04T16:57:55.530+0000] {taskinstance.py:1935} ERROR - Task failed with exception
Traceback (most recent call last):
  File "/home/airflow/.local/lib/python3.8/site-packages/snowflake/connector/connection.py", line 1193, in _authenticate
    auth.authenticate(
  File "/home/airflow/.local/lib/python3.8/site-packages/snowflake/connector/auth/_auth.py", line 250, in authenticate
    ret = self._rest._post_request(
  File "/home/airflow/.local/lib/python3.8/site-packages/snowflake/connector/network.py", line 730, in _post_request
    ret = self.fetch(
  File "/home/airflow/.local/lib/python3.8/site-packages/snowflake/connector/network.py", line 849, in fetch
    ret = self._request_exec_wrapper(
  File "/home/airflow/.local/lib/python3.8/site-packages/snowflake/connector/network.py", line 987, in _request_exec_wrapper
    raise e
  File "/home/airflow/.local/lib/python3.8/site-packages/snowflake/connector/network.py", line 902, in _request_exec_wrapper
    self._handle_unknown_error(method, full_url, headers, data, conn)
  File "/home/airflow/.local/lib/python3.8/site-packages/snowflake/connector/network.py", line 1042, in _handle_unknown_error
    Error.errorhandler_wrapper(
  File "/home/airflow/.local/lib/python3.8/site-packages/snowflake/connector/errors.py", line 290, in errorhandler_wrapper
    handed_over = Error.hand_to_other_handler(
  File "/home/airflow/.local/lib/python3.8/site-packages/snowflake/connector/errors.py", line 348, in hand_to_other_handler
    connection.errorhandler(connection, cursor, error_class, error_value)
  File "/home/airflow/.local/lib/python3.8/site-packages/snowflake/connector/errors.py", line 221, in default_errorhandler
    raise error_class(
snowflake.connector.errors.OperationalError: 250003: 250003: Failed to get the response. Hanging? method: post, url: https://iy34150.europe-west4.snowflakecomputing.com:443/session/v1/login-request?request_id=a9c383d3-2c08-4324-8fc0-a343b7b7dec3&databaseName=TASKS&schemaName=PUBLIC&warehouse=COMPUTE_WH&roleName=ACCOUNTADMIN&request_guid=503a82d3-f784-4a7f-b0e3-49c88ad6e65d

The above exception was the direct cause of the following exception:

Traceback (most recent call last):
  File "/home/airflow/.local/lib/python3.8/site-packages/airflow/providers/common/sql/operators/sql.py", line 280, in execute
    output = hook.run(
  File "/home/airflow/.local/lib/python3.8/site-packages/airflow/providers/snowflake/hooks/snowflake.py", line 409, in run
    with closing(self.get_conn()) as conn:
  File "/home/airflow/.local/lib/python3.8/site-packages/airflow/providers/snowflake/hooks/snowflake.py", line 303, in get_conn
    conn = connector.connect(**conn_config)
  File "/home/airflow/.local/lib/python3.8/site-packages/snowflake/connector/__init__.py", line 51, in Connect
    return SnowflakeConnection(**kwargs)
  File "/home/airflow/.local/lib/python3.8/site-packages/snowflake/connector/connection.py", line 353, in __init__
    self.connect(**kwargs)
  File "/home/airflow/.local/lib/python3.8/site-packages/snowflake/connector/connection.py", line 625, in connect
    self.__open_connection()
  File "/home/airflow/.local/lib/python3.8/site-packages/snowflake/connector/connection.py", line 898, in __open_connection
    self.authenticate_with_retry(self.auth_class)
  File "/home/airflow/.local/lib/python3.8/site-packages/snowflake/connector/connection.py", line 1167, in authenticate_with_retry
    self._authenticate(auth_instance)
  File "/home/airflow/.local/lib/python3.8/site-packages/snowflake/connector/connection.py", line 1238, in _authenticate
    raise auth_op from e
  File "/home/airflow/.local/lib/python3.8/site-packages/snowflake/connector/connection.py", line 1215, in _authenticate
    auth_instance.handle_timeout(
  File "/home/airflow/.local/lib/python3.8/site-packages/snowflake/connector/auth/by_plugin.py", line 219, in handle_timeout
    raise error
snowflake.connector.errors.OperationalError: 250001: 250001: Could not connect to Snowflake backend after 1 attempt(s).Aborting
[2023-12-04T16:57:55.537+0000] {taskinstance.py:1398} INFO - Marking task as UP_FOR_RETRY. dag_id=Georgy, task_id=query1, execution_date=20231130T211000, start_date=20231204T165751, end_date=20231204T165755
[2023-12-04T16:57:55.550+0000] {standard_task_runner.py:104} ERROR - Failed to execute job 110 for task query1 (250001: 250001: Could not connect to Snowflake backend after 1 attempt(s).Aborting; 1079)
[2023-12-04T16:57:55.589+0000] {local_task_job_runner.py:228} INFO - Task exited with return code 1
[2023-12-04T16:57:55.608+0000] {taskinstance.py:2776} INFO - 0 downstream tasks scheduled from follow-on schedule check
[2023-12-04T17:05:48.998+0000] {taskinstance.py:1157} INFO - Dependencies all met for dep_context=non-requeueable deps ti=<TaskInstance: Georgy.query1 scheduled__2023-11-30T21:10:00+00:00 [queued]>
[2023-12-04T17:05:49.005+0000] {taskinstance.py:1157} INFO - Dependencies all met for dep_context=requeueable deps ti=<TaskInstance: Georgy.query1 scheduled__2023-11-30T21:10:00+00:00 [queued]>
[2023-12-04T17:05:49.005+0000] {taskinstance.py:1359} INFO - Starting attempt 1 of 4
[2023-12-04T17:05:49.016+0000] {taskinstance.py:1380} INFO - Executing <Task(SnowflakeOperator): query1> on 2023-11-30 21:10:00+00:00
[2023-12-04T17:05:49.020+0000] {standard_task_runner.py:57} INFO - Started process 1205 to run task
[2023-12-04T17:05:49.023+0000] {standard_task_runner.py:84} INFO - Running: ['***', 'tasks', 'run', 'Georgy', 'query1', 'scheduled__2023-11-30T21:10:00+00:00', '--job-id', '111', '--raw', '--subdir', 'DAGS_FOLDER/test.py', '--cfg-path', '/tmp/tmpi6ryi_3j']
[2023-12-04T17:05:49.024+0000] {standard_task_runner.py:85} INFO - Job 111: Subtask query1
[2023-12-04T17:05:49.058+0000] {task_command.py:415} INFO - Running <TaskInstance: Georgy.query1 scheduled__2023-11-30T21:10:00+00:00 [running]> on host 435c91f40721
[2023-12-04T17:05:49.111+0000] {taskinstance.py:1660} INFO - Exporting env vars: AIRFLOW_CTX_DAG_OWNER='Gio' AIRFLOW_CTX_DAG_ID='Georgy' AIRFLOW_CTX_TASK_ID='query1' AIRFLOW_CTX_EXECUTION_DATE='2023-11-30T21:10:00+00:00' AIRFLOW_CTX_TRY_NUMBER='1' AIRFLOW_CTX_DAG_RUN_ID='scheduled__2023-11-30T21:10:00+00:00'
[2023-12-04T17:05:49.112+0000] {sql.py:274} INFO - Executing: CREATE TABLE test (col INT);
[2023-12-04T17:05:49.120+0000] {base.py:73} INFO - Using connection ID 'snowflake_default' for task execution.
[2023-12-04T17:05:49.126+0000] {base.py:73} INFO - Using connection ID 'snowflake_default' for task execution.
[2023-12-04T17:05:49.127+0000] {connection.py:314} INFO - Snowflake Connector for Python Version: 3.1.1, Python Version: 3.8.18, Platform: Linux-5.15.133.1-microsoft-standard-WSL2-x86_64-with-glibc2.2.5
[2023-12-04T17:05:49.128+0000] {connection.py:1050} INFO - This connection is in OCSP Fail Open Mode. TLS Certificates would be checked for validity and revocation status. Any other Certificate Revocation related exceptions or OCSP Responder failures would be disregarded in favor of connectivity.
[2023-12-04T17:05:49.128+0000] {connection.py:1068} INFO - Setting use_openssl_only mode to False
[2023-12-04T17:05:50.137+0000] {connection.py:547} WARNING - Certificate did not match expected hostname: iy34150.europe-west4.snowflakecomputing.com. Certificate: {'subject': ((('commonName', '*.prod3.us-west-2.snowflakecomputing.com'),),), 'subjectAltName': [('DNS', '*.prod3.us-west-2.snowflakecomputing.com'), ('DNS', '*.us-west-2.snowflakecomputing.com'), ('DNS', '*.global.snowflakecomputing.com'), ('DNS', '*.snowflakecomputing.com'), ('DNS', '*.prod3.us-west-2.aws.snowflakecomputing.com')]}
[2023-12-04T17:05:50.138+0000] {connectionpool.py:812} WARNING - Retrying (Retry(total=0, connect=None, read=None, redirect=None, status=None)) after connection broken by 'SSLError(CertificateError("hostname 'iy34150.europe-west4.snowflakecomputing.com' doesn't match either of '*.prod3.us-west-2.snowflakecomputing.com', '*.us-west-2.snowflakecomputing.com', '*.global.snowflakecomputing.com', '*.snowflakecomputing.com', '*.prod3.us-west-2.aws.snowflakecomputing.com'"))': /session/v1/login-request?request_id=7723fe4f-82a5-400d-a9e3-dd30d7b19ca2&databaseName=TASKS&schemaName=PUBLIC&warehouse=COMPUTE_WH&roleName=ACCOUNTADMIN&request_guid=44fb6185-9c55-4675-b992-893322bb03d2
[2023-12-04T17:05:50.883+0000] {connection.py:547} WARNING - Certificate did not match expected hostname: iy34150.europe-west4.snowflakecomputing.com. Certificate: {'subject': ((('commonName', '*.prod3.us-west-2.snowflakecomputing.com'),),), 'subjectAltName': [('DNS', '*.prod3.us-west-2.snowflakecomputing.com'), ('DNS', '*.us-west-2.snowflakecomputing.com'), ('DNS', '*.global.snowflakecomputing.com'), ('DNS', '*.snowflakecomputing.com'), ('DNS', '*.prod3.us-west-2.aws.snowflakecomputing.com')]}
[2023-12-04T17:05:50.887+0000] {network.py:1037} ERROR - Failed to get the response. Hanging? method: post, url: https://iy34150.europe-west4.snowflakecomputing.com:443/session/v1/login-request?request_id=7723fe4f-82a5-400d-a9e3-dd30d7b19ca2&databaseName=TASKS&schemaName=PUBLIC&warehouse=COMPUTE_WH&roleName=ACCOUNTADMIN&request_guid=44fb6185-9c55-4675-b992-893322bb03d2, headers:{'Content-Type': 'application/json', 'accept': 'application/snowflake', 'User-Agent': 'PythonConnector/3.1.1 (Linux-5.15.133.1-microsoft-standard-WSL2-x86_64-with-glibc2.2.5) CPython/3.8.18', 'Content-Encoding': 'gzip'}, data: {"data": {"CLIENT_APP_ID": "PythonConnector", "CLIENT_APP_VERSION": "3.1.1", "SVN_REVISION": null, "ACCOUNT_NAME": "iy34150", "LOGIN_NAME": "Medved", "CLIENT_ENVIRONMENT": {"APPLICATION": "AIRFLOW", "OS": "Linux", "OS_VERSION": "Linux-5.15.133.1-microsoft-standard-WSL2-x86_64-with-glibc2.2.5", "PYTHON_VERSION": "3.8.18", "PYTHON_RUNTIME": "CPython", "PYTHON_COMPILER": "GCC 10.2.1 20210110", "OCSP_MODE": "FAIL_OPEN", "TRACING": 20, "LOGIN_TIMEOUT": 120, "NETWORK_TIMEOUT": null}, "PASSWORD": "**** "SESSION_PARAMETERS": {"CLIENT_PREFETCH_THREADS": 4}}}
[2023-12-04T17:05:53.642+0000] {connection.py:547} WARNING - Certificate did not match expected hostname: iy34150.europe-west4.snowflakecomputing.com. Certificate: {'subject': ((('commonName', '*.prod3.us-west-2.snowflakecomputing.com'),),), 'subjectAltName': [('DNS', '*.prod3.us-west-2.snowflakecomputing.com'), ('DNS', '*.us-west-2.snowflakecomputing.com'), ('DNS', '*.global.snowflakecomputing.com'), ('DNS', '*.snowflakecomputing.com'), ('DNS', '*.prod3.us-west-2.aws.snowflakecomputing.com')]}
[2023-12-04T17:05:53.643+0000] {connectionpool.py:812} WARNING - Retrying (Retry(total=0, connect=None, read=None, redirect=None, status=None)) after connection broken by 'SSLError(CertificateError("hostname 'iy34150.europe-west4.snowflakecomputing.com' doesn't match either of '*.prod3.us-west-2.snowflakecomputing.com', '*.us-west-2.snowflakecomputing.com', '*.global.snowflakecomputing.com', '*.snowflakecomputing.com', '*.prod3.us-west-2.aws.snowflakecomputing.com'"))': /session/v1/login-request?request_id=0f29251f-241d-4bed-8aae-20eb83e84544&databaseName=TASKS&schemaName=PUBLIC&warehouse=COMPUTE_WH&roleName=ACCOUNTADMIN&request_guid=6d224c5b-8241-4168-819b-2827ebeaae2e
[2023-12-04T17:05:54.404+0000] {connection.py:547} WARNING - Certificate did not match expected hostname: iy34150.europe-west4.snowflakecomputing.com. Certificate: {'subject': ((('commonName', '*.prod3.us-west-2.snowflakecomputing.com'),),), 'subjectAltName': [('DNS', '*.prod3.us-west-2.snowflakecomputing.com'), ('DNS', '*.us-west-2.snowflakecomputing.com'), ('DNS', '*.global.snowflakecomputing.com'), ('DNS', '*.snowflakecomputing.com'), ('DNS', '*.prod3.us-west-2.aws.snowflakecomputing.com')]}
[2023-12-04T17:05:54.406+0000] {network.py:1037} ERROR - Failed to get the response. Hanging? method: post, url: https://iy34150.europe-west4.snowflakecomputing.com:443/session/v1/login-request?request_id=0f29251f-241d-4bed-8aae-20eb83e84544&databaseName=TASKS&schemaName=PUBLIC&warehouse=COMPUTE_WH&roleName=ACCOUNTADMIN&request_guid=6d224c5b-8241-4168-819b-2827ebeaae2e, headers:{'Content-Type': 'application/json', 'accept': 'application/snowflake', 'User-Agent': 'PythonConnector/3.1.1 (Linux-5.15.133.1-microsoft-standard-WSL2-x86_64-with-glibc2.2.5) CPython/3.8.18', 'Content-Encoding': 'gzip'}, data: {"data": {"CLIENT_APP_ID": "PythonConnector", "CLIENT_APP_VERSION": "3.1.1", "SVN_REVISION": null, "ACCOUNT_NAME": "iy34150", "LOGIN_NAME": "Medved", "CLIENT_ENVIRONMENT": {"APPLICATION": "AIRFLOW", "OS": "Linux", "OS_VERSION": "Linux-5.15.133.1-microsoft-standard-WSL2-x86_64-with-glibc2.2.5", "PYTHON_VERSION": "3.8.18", "PYTHON_RUNTIME": "CPython", "PYTHON_COMPILER": "GCC 10.2.1 20210110", "OCSP_MODE": "FAIL_OPEN", "TRACING": 20, "LOGIN_TIMEOUT": 120, "NETWORK_TIMEOUT": null}, "PASSWORD": "**** "SESSION_PARAMETERS": {"CLIENT_PREFETCH_THREADS": 4}}}
[2023-12-04T17:05:54.408+0000] {taskinstance.py:1935} ERROR - Task failed with exception
Traceback (most recent call last):
  File "/home/airflow/.local/lib/python3.8/site-packages/snowflake/connector/connection.py", line 1193, in _authenticate
    auth.authenticate(
  File "/home/airflow/.local/lib/python3.8/site-packages/snowflake/connector/auth/_auth.py", line 250, in authenticate
    ret = self._rest._post_request(
  File "/home/airflow/.local/lib/python3.8/site-packages/snowflake/connector/network.py", line 730, in _post_request
    ret = self.fetch(
  File "/home/airflow/.local/lib/python3.8/site-packages/snowflake/connector/network.py", line 849, in fetch
    ret = self._request_exec_wrapper(
  File "/home/airflow/.local/lib/python3.8/site-packages/snowflake/connector/network.py", line 987, in _request_exec_wrapper
    raise e
  File "/home/airflow/.local/lib/python3.8/site-packages/snowflake/connector/network.py", line 902, in _request_exec_wrapper
    self._handle_unknown_error(method, full_url, headers, data, conn)
  File "/home/airflow/.local/lib/python3.8/site-packages/snowflake/connector/network.py", line 1042, in _handle_unknown_error
    Error.errorhandler_wrapper(
  File "/home/airflow/.local/lib/python3.8/site-packages/snowflake/connector/errors.py", line 290, in errorhandler_wrapper
    handed_over = Error.hand_to_other_handler(
  File "/home/airflow/.local/lib/python3.8/site-packages/snowflake/connector/errors.py", line 348, in hand_to_other_handler
    connection.errorhandler(connection, cursor, error_class, error_value)
  File "/home/airflow/.local/lib/python3.8/site-packages/snowflake/connector/errors.py", line 221, in default_errorhandler
    raise error_class(
snowflake.connector.errors.OperationalError: 250003: 250003: Failed to get the response. Hanging? method: post, url: https://iy34150.europe-west4.snowflakecomputing.com:443/session/v1/login-request?request_id=7723fe4f-82a5-400d-a9e3-dd30d7b19ca2&databaseName=TASKS&schemaName=PUBLIC&warehouse=COMPUTE_WH&roleName=ACCOUNTADMIN&request_guid=44fb6185-9c55-4675-b992-893322bb03d2

The above exception was the direct cause of the following exception:

Traceback (most recent call last):
  File "/home/airflow/.local/lib/python3.8/site-packages/airflow/providers/common/sql/operators/sql.py", line 280, in execute
    output = hook.run(
  File "/home/airflow/.local/lib/python3.8/site-packages/airflow/providers/snowflake/hooks/snowflake.py", line 409, in run
    with closing(self.get_conn()) as conn:
  File "/home/airflow/.local/lib/python3.8/site-packages/airflow/providers/snowflake/hooks/snowflake.py", line 303, in get_conn
    conn = connector.connect(**conn_config)
  File "/home/airflow/.local/lib/python3.8/site-packages/snowflake/connector/__init__.py", line 51, in Connect
    return SnowflakeConnection(**kwargs)
  File "/home/airflow/.local/lib/python3.8/site-packages/snowflake/connector/connection.py", line 353, in __init__
    self.connect(**kwargs)
  File "/home/airflow/.local/lib/python3.8/site-packages/snowflake/connector/connection.py", line 625, in connect
    self.__open_connection()
  File "/home/airflow/.local/lib/python3.8/site-packages/snowflake/connector/connection.py", line 898, in __open_connection
    self.authenticate_with_retry(self.auth_class)
  File "/home/airflow/.local/lib/python3.8/site-packages/snowflake/connector/connection.py", line 1167, in authenticate_with_retry
    self._authenticate(auth_instance)
  File "/home/airflow/.local/lib/python3.8/site-packages/snowflake/connector/connection.py", line 1238, in _authenticate
    raise auth_op from e
  File "/home/airflow/.local/lib/python3.8/site-packages/snowflake/connector/connection.py", line 1215, in _authenticate
    auth_instance.handle_timeout(
  File "/home/airflow/.local/lib/python3.8/site-packages/snowflake/connector/auth/by_plugin.py", line 219, in handle_timeout
    raise error
snowflake.connector.errors.OperationalError: 250001: 250001: Could not connect to Snowflake backend after 1 attempt(s).Aborting
[2023-12-04T17:05:54.415+0000] {taskinstance.py:1398} INFO - Marking task as UP_FOR_RETRY. dag_id=Georgy, task_id=query1, execution_date=20231130T211000, start_date=20231204T170548, end_date=20231204T170554
[2023-12-04T17:05:54.428+0000] {standard_task_runner.py:104} ERROR - Failed to execute job 111 for task query1 (250001: 250001: Could not connect to Snowflake backend after 1 attempt(s).Aborting; 1205)
[2023-12-04T17:05:54.479+0000] {local_task_job_runner.py:228} INFO - Task exited with return code 1
[2023-12-04T17:05:54.499+0000] {taskinstance.py:2776} INFO - 0 downstream tasks scheduled from follow-on schedule check
[2023-12-04T17:12:23.848+0000] {taskinstance.py:1157} INFO - Dependencies all met for dep_context=non-requeueable deps ti=<TaskInstance: Georgy.query1 scheduled__2023-11-30T21:10:00+00:00 [queued]>
[2023-12-04T17:12:23.854+0000] {taskinstance.py:1157} INFO - Dependencies all met for dep_context=requeueable deps ti=<TaskInstance: Georgy.query1 scheduled__2023-11-30T21:10:00+00:00 [queued]>
[2023-12-04T17:12:23.855+0000] {taskinstance.py:1359} INFO - Starting attempt 1 of 4
[2023-12-04T17:12:23.865+0000] {taskinstance.py:1380} INFO - Executing <Task(SnowflakeOperator): query1> on 2023-11-30 21:10:00+00:00
[2023-12-04T17:12:23.869+0000] {standard_task_runner.py:57} INFO - Started process 1307 to run task
[2023-12-04T17:12:23.872+0000] {standard_task_runner.py:84} INFO - Running: ['***', 'tasks', 'run', 'Georgy', 'query1', 'scheduled__2023-11-30T21:10:00+00:00', '--job-id', '112', '--raw', '--subdir', 'DAGS_FOLDER/test.py', '--cfg-path', '/tmp/tmpupdu8v2n']
[2023-12-04T17:12:23.872+0000] {standard_task_runner.py:85} INFO - Job 112: Subtask query1
[2023-12-04T17:12:23.908+0000] {task_command.py:415} INFO - Running <TaskInstance: Georgy.query1 scheduled__2023-11-30T21:10:00+00:00 [running]> on host 435c91f40721
[2023-12-04T17:12:23.975+0000] {taskinstance.py:1660} INFO - Exporting env vars: AIRFLOW_CTX_DAG_OWNER='Gio' AIRFLOW_CTX_DAG_ID='Georgy' AIRFLOW_CTX_TASK_ID='query1' AIRFLOW_CTX_EXECUTION_DATE='2023-11-30T21:10:00+00:00' AIRFLOW_CTX_TRY_NUMBER='1' AIRFLOW_CTX_DAG_RUN_ID='scheduled__2023-11-30T21:10:00+00:00'
[2023-12-04T17:12:23.976+0000] {sql.py:274} INFO - Executing: CREATE TABLE test (col INT);
[2023-12-04T17:12:23.985+0000] {base.py:73} INFO - Using connection ID 'snowflake_default' for task execution.
[2023-12-04T17:12:23.993+0000] {base.py:73} INFO - Using connection ID 'snowflake_default' for task execution.
[2023-12-04T17:12:23.993+0000] {connection.py:314} INFO - Snowflake Connector for Python Version: 3.1.1, Python Version: 3.8.18, Platform: Linux-5.15.133.1-microsoft-standard-WSL2-x86_64-with-glibc2.2.5
[2023-12-04T17:12:23.994+0000] {connection.py:1050} INFO - This connection is in OCSP Fail Open Mode. TLS Certificates would be checked for validity and revocation status. Any other Certificate Revocation related exceptions or OCSP Responder failures would be disregarded in favor of connectivity.
[2023-12-04T17:12:23.995+0000] {connection.py:1068} INFO - Setting use_openssl_only mode to False
[2023-12-04T17:12:25.013+0000] {connection.py:547} WARNING - Certificate did not match expected hostname: iy34150.europe-west4.snowflakecomputing.com. Certificate: {'subject': ((('commonName', '*.prod3.us-west-2.snowflakecomputing.com'),),), 'subjectAltName': [('DNS', '*.prod3.us-west-2.snowflakecomputing.com'), ('DNS', '*.us-west-2.snowflakecomputing.com'), ('DNS', '*.global.snowflakecomputing.com'), ('DNS', '*.snowflakecomputing.com'), ('DNS', '*.prod3.us-west-2.aws.snowflakecomputing.com')]}
[2023-12-04T17:12:25.014+0000] {connectionpool.py:812} WARNING - Retrying (Retry(total=0, connect=None, read=None, redirect=None, status=None)) after connection broken by 'SSLError(CertificateError("hostname 'iy34150.europe-west4.snowflakecomputing.com' doesn't match either of '*.prod3.us-west-2.snowflakecomputing.com', '*.us-west-2.snowflakecomputing.com', '*.global.snowflakecomputing.com', '*.snowflakecomputing.com', '*.prod3.us-west-2.aws.snowflakecomputing.com'"))': /session/v1/login-request?request_id=443d5730-d64e-4af5-8bc5-ca2c51022555&databaseName=TASKS&schemaName=PUBLIC&warehouse=COMPUTE_WH&roleName=ACCOUNTADMIN&request_guid=159c09b0-eb1b-43de-b907-a80603b25fd1
[2023-12-04T17:12:25.760+0000] {connection.py:547} WARNING - Certificate did not match expected hostname: iy34150.europe-west4.snowflakecomputing.com. Certificate: {'subject': ((('commonName', '*.prod3.us-west-2.snowflakecomputing.com'),),), 'subjectAltName': [('DNS', '*.prod3.us-west-2.snowflakecomputing.com'), ('DNS', '*.us-west-2.snowflakecomputing.com'), ('DNS', '*.global.snowflakecomputing.com'), ('DNS', '*.snowflakecomputing.com'), ('DNS', '*.prod3.us-west-2.aws.snowflakecomputing.com')]}
[2023-12-04T17:12:25.763+0000] {network.py:1037} ERROR - Failed to get the response. Hanging? method: post, url: https://iy34150.europe-west4.snowflakecomputing.com:443/session/v1/login-request?request_id=443d5730-d64e-4af5-8bc5-ca2c51022555&databaseName=TASKS&schemaName=PUBLIC&warehouse=COMPUTE_WH&roleName=ACCOUNTADMIN&request_guid=159c09b0-eb1b-43de-b907-a80603b25fd1, headers:{'Content-Type': 'application/json', 'accept': 'application/snowflake', 'User-Agent': 'PythonConnector/3.1.1 (Linux-5.15.133.1-microsoft-standard-WSL2-x86_64-with-glibc2.2.5) CPython/3.8.18', 'Content-Encoding': 'gzip'}, data: {"data": {"CLIENT_APP_ID": "PythonConnector", "CLIENT_APP_VERSION": "3.1.1", "SVN_REVISION": null, "ACCOUNT_NAME": "iy34150", "LOGIN_NAME": "MEDVED", "CLIENT_ENVIRONMENT": {"APPLICATION": "AIRFLOW", "OS": "Linux", "OS_VERSION": "Linux-5.15.133.1-microsoft-standard-WSL2-x86_64-with-glibc2.2.5", "PYTHON_VERSION": "3.8.18", "PYTHON_RUNTIME": "CPython", "PYTHON_COMPILER": "GCC 10.2.1 20210110", "OCSP_MODE": "FAIL_OPEN", "TRACING": 20, "LOGIN_TIMEOUT": 120, "NETWORK_TIMEOUT": null}, "PASSWORD": "**** "SESSION_PARAMETERS": {"CLIENT_PREFETCH_THREADS": 4}}}
[2023-12-04T17:12:29.521+0000] {connection.py:547} WARNING - Certificate did not match expected hostname: iy34150.europe-west4.snowflakecomputing.com. Certificate: {'subject': ((('commonName', '*.prod3.us-west-2.snowflakecomputing.com'),),), 'subjectAltName': [('DNS', '*.prod3.us-west-2.snowflakecomputing.com'), ('DNS', '*.us-west-2.snowflakecomputing.com'), ('DNS', '*.global.snowflakecomputing.com'), ('DNS', '*.snowflakecomputing.com'), ('DNS', '*.prod3.us-west-2.aws.snowflakecomputing.com')]}
[2023-12-04T17:12:29.522+0000] {connectionpool.py:812} WARNING - Retrying (Retry(total=0, connect=None, read=None, redirect=None, status=None)) after connection broken by 'SSLError(CertificateError("hostname 'iy34150.europe-west4.snowflakecomputing.com' doesn't match either of '*.prod3.us-west-2.snowflakecomputing.com', '*.us-west-2.snowflakecomputing.com', '*.global.snowflakecomputing.com', '*.snowflakecomputing.com', '*.prod3.us-west-2.aws.snowflakecomputing.com'"))': /session/v1/login-request?request_id=7299d73c-ad30-4b79-ab4f-741f997c7d52&databaseName=TASKS&schemaName=PUBLIC&warehouse=COMPUTE_WH&roleName=ACCOUNTADMIN&request_guid=02c5eb94-6a9c-47af-bb9c-5ea7789d4180
[2023-12-04T17:12:30.268+0000] {connection.py:547} WARNING - Certificate did not match expected hostname: iy34150.europe-west4.snowflakecomputing.com. Certificate: {'subject': ((('commonName', '*.prod3.us-west-2.snowflakecomputing.com'),),), 'subjectAltName': [('DNS', '*.prod3.us-west-2.snowflakecomputing.com'), ('DNS', '*.us-west-2.snowflakecomputing.com'), ('DNS', '*.global.snowflakecomputing.com'), ('DNS', '*.snowflakecomputing.com'), ('DNS', '*.prod3.us-west-2.aws.snowflakecomputing.com')]}
[2023-12-04T17:12:30.270+0000] {network.py:1037} ERROR - Failed to get the response. Hanging? method: post, url: https://iy34150.europe-west4.snowflakecomputing.com:443/session/v1/login-request?request_id=7299d73c-ad30-4b79-ab4f-741f997c7d52&databaseName=TASKS&schemaName=PUBLIC&warehouse=COMPUTE_WH&roleName=ACCOUNTADMIN&request_guid=02c5eb94-6a9c-47af-bb9c-5ea7789d4180, headers:{'Content-Type': 'application/json', 'accept': 'application/snowflake', 'User-Agent': 'PythonConnector/3.1.1 (Linux-5.15.133.1-microsoft-standard-WSL2-x86_64-with-glibc2.2.5) CPython/3.8.18', 'Content-Encoding': 'gzip'}, data: {"data": {"CLIENT_APP_ID": "PythonConnector", "CLIENT_APP_VERSION": "3.1.1", "SVN_REVISION": null, "ACCOUNT_NAME": "iy34150", "LOGIN_NAME": "MEDVED", "CLIENT_ENVIRONMENT": {"APPLICATION": "AIRFLOW", "OS": "Linux", "OS_VERSION": "Linux-5.15.133.1-microsoft-standard-WSL2-x86_64-with-glibc2.2.5", "PYTHON_VERSION": "3.8.18", "PYTHON_RUNTIME": "CPython", "PYTHON_COMPILER": "GCC 10.2.1 20210110", "OCSP_MODE": "FAIL_OPEN", "TRACING": 20, "LOGIN_TIMEOUT": 120, "NETWORK_TIMEOUT": null}, "PASSWORD": "**** "SESSION_PARAMETERS": {"CLIENT_PREFETCH_THREADS": 4}}}
[2023-12-04T17:12:30.272+0000] {taskinstance.py:1935} ERROR - Task failed with exception
Traceback (most recent call last):
  File "/home/airflow/.local/lib/python3.8/site-packages/snowflake/connector/connection.py", line 1193, in _authenticate
    auth.authenticate(
  File "/home/airflow/.local/lib/python3.8/site-packages/snowflake/connector/auth/_auth.py", line 250, in authenticate
    ret = self._rest._post_request(
  File "/home/airflow/.local/lib/python3.8/site-packages/snowflake/connector/network.py", line 730, in _post_request
    ret = self.fetch(
  File "/home/airflow/.local/lib/python3.8/site-packages/snowflake/connector/network.py", line 849, in fetch
    ret = self._request_exec_wrapper(
  File "/home/airflow/.local/lib/python3.8/site-packages/snowflake/connector/network.py", line 987, in _request_exec_wrapper
    raise e
  File "/home/airflow/.local/lib/python3.8/site-packages/snowflake/connector/network.py", line 902, in _request_exec_wrapper
    self._handle_unknown_error(method, full_url, headers, data, conn)
  File "/home/airflow/.local/lib/python3.8/site-packages/snowflake/connector/network.py", line 1042, in _handle_unknown_error
    Error.errorhandler_wrapper(
  File "/home/airflow/.local/lib/python3.8/site-packages/snowflake/connector/errors.py", line 290, in errorhandler_wrapper
    handed_over = Error.hand_to_other_handler(
  File "/home/airflow/.local/lib/python3.8/site-packages/snowflake/connector/errors.py", line 348, in hand_to_other_handler
    connection.errorhandler(connection, cursor, error_class, error_value)
  File "/home/airflow/.local/lib/python3.8/site-packages/snowflake/connector/errors.py", line 221, in default_errorhandler
    raise error_class(
snowflake.connector.errors.OperationalError: 250003: 250003: Failed to get the response. Hanging? method: post, url: https://iy34150.europe-west4.snowflakecomputing.com:443/session/v1/login-request?request_id=443d5730-d64e-4af5-8bc5-ca2c51022555&databaseName=TASKS&schemaName=PUBLIC&warehouse=COMPUTE_WH&roleName=ACCOUNTADMIN&request_guid=159c09b0-eb1b-43de-b907-a80603b25fd1

The above exception was the direct cause of the following exception:

Traceback (most recent call last):
  File "/home/airflow/.local/lib/python3.8/site-packages/airflow/providers/common/sql/operators/sql.py", line 280, in execute
    output = hook.run(
  File "/home/airflow/.local/lib/python3.8/site-packages/airflow/providers/snowflake/hooks/snowflake.py", line 409, in run
    with closing(self.get_conn()) as conn:
  File "/home/airflow/.local/lib/python3.8/site-packages/airflow/providers/snowflake/hooks/snowflake.py", line 303, in get_conn
    conn = connector.connect(**conn_config)
  File "/home/airflow/.local/lib/python3.8/site-packages/snowflake/connector/__init__.py", line 51, in Connect
    return SnowflakeConnection(**kwargs)
  File "/home/airflow/.local/lib/python3.8/site-packages/snowflake/connector/connection.py", line 353, in __init__
    self.connect(**kwargs)
  File "/home/airflow/.local/lib/python3.8/site-packages/snowflake/connector/connection.py", line 625, in connect
    self.__open_connection()
  File "/home/airflow/.local/lib/python3.8/site-packages/snowflake/connector/connection.py", line 898, in __open_connection
    self.authenticate_with_retry(self.auth_class)
  File "/home/airflow/.local/lib/python3.8/site-packages/snowflake/connector/connection.py", line 1167, in authenticate_with_retry
    self._authenticate(auth_instance)
  File "/home/airflow/.local/lib/python3.8/site-packages/snowflake/connector/connection.py", line 1238, in _authenticate
    raise auth_op from e
  File "/home/airflow/.local/lib/python3.8/site-packages/snowflake/connector/connection.py", line 1215, in _authenticate
    auth_instance.handle_timeout(
  File "/home/airflow/.local/lib/python3.8/site-packages/snowflake/connector/auth/by_plugin.py", line 219, in handle_timeout
    raise error
snowflake.connector.errors.OperationalError: 250001: 250001: Could not connect to Snowflake backend after 1 attempt(s).Aborting
[2023-12-04T17:12:30.279+0000] {taskinstance.py:1398} INFO - Marking task as UP_FOR_RETRY. dag_id=Georgy, task_id=query1, execution_date=20231130T211000, start_date=20231204T171223, end_date=20231204T171230
[2023-12-04T17:12:30.293+0000] {standard_task_runner.py:104} ERROR - Failed to execute job 112 for task query1 (250001: 250001: Could not connect to Snowflake backend after 1 attempt(s).Aborting; 1307)
[2023-12-04T17:12:30.330+0000] {local_task_job_runner.py:228} INFO - Task exited with return code 1
[2023-12-04T17:12:30.347+0000] {taskinstance.py:2776} INFO - 0 downstream tasks scheduled from follow-on schedule check
[2023-12-04T17:33:05.174+0000] {taskinstance.py:1157} INFO - Dependencies all met for dep_context=non-requeueable deps ti=<TaskInstance: Georgy.query1 scheduled__2023-11-30T21:10:00+00:00 [queued]>
[2023-12-04T17:33:05.180+0000] {taskinstance.py:1157} INFO - Dependencies all met for dep_context=requeueable deps ti=<TaskInstance: Georgy.query1 scheduled__2023-11-30T21:10:00+00:00 [queued]>
[2023-12-04T17:33:05.181+0000] {taskinstance.py:1359} INFO - Starting attempt 1 of 4
[2023-12-04T17:33:05.192+0000] {taskinstance.py:1380} INFO - Executing <Task(SnowflakeOperator): query1> on 2023-11-30 21:10:00+00:00
[2023-12-04T17:33:05.197+0000] {standard_task_runner.py:57} INFO - Started process 1633 to run task
[2023-12-04T17:33:05.201+0000] {standard_task_runner.py:84} INFO - Running: ['***', 'tasks', 'run', 'Georgy', 'query1', 'scheduled__2023-11-30T21:10:00+00:00', '--job-id', '113', '--raw', '--subdir', 'DAGS_FOLDER/test.py', '--cfg-path', '/tmp/tmpmfsj9d44']
[2023-12-04T17:33:05.202+0000] {standard_task_runner.py:85} INFO - Job 113: Subtask query1
[2023-12-04T17:33:05.253+0000] {task_command.py:415} INFO - Running <TaskInstance: Georgy.query1 scheduled__2023-11-30T21:10:00+00:00 [running]> on host 435c91f40721
[2023-12-04T17:33:05.310+0000] {taskinstance.py:1660} INFO - Exporting env vars: AIRFLOW_CTX_DAG_OWNER='Gio' AIRFLOW_CTX_DAG_ID='Georgy' AIRFLOW_CTX_TASK_ID='query1' AIRFLOW_CTX_EXECUTION_DATE='2023-11-30T21:10:00+00:00' AIRFLOW_CTX_TRY_NUMBER='1' AIRFLOW_CTX_DAG_RUN_ID='scheduled__2023-11-30T21:10:00+00:00'
[2023-12-04T17:33:05.314+0000] {sql.py:274} INFO - Executing: CREATE TABLE test (col INT);
[2023-12-04T17:33:05.327+0000] {base.py:73} INFO - Using connection ID 'snowflake_default' for task execution.
[2023-12-04T17:33:05.335+0000] {base.py:73} INFO - Using connection ID 'snowflake_default' for task execution.
[2023-12-04T17:33:05.336+0000] {connection.py:314} INFO - Snowflake Connector for Python Version: 3.1.1, Python Version: 3.8.18, Platform: Linux-5.15.133.1-microsoft-standard-WSL2-x86_64-with-glibc2.2.5
[2023-12-04T17:33:05.336+0000] {connection.py:1050} INFO - This connection is in OCSP Fail Open Mode. TLS Certificates would be checked for validity and revocation status. Any other Certificate Revocation related exceptions or OCSP Responder failures would be disregarded in favor of connectivity.
[2023-12-04T17:33:05.337+0000] {connection.py:1068} INFO - Setting use_openssl_only mode to False
[2023-12-04T17:33:06.381+0000] {connection.py:547} WARNING - Certificate did not match expected hostname: iy34150.europe-west4.snowflakecomputing.com. Certificate: {'subject': ((('commonName', '*.prod3.us-west-2.snowflakecomputing.com'),),), 'subjectAltName': [('DNS', '*.prod3.us-west-2.snowflakecomputing.com'), ('DNS', '*.us-west-2.snowflakecomputing.com'), ('DNS', '*.global.snowflakecomputing.com'), ('DNS', '*.snowflakecomputing.com'), ('DNS', '*.prod3.us-west-2.aws.snowflakecomputing.com')]}
[2023-12-04T17:33:06.382+0000] {connectionpool.py:812} WARNING - Retrying (Retry(total=0, connect=None, read=None, redirect=None, status=None)) after connection broken by 'SSLError(CertificateError("hostname 'iy34150.europe-west4.snowflakecomputing.com' doesn't match either of '*.prod3.us-west-2.snowflakecomputing.com', '*.us-west-2.snowflakecomputing.com', '*.global.snowflakecomputing.com', '*.snowflakecomputing.com', '*.prod3.us-west-2.aws.snowflakecomputing.com'"))': /session/v1/login-request?request_id=8bbcd4b7-9620-4e6f-9a29-3ea2a66b3b3f&databaseName=TASKS&schemaName=PUBLIC&warehouse=COMPUTE_WH&roleName=ACCOUNTADMIN&request_guid=26ac518c-aa6e-42c8-a6a5-4074adf3bf29
[2023-12-04T17:33:07.123+0000] {connection.py:547} WARNING - Certificate did not match expected hostname: iy34150.europe-west4.snowflakecomputing.com. Certificate: {'subject': ((('commonName', '*.prod3.us-west-2.snowflakecomputing.com'),),), 'subjectAltName': [('DNS', '*.prod3.us-west-2.snowflakecomputing.com'), ('DNS', '*.us-west-2.snowflakecomputing.com'), ('DNS', '*.global.snowflakecomputing.com'), ('DNS', '*.snowflakecomputing.com'), ('DNS', '*.prod3.us-west-2.aws.snowflakecomputing.com')]}
[2023-12-04T17:33:07.127+0000] {network.py:1037} ERROR - Failed to get the response. Hanging? method: post, url: https://iy34150.europe-west4.snowflakecomputing.com:443/session/v1/login-request?request_id=8bbcd4b7-9620-4e6f-9a29-3ea2a66b3b3f&databaseName=TASKS&schemaName=PUBLIC&warehouse=COMPUTE_WH&roleName=ACCOUNTADMIN&request_guid=26ac518c-aa6e-42c8-a6a5-4074adf3bf29, headers:{'Content-Type': 'application/json', 'accept': 'application/snowflake', 'User-Agent': 'PythonConnector/3.1.1 (Linux-5.15.133.1-microsoft-standard-WSL2-x86_64-with-glibc2.2.5) CPython/3.8.18', 'Content-Encoding': 'gzip'}, data: {"data": {"CLIENT_APP_ID": "PythonConnector", "CLIENT_APP_VERSION": "3.1.1", "SVN_REVISION": null, "ACCOUNT_NAME": "iy34150", "LOGIN_NAME": "MEDVED", "CLIENT_ENVIRONMENT": {"APPLICATION": "AIRFLOW", "OS": "Linux", "OS_VERSION": "Linux-5.15.133.1-microsoft-standard-WSL2-x86_64-with-glibc2.2.5", "PYTHON_VERSION": "3.8.18", "PYTHON_RUNTIME": "CPython", "PYTHON_COMPILER": "GCC 10.2.1 20210110", "OCSP_MODE": "FAIL_OPEN", "TRACING": 20, "LOGIN_TIMEOUT": 120, "NETWORK_TIMEOUT": null}, "PASSWORD": "**** "SESSION_PARAMETERS": {"CLIENT_PREFETCH_THREADS": 4}}}
[2023-12-04T17:33:08.887+0000] {connection.py:547} WARNING - Certificate did not match expected hostname: iy34150.europe-west4.snowflakecomputing.com. Certificate: {'subject': ((('commonName', '*.prod3.us-west-2.snowflakecomputing.com'),),), 'subjectAltName': [('DNS', '*.prod3.us-west-2.snowflakecomputing.com'), ('DNS', '*.us-west-2.snowflakecomputing.com'), ('DNS', '*.global.snowflakecomputing.com'), ('DNS', '*.snowflakecomputing.com'), ('DNS', '*.prod3.us-west-2.aws.snowflakecomputing.com')]}
[2023-12-04T17:33:08.888+0000] {connectionpool.py:812} WARNING - Retrying (Retry(total=0, connect=None, read=None, redirect=None, status=None)) after connection broken by 'SSLError(CertificateError("hostname 'iy34150.europe-west4.snowflakecomputing.com' doesn't match either of '*.prod3.us-west-2.snowflakecomputing.com', '*.us-west-2.snowflakecomputing.com', '*.global.snowflakecomputing.com', '*.snowflakecomputing.com', '*.prod3.us-west-2.aws.snowflakecomputing.com'"))': /session/v1/login-request?request_id=06b4a39c-3804-42ee-9aae-ff265178b3fb&databaseName=TASKS&schemaName=PUBLIC&warehouse=COMPUTE_WH&roleName=ACCOUNTADMIN&request_guid=a0cbdda3-3a82-4c7e-be8f-d084c5d2c706
[2023-12-04T17:33:09.626+0000] {connection.py:547} WARNING - Certificate did not match expected hostname: iy34150.europe-west4.snowflakecomputing.com. Certificate: {'subject': ((('commonName', '*.prod3.us-west-2.snowflakecomputing.com'),),), 'subjectAltName': [('DNS', '*.prod3.us-west-2.snowflakecomputing.com'), ('DNS', '*.us-west-2.snowflakecomputing.com'), ('DNS', '*.global.snowflakecomputing.com'), ('DNS', '*.snowflakecomputing.com'), ('DNS', '*.prod3.us-west-2.aws.snowflakecomputing.com')]}
[2023-12-04T17:33:09.629+0000] {network.py:1037} ERROR - Failed to get the response. Hanging? method: post, url: https://iy34150.europe-west4.snowflakecomputing.com:443/session/v1/login-request?request_id=06b4a39c-3804-42ee-9aae-ff265178b3fb&databaseName=TASKS&schemaName=PUBLIC&warehouse=COMPUTE_WH&roleName=ACCOUNTADMIN&request_guid=a0cbdda3-3a82-4c7e-be8f-d084c5d2c706, headers:{'Content-Type': 'application/json', 'accept': 'application/snowflake', 'User-Agent': 'PythonConnector/3.1.1 (Linux-5.15.133.1-microsoft-standard-WSL2-x86_64-with-glibc2.2.5) CPython/3.8.18', 'Content-Encoding': 'gzip'}, data: {"data": {"CLIENT_APP_ID": "PythonConnector", "CLIENT_APP_VERSION": "3.1.1", "SVN_REVISION": null, "ACCOUNT_NAME": "iy34150", "LOGIN_NAME": "MEDVED", "CLIENT_ENVIRONMENT": {"APPLICATION": "AIRFLOW", "OS": "Linux", "OS_VERSION": "Linux-5.15.133.1-microsoft-standard-WSL2-x86_64-with-glibc2.2.5", "PYTHON_VERSION": "3.8.18", "PYTHON_RUNTIME": "CPython", "PYTHON_COMPILER": "GCC 10.2.1 20210110", "OCSP_MODE": "FAIL_OPEN", "TRACING": 20, "LOGIN_TIMEOUT": 120, "NETWORK_TIMEOUT": null}, "PASSWORD": "**** "SESSION_PARAMETERS": {"CLIENT_PREFETCH_THREADS": 4}}}
[2023-12-04T17:33:09.631+0000] {taskinstance.py:1935} ERROR - Task failed with exception
Traceback (most recent call last):
  File "/home/airflow/.local/lib/python3.8/site-packages/snowflake/connector/connection.py", line 1193, in _authenticate
    auth.authenticate(
  File "/home/airflow/.local/lib/python3.8/site-packages/snowflake/connector/auth/_auth.py", line 250, in authenticate
    ret = self._rest._post_request(
  File "/home/airflow/.local/lib/python3.8/site-packages/snowflake/connector/network.py", line 730, in _post_request
    ret = self.fetch(
  File "/home/airflow/.local/lib/python3.8/site-packages/snowflake/connector/network.py", line 849, in fetch
    ret = self._request_exec_wrapper(
  File "/home/airflow/.local/lib/python3.8/site-packages/snowflake/connector/network.py", line 987, in _request_exec_wrapper
    raise e
  File "/home/airflow/.local/lib/python3.8/site-packages/snowflake/connector/network.py", line 902, in _request_exec_wrapper
    self._handle_unknown_error(method, full_url, headers, data, conn)
  File "/home/airflow/.local/lib/python3.8/site-packages/snowflake/connector/network.py", line 1042, in _handle_unknown_error
    Error.errorhandler_wrapper(
  File "/home/airflow/.local/lib/python3.8/site-packages/snowflake/connector/errors.py", line 290, in errorhandler_wrapper
    handed_over = Error.hand_to_other_handler(
  File "/home/airflow/.local/lib/python3.8/site-packages/snowflake/connector/errors.py", line 348, in hand_to_other_handler
    connection.errorhandler(connection, cursor, error_class, error_value)
  File "/home/airflow/.local/lib/python3.8/site-packages/snowflake/connector/errors.py", line 221, in default_errorhandler
    raise error_class(
snowflake.connector.errors.OperationalError: 250003: 250003: Failed to get the response. Hanging? method: post, url: https://iy34150.europe-west4.snowflakecomputing.com:443/session/v1/login-request?request_id=8bbcd4b7-9620-4e6f-9a29-3ea2a66b3b3f&databaseName=TASKS&schemaName=PUBLIC&warehouse=COMPUTE_WH&roleName=ACCOUNTADMIN&request_guid=26ac518c-aa6e-42c8-a6a5-4074adf3bf29

The above exception was the direct cause of the following exception:

Traceback (most recent call last):
  File "/home/airflow/.local/lib/python3.8/site-packages/airflow/providers/common/sql/operators/sql.py", line 280, in execute
    output = hook.run(
  File "/home/airflow/.local/lib/python3.8/site-packages/airflow/providers/snowflake/hooks/snowflake.py", line 409, in run
    with closing(self.get_conn()) as conn:
  File "/home/airflow/.local/lib/python3.8/site-packages/airflow/providers/snowflake/hooks/snowflake.py", line 303, in get_conn
    conn = connector.connect(**conn_config)
  File "/home/airflow/.local/lib/python3.8/site-packages/snowflake/connector/__init__.py", line 51, in Connect
    return SnowflakeConnection(**kwargs)
  File "/home/airflow/.local/lib/python3.8/site-packages/snowflake/connector/connection.py", line 353, in __init__
    self.connect(**kwargs)
  File "/home/airflow/.local/lib/python3.8/site-packages/snowflake/connector/connection.py", line 625, in connect
    self.__open_connection()
  File "/home/airflow/.local/lib/python3.8/site-packages/snowflake/connector/connection.py", line 898, in __open_connection
    self.authenticate_with_retry(self.auth_class)
  File "/home/airflow/.local/lib/python3.8/site-packages/snowflake/connector/connection.py", line 1167, in authenticate_with_retry
    self._authenticate(auth_instance)
  File "/home/airflow/.local/lib/python3.8/site-packages/snowflake/connector/connection.py", line 1238, in _authenticate
    raise auth_op from e
  File "/home/airflow/.local/lib/python3.8/site-packages/snowflake/connector/connection.py", line 1215, in _authenticate
    auth_instance.handle_timeout(
  File "/home/airflow/.local/lib/python3.8/site-packages/snowflake/connector/auth/by_plugin.py", line 219, in handle_timeout
    raise error
snowflake.connector.errors.OperationalError: 250001: 250001: Could not connect to Snowflake backend after 1 attempt(s).Aborting
[2023-12-04T17:33:09.638+0000] {taskinstance.py:1398} INFO - Marking task as UP_FOR_RETRY. dag_id=Georgy, task_id=query1, execution_date=20231130T211000, start_date=20231204T173305, end_date=20231204T173309
[2023-12-04T17:33:09.650+0000] {standard_task_runner.py:104} ERROR - Failed to execute job 113 for task query1 (250001: 250001: Could not connect to Snowflake backend after 1 attempt(s).Aborting; 1633)
[2023-12-04T17:33:09.666+0000] {local_task_job_runner.py:228} INFO - Task exited with return code 1
[2023-12-04T17:33:09.685+0000] {taskinstance.py:2776} INFO - 0 downstream tasks scheduled from follow-on schedule check
[2023-12-04T17:37:23.152+0000] {taskinstance.py:1157} INFO - Dependencies all met for dep_context=non-requeueable deps ti=<TaskInstance: Georgy.query1 scheduled__2023-11-30T21:10:00+00:00 [queued]>
[2023-12-04T17:37:23.159+0000] {taskinstance.py:1157} INFO - Dependencies all met for dep_context=requeueable deps ti=<TaskInstance: Georgy.query1 scheduled__2023-11-30T21:10:00+00:00 [queued]>
[2023-12-04T17:37:23.159+0000] {taskinstance.py:1359} INFO - Starting attempt 1 of 4
[2023-12-04T17:37:23.173+0000] {taskinstance.py:1380} INFO - Executing <Task(SnowflakeOperator): query1> on 2023-11-30 21:10:00+00:00
[2023-12-04T17:37:23.179+0000] {standard_task_runner.py:57} INFO - Started process 1703 to run task
[2023-12-04T17:37:23.183+0000] {standard_task_runner.py:84} INFO - Running: ['***', 'tasks', 'run', 'Georgy', 'query1', 'scheduled__2023-11-30T21:10:00+00:00', '--job-id', '114', '--raw', '--subdir', 'DAGS_FOLDER/test.py', '--cfg-path', '/tmp/tmpfwbfe4d9']
[2023-12-04T17:37:23.184+0000] {standard_task_runner.py:85} INFO - Job 114: Subtask query1
[2023-12-04T17:37:23.229+0000] {task_command.py:415} INFO - Running <TaskInstance: Georgy.query1 scheduled__2023-11-30T21:10:00+00:00 [running]> on host 435c91f40721
[2023-12-04T17:37:23.299+0000] {taskinstance.py:1660} INFO - Exporting env vars: AIRFLOW_CTX_DAG_OWNER='Gio' AIRFLOW_CTX_DAG_ID='Georgy' AIRFLOW_CTX_TASK_ID='query1' AIRFLOW_CTX_EXECUTION_DATE='2023-11-30T21:10:00+00:00' AIRFLOW_CTX_TRY_NUMBER='1' AIRFLOW_CTX_DAG_RUN_ID='scheduled__2023-11-30T21:10:00+00:00'
[2023-12-04T17:37:23.300+0000] {sql.py:274} INFO - Executing: CREATE TABLE test (col INT);
[2023-12-04T17:37:23.312+0000] {base.py:73} INFO - Using connection ID 'snowflake_default' for task execution.
[2023-12-04T17:37:23.319+0000] {base.py:73} INFO - Using connection ID 'snowflake_default' for task execution.
[2023-12-04T17:37:23.319+0000] {connection.py:314} INFO - Snowflake Connector for Python Version: 3.1.1, Python Version: 3.8.18, Platform: Linux-5.15.133.1-microsoft-standard-WSL2-x86_64-with-glibc2.2.5
[2023-12-04T17:37:23.320+0000] {connection.py:1050} INFO - This connection is in OCSP Fail Open Mode. TLS Certificates would be checked for validity and revocation status. Any other Certificate Revocation related exceptions or OCSP Responder failures would be disregarded in favor of connectivity.
[2023-12-04T17:37:23.321+0000] {connection.py:1068} INFO - Setting use_openssl_only mode to False
[2023-12-04T17:37:24.336+0000] {connection.py:547} WARNING - Certificate did not match expected hostname: iy34150.europe-west4.snowflakecomputing.com. Certificate: {'subject': ((('commonName', '*.prod3.us-west-2.snowflakecomputing.com'),),), 'subjectAltName': [('DNS', '*.prod3.us-west-2.snowflakecomputing.com'), ('DNS', '*.us-west-2.snowflakecomputing.com'), ('DNS', '*.global.snowflakecomputing.com'), ('DNS', '*.snowflakecomputing.com'), ('DNS', '*.prod3.us-west-2.aws.snowflakecomputing.com')]}
[2023-12-04T17:37:24.337+0000] {connectionpool.py:812} WARNING - Retrying (Retry(total=0, connect=None, read=None, redirect=None, status=None)) after connection broken by 'SSLError(CertificateError("hostname 'iy34150.europe-west4.snowflakecomputing.com' doesn't match either of '*.prod3.us-west-2.snowflakecomputing.com', '*.us-west-2.snowflakecomputing.com', '*.global.snowflakecomputing.com', '*.snowflakecomputing.com', '*.prod3.us-west-2.aws.snowflakecomputing.com'"))': /session/v1/login-request?request_id=d64ccd56-68ba-43f8-bfd2-b934e1655448&databaseName=tasks&schemaName=public&warehouse=COMPUTE_WH&roleName=ACCOUNTADMIN&request_guid=5f2e12db-bf68-4362-a0f1-63bcc03c8a72
[2023-12-04T17:37:25.080+0000] {connection.py:547} WARNING - Certificate did not match expected hostname: iy34150.europe-west4.snowflakecomputing.com. Certificate: {'subject': ((('commonName', '*.prod3.us-west-2.snowflakecomputing.com'),),), 'subjectAltName': [('DNS', '*.prod3.us-west-2.snowflakecomputing.com'), ('DNS', '*.us-west-2.snowflakecomputing.com'), ('DNS', '*.global.snowflakecomputing.com'), ('DNS', '*.snowflakecomputing.com'), ('DNS', '*.prod3.us-west-2.aws.snowflakecomputing.com')]}
[2023-12-04T17:37:25.084+0000] {network.py:1037} ERROR - Failed to get the response. Hanging? method: post, url: https://iy34150.europe-west4.snowflakecomputing.com:443/session/v1/login-request?request_id=d64ccd56-68ba-43f8-bfd2-b934e1655448&databaseName=tasks&schemaName=public&warehouse=COMPUTE_WH&roleName=ACCOUNTADMIN&request_guid=5f2e12db-bf68-4362-a0f1-63bcc03c8a72, headers:{'Content-Type': 'application/json', 'accept': 'application/snowflake', 'User-Agent': 'PythonConnector/3.1.1 (Linux-5.15.133.1-microsoft-standard-WSL2-x86_64-with-glibc2.2.5) CPython/3.8.18', 'Content-Encoding': 'gzip'}, data: {"data": {"CLIENT_APP_ID": "PythonConnector", "CLIENT_APP_VERSION": "3.1.1", "SVN_REVISION": null, "ACCOUNT_NAME": "iy34150", "LOGIN_NAME": "MEDVED", "CLIENT_ENVIRONMENT": {"APPLICATION": "AIRFLOW", "OS": "Linux", "OS_VERSION": "Linux-5.15.133.1-microsoft-standard-WSL2-x86_64-with-glibc2.2.5", "PYTHON_VERSION": "3.8.18", "PYTHON_RUNTIME": "CPython", "PYTHON_COMPILER": "GCC 10.2.1 20210110", "OCSP_MODE": "FAIL_OPEN", "TRACING": 20, "LOGIN_TIMEOUT": 120, "NETWORK_TIMEOUT": null}, "PASSWORD": "**** "SESSION_PARAMETERS": {"CLIENT_PREFETCH_THREADS": 4}}}
[2023-12-04T17:37:29.617+0000] {connection.py:547} WARNING - Certificate did not match expected hostname: iy34150.europe-west4.snowflakecomputing.com. Certificate: {'subject': ((('commonName', '*.prod3.us-west-2.snowflakecomputing.com'),),), 'subjectAltName': [('DNS', '*.prod3.us-west-2.snowflakecomputing.com'), ('DNS', '*.us-west-2.snowflakecomputing.com'), ('DNS', '*.global.snowflakecomputing.com'), ('DNS', '*.snowflakecomputing.com'), ('DNS', '*.prod3.us-west-2.aws.snowflakecomputing.com')]}
[2023-12-04T17:37:29.618+0000] {connectionpool.py:812} WARNING - Retrying (Retry(total=0, connect=None, read=None, redirect=None, status=None)) after connection broken by 'SSLError(CertificateError("hostname 'iy34150.europe-west4.snowflakecomputing.com' doesn't match either of '*.prod3.us-west-2.snowflakecomputing.com', '*.us-west-2.snowflakecomputing.com', '*.global.snowflakecomputing.com', '*.snowflakecomputing.com', '*.prod3.us-west-2.aws.snowflakecomputing.com'"))': /session/v1/login-request?request_id=95fc0a16-e667-478d-ae7f-dadcfe689eee&databaseName=tasks&schemaName=public&warehouse=COMPUTE_WH&roleName=ACCOUNTADMIN&request_guid=27633cea-d563-4827-a5c4-9ee80716ebb6
[2023-12-04T17:37:30.360+0000] {connection.py:547} WARNING - Certificate did not match expected hostname: iy34150.europe-west4.snowflakecomputing.com. Certificate: {'subject': ((('commonName', '*.prod3.us-west-2.snowflakecomputing.com'),),), 'subjectAltName': [('DNS', '*.prod3.us-west-2.snowflakecomputing.com'), ('DNS', '*.us-west-2.snowflakecomputing.com'), ('DNS', '*.global.snowflakecomputing.com'), ('DNS', '*.snowflakecomputing.com'), ('DNS', '*.prod3.us-west-2.aws.snowflakecomputing.com')]}
[2023-12-04T17:37:30.362+0000] {network.py:1037} ERROR - Failed to get the response. Hanging? method: post, url: https://iy34150.europe-west4.snowflakecomputing.com:443/session/v1/login-request?request_id=95fc0a16-e667-478d-ae7f-dadcfe689eee&databaseName=tasks&schemaName=public&warehouse=COMPUTE_WH&roleName=ACCOUNTADMIN&request_guid=27633cea-d563-4827-a5c4-9ee80716ebb6, headers:{'Content-Type': 'application/json', 'accept': 'application/snowflake', 'User-Agent': 'PythonConnector/3.1.1 (Linux-5.15.133.1-microsoft-standard-WSL2-x86_64-with-glibc2.2.5) CPython/3.8.18', 'Content-Encoding': 'gzip'}, data: {"data": {"CLIENT_APP_ID": "PythonConnector", "CLIENT_APP_VERSION": "3.1.1", "SVN_REVISION": null, "ACCOUNT_NAME": "iy34150", "LOGIN_NAME": "MEDVED", "CLIENT_ENVIRONMENT": {"APPLICATION": "AIRFLOW", "OS": "Linux", "OS_VERSION": "Linux-5.15.133.1-microsoft-standard-WSL2-x86_64-with-glibc2.2.5", "PYTHON_VERSION": "3.8.18", "PYTHON_RUNTIME": "CPython", "PYTHON_COMPILER": "GCC 10.2.1 20210110", "OCSP_MODE": "FAIL_OPEN", "TRACING": 20, "LOGIN_TIMEOUT": 120, "NETWORK_TIMEOUT": null}, "PASSWORD": "**** "SESSION_PARAMETERS": {"CLIENT_PREFETCH_THREADS": 4}}}
[2023-12-04T17:37:30.364+0000] {taskinstance.py:1935} ERROR - Task failed with exception
Traceback (most recent call last):
  File "/home/airflow/.local/lib/python3.8/site-packages/snowflake/connector/connection.py", line 1193, in _authenticate
    auth.authenticate(
  File "/home/airflow/.local/lib/python3.8/site-packages/snowflake/connector/auth/_auth.py", line 250, in authenticate
    ret = self._rest._post_request(
  File "/home/airflow/.local/lib/python3.8/site-packages/snowflake/connector/network.py", line 730, in _post_request
    ret = self.fetch(
  File "/home/airflow/.local/lib/python3.8/site-packages/snowflake/connector/network.py", line 849, in fetch
    ret = self._request_exec_wrapper(
  File "/home/airflow/.local/lib/python3.8/site-packages/snowflake/connector/network.py", line 987, in _request_exec_wrapper
    raise e
  File "/home/airflow/.local/lib/python3.8/site-packages/snowflake/connector/network.py", line 902, in _request_exec_wrapper
    self._handle_unknown_error(method, full_url, headers, data, conn)
  File "/home/airflow/.local/lib/python3.8/site-packages/snowflake/connector/network.py", line 1042, in _handle_unknown_error
    Error.errorhandler_wrapper(
  File "/home/airflow/.local/lib/python3.8/site-packages/snowflake/connector/errors.py", line 290, in errorhandler_wrapper
    handed_over = Error.hand_to_other_handler(
  File "/home/airflow/.local/lib/python3.8/site-packages/snowflake/connector/errors.py", line 348, in hand_to_other_handler
    connection.errorhandler(connection, cursor, error_class, error_value)
  File "/home/airflow/.local/lib/python3.8/site-packages/snowflake/connector/errors.py", line 221, in default_errorhandler
    raise error_class(
snowflake.connector.errors.OperationalError: 250003: 250003: Failed to get the response. Hanging? method: post, url: https://iy34150.europe-west4.snowflakecomputing.com:443/session/v1/login-request?request_id=d64ccd56-68ba-43f8-bfd2-b934e1655448&databaseName=tasks&schemaName=public&warehouse=COMPUTE_WH&roleName=ACCOUNTADMIN&request_guid=5f2e12db-bf68-4362-a0f1-63bcc03c8a72

The above exception was the direct cause of the following exception:

Traceback (most recent call last):
  File "/home/airflow/.local/lib/python3.8/site-packages/airflow/providers/common/sql/operators/sql.py", line 280, in execute
    output = hook.run(
  File "/home/airflow/.local/lib/python3.8/site-packages/airflow/providers/snowflake/hooks/snowflake.py", line 409, in run
    with closing(self.get_conn()) as conn:
  File "/home/airflow/.local/lib/python3.8/site-packages/airflow/providers/snowflake/hooks/snowflake.py", line 303, in get_conn
    conn = connector.connect(**conn_config)
  File "/home/airflow/.local/lib/python3.8/site-packages/snowflake/connector/__init__.py", line 51, in Connect
    return SnowflakeConnection(**kwargs)
  File "/home/airflow/.local/lib/python3.8/site-packages/snowflake/connector/connection.py", line 353, in __init__
    self.connect(**kwargs)
  File "/home/airflow/.local/lib/python3.8/site-packages/snowflake/connector/connection.py", line 625, in connect
    self.__open_connection()
  File "/home/airflow/.local/lib/python3.8/site-packages/snowflake/connector/connection.py", line 898, in __open_connection
    self.authenticate_with_retry(self.auth_class)
  File "/home/airflow/.local/lib/python3.8/site-packages/snowflake/connector/connection.py", line 1167, in authenticate_with_retry
    self._authenticate(auth_instance)
  File "/home/airflow/.local/lib/python3.8/site-packages/snowflake/connector/connection.py", line 1238, in _authenticate
    raise auth_op from e
  File "/home/airflow/.local/lib/python3.8/site-packages/snowflake/connector/connection.py", line 1215, in _authenticate
    auth_instance.handle_timeout(
  File "/home/airflow/.local/lib/python3.8/site-packages/snowflake/connector/auth/by_plugin.py", line 219, in handle_timeout
    raise error
snowflake.connector.errors.OperationalError: 250001: 250001: Could not connect to Snowflake backend after 1 attempt(s).Aborting
[2023-12-04T17:37:30.371+0000] {taskinstance.py:1398} INFO - Marking task as UP_FOR_RETRY. dag_id=Georgy, task_id=query1, execution_date=20231130T211000, start_date=20231204T173723, end_date=20231204T173730
[2023-12-04T17:37:30.381+0000] {standard_task_runner.py:104} ERROR - Failed to execute job 114 for task query1 (250001: 250001: Could not connect to Snowflake backend after 1 attempt(s).Aborting; 1703)
[2023-12-04T17:37:30.403+0000] {local_task_job_runner.py:228} INFO - Task exited with return code 1
[2023-12-04T17:37:30.419+0000] {taskinstance.py:2776} INFO - 0 downstream tasks scheduled from follow-on schedule check
[2023-12-04T17:40:28.495+0000] {taskinstance.py:1157} INFO - Dependencies all met for dep_context=non-requeueable deps ti=<TaskInstance: Georgy.query1 scheduled__2023-11-30T21:10:00+00:00 [queued]>
[2023-12-04T17:40:28.502+0000] {taskinstance.py:1157} INFO - Dependencies all met for dep_context=requeueable deps ti=<TaskInstance: Georgy.query1 scheduled__2023-11-30T21:10:00+00:00 [queued]>
[2023-12-04T17:40:28.502+0000] {taskinstance.py:1359} INFO - Starting attempt 1 of 4
[2023-12-04T17:40:28.513+0000] {taskinstance.py:1380} INFO - Executing <Task(SnowflakeOperator): query1> on 2023-11-30 21:10:00+00:00
[2023-12-04T17:40:28.518+0000] {standard_task_runner.py:57} INFO - Started process 1758 to run task
[2023-12-04T17:40:28.521+0000] {standard_task_runner.py:84} INFO - Running: ['***', 'tasks', 'run', 'Georgy', 'query1', 'scheduled__2023-11-30T21:10:00+00:00', '--job-id', '115', '--raw', '--subdir', 'DAGS_FOLDER/test.py', '--cfg-path', '/tmp/tmp4oxmgs53']
[2023-12-04T17:40:28.521+0000] {standard_task_runner.py:85} INFO - Job 115: Subtask query1
[2023-12-04T17:40:28.558+0000] {task_command.py:415} INFO - Running <TaskInstance: Georgy.query1 scheduled__2023-11-30T21:10:00+00:00 [running]> on host 435c91f40721
[2023-12-04T17:40:28.613+0000] {taskinstance.py:1660} INFO - Exporting env vars: AIRFLOW_CTX_DAG_OWNER='Gio' AIRFLOW_CTX_DAG_ID='Georgy' AIRFLOW_CTX_TASK_ID='query1' AIRFLOW_CTX_EXECUTION_DATE='2023-11-30T21:10:00+00:00' AIRFLOW_CTX_TRY_NUMBER='1' AIRFLOW_CTX_DAG_RUN_ID='scheduled__2023-11-30T21:10:00+00:00'
[2023-12-04T17:40:28.614+0000] {sql.py:274} INFO - Executing: CREATE TABLE test (col INT);
[2023-12-04T17:40:28.632+0000] {base.py:73} INFO - Using connection ID 'snowflake_default' for task execution.
[2023-12-04T17:40:28.647+0000] {base.py:73} INFO - Using connection ID 'snowflake_default' for task execution.
[2023-12-04T17:40:28.649+0000] {connection.py:314} INFO - Snowflake Connector for Python Version: 3.1.1, Python Version: 3.8.18, Platform: Linux-5.15.133.1-microsoft-standard-WSL2-x86_64-with-glibc2.2.5
[2023-12-04T17:40:28.651+0000] {connection.py:1050} INFO - This connection is in OCSP Fail Open Mode. TLS Certificates would be checked for validity and revocation status. Any other Certificate Revocation related exceptions or OCSP Responder failures would be disregarded in favor of connectivity.
[2023-12-04T17:40:28.652+0000] {connection.py:1068} INFO - Setting use_openssl_only mode to False
[2023-12-04T17:40:29.662+0000] {connection.py:547} WARNING - Certificate did not match expected hostname: iy34150.europe-west4.snowflakecomputing.com. Certificate: {'subject': ((('commonName', '*.prod3.us-west-2.snowflakecomputing.com'),),), 'subjectAltName': [('DNS', '*.prod3.us-west-2.snowflakecomputing.com'), ('DNS', '*.us-west-2.snowflakecomputing.com'), ('DNS', '*.global.snowflakecomputing.com'), ('DNS', '*.snowflakecomputing.com'), ('DNS', '*.prod3.us-west-2.aws.snowflakecomputing.com')]}
[2023-12-04T17:40:29.663+0000] {connectionpool.py:812} WARNING - Retrying (Retry(total=0, connect=None, read=None, redirect=None, status=None)) after connection broken by 'SSLError(CertificateError("hostname 'iy34150.europe-west4.snowflakecomputing.com' doesn't match either of '*.prod3.us-west-2.snowflakecomputing.com', '*.us-west-2.snowflakecomputing.com', '*.global.snowflakecomputing.com', '*.snowflakecomputing.com', '*.prod3.us-west-2.aws.snowflakecomputing.com'"))': /session/v1/login-request?request_id=e0172039-4519-473f-95fd-eaf354caf181&databaseName=tasks&schemaName=public&warehouse=COMPUTE_WH&roleName=ACCOUNTADMIN&request_guid=cd5156d8-c675-4044-921f-bfbb058e70a8
[2023-12-04T17:40:30.422+0000] {connection.py:547} WARNING - Certificate did not match expected hostname: iy34150.europe-west4.snowflakecomputing.com. Certificate: {'subject': ((('commonName', '*.prod3.us-west-2.snowflakecomputing.com'),),), 'subjectAltName': [('DNS', '*.prod3.us-west-2.snowflakecomputing.com'), ('DNS', '*.us-west-2.snowflakecomputing.com'), ('DNS', '*.global.snowflakecomputing.com'), ('DNS', '*.snowflakecomputing.com'), ('DNS', '*.prod3.us-west-2.aws.snowflakecomputing.com')]}
[2023-12-04T17:40:30.425+0000] {network.py:1037} ERROR - Failed to get the response. Hanging? method: post, url: https://iy34150.europe-west4.snowflakecomputing.com:443/session/v1/login-request?request_id=e0172039-4519-473f-95fd-eaf354caf181&databaseName=tasks&schemaName=public&warehouse=COMPUTE_WH&roleName=ACCOUNTADMIN&request_guid=cd5156d8-c675-4044-921f-bfbb058e70a8, headers:{'Content-Type': 'application/json', 'accept': 'application/snowflake', 'User-Agent': 'PythonConnector/3.1.1 (Linux-5.15.133.1-microsoft-standard-WSL2-x86_64-with-glibc2.2.5) CPython/3.8.18', 'Content-Encoding': 'gzip'}, data: {"data": {"CLIENT_APP_ID": "PythonConnector", "CLIENT_APP_VERSION": "3.1.1", "SVN_REVISION": null, "ACCOUNT_NAME": "iy34150", "LOGIN_NAME": "MEDVED", "CLIENT_ENVIRONMENT": {"APPLICATION": "AIRFLOW", "OS": "Linux", "OS_VERSION": "Linux-5.15.133.1-microsoft-standard-WSL2-x86_64-with-glibc2.2.5", "PYTHON_VERSION": "3.8.18", "PYTHON_RUNTIME": "CPython", "PYTHON_COMPILER": "GCC 10.2.1 20210110", "OCSP_MODE": "FAIL_OPEN", "TRACING": 20, "LOGIN_TIMEOUT": 120, "NETWORK_TIMEOUT": null}, "PASSWORD": "**** "SESSION_PARAMETERS": {"CLIENT_PREFETCH_THREADS": 4}}}
[2023-12-04T17:40:34.175+0000] {connection.py:547} WARNING - Certificate did not match expected hostname: iy34150.europe-west4.snowflakecomputing.com. Certificate: {'subject': ((('commonName', '*.prod3.us-west-2.snowflakecomputing.com'),),), 'subjectAltName': [('DNS', '*.prod3.us-west-2.snowflakecomputing.com'), ('DNS', '*.us-west-2.snowflakecomputing.com'), ('DNS', '*.global.snowflakecomputing.com'), ('DNS', '*.snowflakecomputing.com'), ('DNS', '*.prod3.us-west-2.aws.snowflakecomputing.com')]}
[2023-12-04T17:40:34.176+0000] {connectionpool.py:812} WARNING - Retrying (Retry(total=0, connect=None, read=None, redirect=None, status=None)) after connection broken by 'SSLError(CertificateError("hostname 'iy34150.europe-west4.snowflakecomputing.com' doesn't match either of '*.prod3.us-west-2.snowflakecomputing.com', '*.us-west-2.snowflakecomputing.com', '*.global.snowflakecomputing.com', '*.snowflakecomputing.com', '*.prod3.us-west-2.aws.snowflakecomputing.com'"))': /session/v1/login-request?request_id=4ddcfc5d-d36c-4fa3-8333-c550979359a1&databaseName=tasks&schemaName=public&warehouse=COMPUTE_WH&roleName=ACCOUNTADMIN&request_guid=70637b28-d4c2-42e1-bf19-03de8bee26fb
[2023-12-04T17:40:34.918+0000] {connection.py:547} WARNING - Certificate did not match expected hostname: iy34150.europe-west4.snowflakecomputing.com. Certificate: {'subject': ((('commonName', '*.prod3.us-west-2.snowflakecomputing.com'),),), 'subjectAltName': [('DNS', '*.prod3.us-west-2.snowflakecomputing.com'), ('DNS', '*.us-west-2.snowflakecomputing.com'), ('DNS', '*.global.snowflakecomputing.com'), ('DNS', '*.snowflakecomputing.com'), ('DNS', '*.prod3.us-west-2.aws.snowflakecomputing.com')]}
[2023-12-04T17:40:34.921+0000] {network.py:1037} ERROR - Failed to get the response. Hanging? method: post, url: https://iy34150.europe-west4.snowflakecomputing.com:443/session/v1/login-request?request_id=4ddcfc5d-d36c-4fa3-8333-c550979359a1&databaseName=tasks&schemaName=public&warehouse=COMPUTE_WH&roleName=ACCOUNTADMIN&request_guid=70637b28-d4c2-42e1-bf19-03de8bee26fb, headers:{'Content-Type': 'application/json', 'accept': 'application/snowflake', 'User-Agent': 'PythonConnector/3.1.1 (Linux-5.15.133.1-microsoft-standard-WSL2-x86_64-with-glibc2.2.5) CPython/3.8.18', 'Content-Encoding': 'gzip'}, data: {"data": {"CLIENT_APP_ID": "PythonConnector", "CLIENT_APP_VERSION": "3.1.1", "SVN_REVISION": null, "ACCOUNT_NAME": "iy34150", "LOGIN_NAME": "MEDVED", "CLIENT_ENVIRONMENT": {"APPLICATION": "AIRFLOW", "OS": "Linux", "OS_VERSION": "Linux-5.15.133.1-microsoft-standard-WSL2-x86_64-with-glibc2.2.5", "PYTHON_VERSION": "3.8.18", "PYTHON_RUNTIME": "CPython", "PYTHON_COMPILER": "GCC 10.2.1 20210110", "OCSP_MODE": "FAIL_OPEN", "TRACING": 20, "LOGIN_TIMEOUT": 120, "NETWORK_TIMEOUT": null}, "PASSWORD": "**** "SESSION_PARAMETERS": {"CLIENT_PREFETCH_THREADS": 4}}}
[2023-12-04T17:40:34.923+0000] {taskinstance.py:1935} ERROR - Task failed with exception
Traceback (most recent call last):
  File "/home/airflow/.local/lib/python3.8/site-packages/snowflake/connector/connection.py", line 1193, in _authenticate
    auth.authenticate(
  File "/home/airflow/.local/lib/python3.8/site-packages/snowflake/connector/auth/_auth.py", line 250, in authenticate
    ret = self._rest._post_request(
  File "/home/airflow/.local/lib/python3.8/site-packages/snowflake/connector/network.py", line 730, in _post_request
    ret = self.fetch(
  File "/home/airflow/.local/lib/python3.8/site-packages/snowflake/connector/network.py", line 849, in fetch
    ret = self._request_exec_wrapper(
  File "/home/airflow/.local/lib/python3.8/site-packages/snowflake/connector/network.py", line 987, in _request_exec_wrapper
    raise e
  File "/home/airflow/.local/lib/python3.8/site-packages/snowflake/connector/network.py", line 902, in _request_exec_wrapper
    self._handle_unknown_error(method, full_url, headers, data, conn)
  File "/home/airflow/.local/lib/python3.8/site-packages/snowflake/connector/network.py", line 1042, in _handle_unknown_error
    Error.errorhandler_wrapper(
  File "/home/airflow/.local/lib/python3.8/site-packages/snowflake/connector/errors.py", line 290, in errorhandler_wrapper
    handed_over = Error.hand_to_other_handler(
  File "/home/airflow/.local/lib/python3.8/site-packages/snowflake/connector/errors.py", line 348, in hand_to_other_handler
    connection.errorhandler(connection, cursor, error_class, error_value)
  File "/home/airflow/.local/lib/python3.8/site-packages/snowflake/connector/errors.py", line 221, in default_errorhandler
    raise error_class(
snowflake.connector.errors.OperationalError: 250003: 250003: Failed to get the response. Hanging? method: post, url: https://iy34150.europe-west4.snowflakecomputing.com:443/session/v1/login-request?request_id=e0172039-4519-473f-95fd-eaf354caf181&databaseName=tasks&schemaName=public&warehouse=COMPUTE_WH&roleName=ACCOUNTADMIN&request_guid=cd5156d8-c675-4044-921f-bfbb058e70a8

The above exception was the direct cause of the following exception:

Traceback (most recent call last):
  File "/home/airflow/.local/lib/python3.8/site-packages/airflow/providers/common/sql/operators/sql.py", line 280, in execute
    output = hook.run(
  File "/home/airflow/.local/lib/python3.8/site-packages/airflow/providers/snowflake/hooks/snowflake.py", line 409, in run
    with closing(self.get_conn()) as conn:
  File "/home/airflow/.local/lib/python3.8/site-packages/airflow/providers/snowflake/hooks/snowflake.py", line 303, in get_conn
    conn = connector.connect(**conn_config)
  File "/home/airflow/.local/lib/python3.8/site-packages/snowflake/connector/__init__.py", line 51, in Connect
    return SnowflakeConnection(**kwargs)
  File "/home/airflow/.local/lib/python3.8/site-packages/snowflake/connector/connection.py", line 353, in __init__
    self.connect(**kwargs)
  File "/home/airflow/.local/lib/python3.8/site-packages/snowflake/connector/connection.py", line 625, in connect
    self.__open_connection()
  File "/home/airflow/.local/lib/python3.8/site-packages/snowflake/connector/connection.py", line 898, in __open_connection
    self.authenticate_with_retry(self.auth_class)
  File "/home/airflow/.local/lib/python3.8/site-packages/snowflake/connector/connection.py", line 1167, in authenticate_with_retry
    self._authenticate(auth_instance)
  File "/home/airflow/.local/lib/python3.8/site-packages/snowflake/connector/connection.py", line 1238, in _authenticate
    raise auth_op from e
  File "/home/airflow/.local/lib/python3.8/site-packages/snowflake/connector/connection.py", line 1215, in _authenticate
    auth_instance.handle_timeout(
  File "/home/airflow/.local/lib/python3.8/site-packages/snowflake/connector/auth/by_plugin.py", line 219, in handle_timeout
    raise error
snowflake.connector.errors.OperationalError: 250001: 250001: Could not connect to Snowflake backend after 1 attempt(s).Aborting
[2023-12-04T17:40:34.929+0000] {taskinstance.py:1398} INFO - Marking task as UP_FOR_RETRY. dag_id=Georgy, task_id=query1, execution_date=20231130T211000, start_date=20231204T174028, end_date=20231204T174034
[2023-12-04T17:40:34.941+0000] {standard_task_runner.py:104} ERROR - Failed to execute job 115 for task query1 (250001: 250001: Could not connect to Snowflake backend after 1 attempt(s).Aborting; 1758)
[2023-12-04T17:40:34.948+0000] {local_task_job_runner.py:228} INFO - Task exited with return code 1
[2023-12-04T17:40:34.966+0000] {taskinstance.py:2776} INFO - 0 downstream tasks scheduled from follow-on schedule check
[2023-12-04T17:45:39.749+0000] {taskinstance.py:1157} INFO - Dependencies all met for dep_context=non-requeueable deps ti=<TaskInstance: Georgy.query1 scheduled__2023-11-30T21:10:00+00:00 [queued]>
[2023-12-04T17:45:39.756+0000] {taskinstance.py:1157} INFO - Dependencies all met for dep_context=requeueable deps ti=<TaskInstance: Georgy.query1 scheduled__2023-11-30T21:10:00+00:00 [queued]>
[2023-12-04T17:45:39.756+0000] {taskinstance.py:1359} INFO - Starting attempt 1 of 4
[2023-12-04T17:45:39.769+0000] {taskinstance.py:1380} INFO - Executing <Task(SnowflakeOperator): query1> on 2023-11-30 21:10:00+00:00
[2023-12-04T17:45:39.774+0000] {standard_task_runner.py:57} INFO - Started process 1844 to run task
[2023-12-04T17:45:39.777+0000] {standard_task_runner.py:84} INFO - Running: ['***', 'tasks', 'run', 'Georgy', 'query1', 'scheduled__2023-11-30T21:10:00+00:00', '--job-id', '116', '--raw', '--subdir', 'DAGS_FOLDER/test.py', '--cfg-path', '/tmp/tmp3v0jab4d']
[2023-12-04T17:45:39.778+0000] {standard_task_runner.py:85} INFO - Job 116: Subtask query1
[2023-12-04T17:45:39.813+0000] {task_command.py:415} INFO - Running <TaskInstance: Georgy.query1 scheduled__2023-11-30T21:10:00+00:00 [running]> on host 435c91f40721
[2023-12-04T17:45:39.870+0000] {taskinstance.py:1660} INFO - Exporting env vars: AIRFLOW_CTX_DAG_OWNER='Gio' AIRFLOW_CTX_DAG_ID='Georgy' AIRFLOW_CTX_TASK_ID='query1' AIRFLOW_CTX_EXECUTION_DATE='2023-11-30T21:10:00+00:00' AIRFLOW_CTX_TRY_NUMBER='1' AIRFLOW_CTX_DAG_RUN_ID='scheduled__2023-11-30T21:10:00+00:00'
[2023-12-04T17:45:39.871+0000] {sql.py:274} INFO - Executing: Select '1';
[2023-12-04T17:45:39.881+0000] {base.py:73} INFO - Using connection ID 'snowflake_default' for task execution.
[2023-12-04T17:45:39.889+0000] {base.py:73} INFO - Using connection ID 'snowflake_default' for task execution.
[2023-12-04T17:45:39.889+0000] {connection.py:314} INFO - Snowflake Connector for Python Version: 3.1.1, Python Version: 3.8.18, Platform: Linux-5.15.133.1-microsoft-standard-WSL2-x86_64-with-glibc2.2.5
[2023-12-04T17:45:39.890+0000] {connection.py:1050} INFO - This connection is in OCSP Fail Open Mode. TLS Certificates would be checked for validity and revocation status. Any other Certificate Revocation related exceptions or OCSP Responder failures would be disregarded in favor of connectivity.
[2023-12-04T17:45:39.890+0000] {connection.py:1068} INFO - Setting use_openssl_only mode to False
[2023-12-04T17:45:40.880+0000] {connection.py:547} WARNING - Certificate did not match expected hostname: iy34150.europe-west4.snowflakecomputing.com. Certificate: {'subject': ((('commonName', '*.prod3.us-west-2.snowflakecomputing.com'),),), 'subjectAltName': [('DNS', '*.prod3.us-west-2.snowflakecomputing.com'), ('DNS', '*.us-west-2.snowflakecomputing.com'), ('DNS', '*.global.snowflakecomputing.com'), ('DNS', '*.snowflakecomputing.com'), ('DNS', '*.prod3.us-west-2.aws.snowflakecomputing.com')]}
[2023-12-04T17:45:40.882+0000] {connectionpool.py:812} WARNING - Retrying (Retry(total=0, connect=None, read=None, redirect=None, status=None)) after connection broken by 'SSLError(CertificateError("hostname 'iy34150.europe-west4.snowflakecomputing.com' doesn't match either of '*.prod3.us-west-2.snowflakecomputing.com', '*.us-west-2.snowflakecomputing.com', '*.global.snowflakecomputing.com', '*.snowflakecomputing.com', '*.prod3.us-west-2.aws.snowflakecomputing.com'"))': /session/v1/login-request?request_id=bdb5e023-bfd6-4d23-bd17-c82d4050f6d2&databaseName=tasks&schemaName=public&warehouse=COMPUTE_WH&roleName=ACCOUNTADMIN&request_guid=a0b80efc-9b32-4331-94c6-ba887bc0175d
[2023-12-04T17:45:41.624+0000] {connection.py:547} WARNING - Certificate did not match expected hostname: iy34150.europe-west4.snowflakecomputing.com. Certificate: {'subject': ((('commonName', '*.prod3.us-west-2.snowflakecomputing.com'),),), 'subjectAltName': [('DNS', '*.prod3.us-west-2.snowflakecomputing.com'), ('DNS', '*.us-west-2.snowflakecomputing.com'), ('DNS', '*.global.snowflakecomputing.com'), ('DNS', '*.snowflakecomputing.com'), ('DNS', '*.prod3.us-west-2.aws.snowflakecomputing.com')]}
[2023-12-04T17:45:41.628+0000] {network.py:1037} ERROR - Failed to get the response. Hanging? method: post, url: https://iy34150.europe-west4.snowflakecomputing.com:443/session/v1/login-request?request_id=bdb5e023-bfd6-4d23-bd17-c82d4050f6d2&databaseName=tasks&schemaName=public&warehouse=COMPUTE_WH&roleName=ACCOUNTADMIN&request_guid=a0b80efc-9b32-4331-94c6-ba887bc0175d, headers:{'Content-Type': 'application/json', 'accept': 'application/snowflake', 'User-Agent': 'PythonConnector/3.1.1 (Linux-5.15.133.1-microsoft-standard-WSL2-x86_64-with-glibc2.2.5) CPython/3.8.18', 'Content-Encoding': 'gzip'}, data: {"data": {"CLIENT_APP_ID": "PythonConnector", "CLIENT_APP_VERSION": "3.1.1", "SVN_REVISION": null, "ACCOUNT_NAME": "iy34150", "LOGIN_NAME": "MEDVED", "CLIENT_ENVIRONMENT": {"APPLICATION": "AIRFLOW", "OS": "Linux", "OS_VERSION": "Linux-5.15.133.1-microsoft-standard-WSL2-x86_64-with-glibc2.2.5", "PYTHON_VERSION": "3.8.18", "PYTHON_RUNTIME": "CPython", "PYTHON_COMPILER": "GCC 10.2.1 20210110", "OCSP_MODE": "FAIL_OPEN", "TRACING": 20, "LOGIN_TIMEOUT": 120, "NETWORK_TIMEOUT": null}, "PASSWORD": "**** "SESSION_PARAMETERS": {"CLIENT_PREFETCH_THREADS": 4}}}
[2023-12-04T17:45:44.378+0000] {connection.py:547} WARNING - Certificate did not match expected hostname: iy34150.europe-west4.snowflakecomputing.com. Certificate: {'subject': ((('commonName', '*.prod3.us-west-2.snowflakecomputing.com'),),), 'subjectAltName': [('DNS', '*.prod3.us-west-2.snowflakecomputing.com'), ('DNS', '*.us-west-2.snowflakecomputing.com'), ('DNS', '*.global.snowflakecomputing.com'), ('DNS', '*.snowflakecomputing.com'), ('DNS', '*.prod3.us-west-2.aws.snowflakecomputing.com')]}
[2023-12-04T17:45:44.378+0000] {connectionpool.py:812} WARNING - Retrying (Retry(total=0, connect=None, read=None, redirect=None, status=None)) after connection broken by 'SSLError(CertificateError("hostname 'iy34150.europe-west4.snowflakecomputing.com' doesn't match either of '*.prod3.us-west-2.snowflakecomputing.com', '*.us-west-2.snowflakecomputing.com', '*.global.snowflakecomputing.com', '*.snowflakecomputing.com', '*.prod3.us-west-2.aws.snowflakecomputing.com'"))': /session/v1/login-request?request_id=9925558d-dd87-481b-afc2-857f4ce29db7&databaseName=tasks&schemaName=public&warehouse=COMPUTE_WH&roleName=ACCOUNTADMIN&request_guid=ab5b75c0-8f99-4478-b322-cbbf598c50e5
[2023-12-04T17:45:45.125+0000] {connection.py:547} WARNING - Certificate did not match expected hostname: iy34150.europe-west4.snowflakecomputing.com. Certificate: {'subject': ((('commonName', '*.prod3.us-west-2.snowflakecomputing.com'),),), 'subjectAltName': [('DNS', '*.prod3.us-west-2.snowflakecomputing.com'), ('DNS', '*.us-west-2.snowflakecomputing.com'), ('DNS', '*.global.snowflakecomputing.com'), ('DNS', '*.snowflakecomputing.com'), ('DNS', '*.prod3.us-west-2.aws.snowflakecomputing.com')]}
[2023-12-04T17:45:45.127+0000] {network.py:1037} ERROR - Failed to get the response. Hanging? method: post, url: https://iy34150.europe-west4.snowflakecomputing.com:443/session/v1/login-request?request_id=9925558d-dd87-481b-afc2-857f4ce29db7&databaseName=tasks&schemaName=public&warehouse=COMPUTE_WH&roleName=ACCOUNTADMIN&request_guid=ab5b75c0-8f99-4478-b322-cbbf598c50e5, headers:{'Content-Type': 'application/json', 'accept': 'application/snowflake', 'User-Agent': 'PythonConnector/3.1.1 (Linux-5.15.133.1-microsoft-standard-WSL2-x86_64-with-glibc2.2.5) CPython/3.8.18', 'Content-Encoding': 'gzip'}, data: {"data": {"CLIENT_APP_ID": "PythonConnector", "CLIENT_APP_VERSION": "3.1.1", "SVN_REVISION": null, "ACCOUNT_NAME": "iy34150", "LOGIN_NAME": "MEDVED", "CLIENT_ENVIRONMENT": {"APPLICATION": "AIRFLOW", "OS": "Linux", "OS_VERSION": "Linux-5.15.133.1-microsoft-standard-WSL2-x86_64-with-glibc2.2.5", "PYTHON_VERSION": "3.8.18", "PYTHON_RUNTIME": "CPython", "PYTHON_COMPILER": "GCC 10.2.1 20210110", "OCSP_MODE": "FAIL_OPEN", "TRACING": 20, "LOGIN_TIMEOUT": 120, "NETWORK_TIMEOUT": null}, "PASSWORD": "**** "SESSION_PARAMETERS": {"CLIENT_PREFETCH_THREADS": 4}}}
[2023-12-04T17:45:45.129+0000] {taskinstance.py:1935} ERROR - Task failed with exception
Traceback (most recent call last):
  File "/home/airflow/.local/lib/python3.8/site-packages/snowflake/connector/connection.py", line 1193, in _authenticate
    auth.authenticate(
  File "/home/airflow/.local/lib/python3.8/site-packages/snowflake/connector/auth/_auth.py", line 250, in authenticate
    ret = self._rest._post_request(
  File "/home/airflow/.local/lib/python3.8/site-packages/snowflake/connector/network.py", line 730, in _post_request
    ret = self.fetch(
  File "/home/airflow/.local/lib/python3.8/site-packages/snowflake/connector/network.py", line 849, in fetch
    ret = self._request_exec_wrapper(
  File "/home/airflow/.local/lib/python3.8/site-packages/snowflake/connector/network.py", line 987, in _request_exec_wrapper
    raise e
  File "/home/airflow/.local/lib/python3.8/site-packages/snowflake/connector/network.py", line 902, in _request_exec_wrapper
    self._handle_unknown_error(method, full_url, headers, data, conn)
  File "/home/airflow/.local/lib/python3.8/site-packages/snowflake/connector/network.py", line 1042, in _handle_unknown_error
    Error.errorhandler_wrapper(
  File "/home/airflow/.local/lib/python3.8/site-packages/snowflake/connector/errors.py", line 290, in errorhandler_wrapper
    handed_over = Error.hand_to_other_handler(
  File "/home/airflow/.local/lib/python3.8/site-packages/snowflake/connector/errors.py", line 348, in hand_to_other_handler
    connection.errorhandler(connection, cursor, error_class, error_value)
  File "/home/airflow/.local/lib/python3.8/site-packages/snowflake/connector/errors.py", line 221, in default_errorhandler
    raise error_class(
snowflake.connector.errors.OperationalError: 250003: 250003: Failed to get the response. Hanging? method: post, url: https://iy34150.europe-west4.snowflakecomputing.com:443/session/v1/login-request?request_id=bdb5e023-bfd6-4d23-bd17-c82d4050f6d2&databaseName=tasks&schemaName=public&warehouse=COMPUTE_WH&roleName=ACCOUNTADMIN&request_guid=a0b80efc-9b32-4331-94c6-ba887bc0175d

The above exception was the direct cause of the following exception:

Traceback (most recent call last):
  File "/home/airflow/.local/lib/python3.8/site-packages/airflow/providers/common/sql/operators/sql.py", line 280, in execute
    output = hook.run(
  File "/home/airflow/.local/lib/python3.8/site-packages/airflow/providers/snowflake/hooks/snowflake.py", line 409, in run
    with closing(self.get_conn()) as conn:
  File "/home/airflow/.local/lib/python3.8/site-packages/airflow/providers/snowflake/hooks/snowflake.py", line 303, in get_conn
    conn = connector.connect(**conn_config)
  File "/home/airflow/.local/lib/python3.8/site-packages/snowflake/connector/__init__.py", line 51, in Connect
    return SnowflakeConnection(**kwargs)
  File "/home/airflow/.local/lib/python3.8/site-packages/snowflake/connector/connection.py", line 353, in __init__
    self.connect(**kwargs)
  File "/home/airflow/.local/lib/python3.8/site-packages/snowflake/connector/connection.py", line 625, in connect
    self.__open_connection()
  File "/home/airflow/.local/lib/python3.8/site-packages/snowflake/connector/connection.py", line 898, in __open_connection
    self.authenticate_with_retry(self.auth_class)
  File "/home/airflow/.local/lib/python3.8/site-packages/snowflake/connector/connection.py", line 1167, in authenticate_with_retry
    self._authenticate(auth_instance)
  File "/home/airflow/.local/lib/python3.8/site-packages/snowflake/connector/connection.py", line 1238, in _authenticate
    raise auth_op from e
  File "/home/airflow/.local/lib/python3.8/site-packages/snowflake/connector/connection.py", line 1215, in _authenticate
    auth_instance.handle_timeout(
  File "/home/airflow/.local/lib/python3.8/site-packages/snowflake/connector/auth/by_plugin.py", line 219, in handle_timeout
    raise error
snowflake.connector.errors.OperationalError: 250001: 250001: Could not connect to Snowflake backend after 1 attempt(s).Aborting
[2023-12-04T17:45:45.135+0000] {taskinstance.py:1398} INFO - Marking task as UP_FOR_RETRY. dag_id=Georgy, task_id=query1, execution_date=20231130T211000, start_date=20231204T174539, end_date=20231204T174545
[2023-12-04T17:45:45.145+0000] {standard_task_runner.py:104} ERROR - Failed to execute job 116 for task query1 (250001: 250001: Could not connect to Snowflake backend after 1 attempt(s).Aborting; 1844)
[2023-12-04T17:45:45.157+0000] {local_task_job_runner.py:228} INFO - Task exited with return code 1
[2023-12-04T17:45:45.173+0000] {taskinstance.py:2776} INFO - 0 downstream tasks scheduled from follow-on schedule check
[2023-12-04T21:33:11.120+0000] {taskinstance.py:1157} INFO - Dependencies all met for dep_context=non-requeueable deps ti=<TaskInstance: Georgy.query1 scheduled__2023-11-30T21:10:00+00:00 [queued]>
[2023-12-04T21:33:11.126+0000] {taskinstance.py:1157} INFO - Dependencies all met for dep_context=requeueable deps ti=<TaskInstance: Georgy.query1 scheduled__2023-11-30T21:10:00+00:00 [queued]>
[2023-12-04T21:33:11.126+0000] {taskinstance.py:1359} INFO - Starting attempt 1 of 4
[2023-12-04T21:33:11.136+0000] {taskinstance.py:1380} INFO - Executing <Task(SnowflakeOperator): query1> on 2023-11-30 21:10:00+00:00
[2023-12-04T21:33:11.142+0000] {standard_task_runner.py:57} INFO - Started process 62 to run task
[2023-12-04T21:33:11.143+0000] {taskinstance.py:1147} INFO - Dependencies not met for <TaskInstance: Georgy.query1 scheduled__2023-11-30T21:10:00+00:00 [running]>, dependency 'Task Instance State' FAILED: Task is in the 'running' state.
[2023-12-04T21:33:11.144+0000] {taskinstance.py:1147} INFO - Dependencies not met for <TaskInstance: Georgy.query1 scheduled__2023-11-30T21:10:00+00:00 [running]>, dependency 'Task Instance Not Running' FAILED: Task is in the running state
[2023-12-04T21:33:11.147+0000] {local_task_job_runner.py:154} INFO - Task is not able to be run
[2023-12-04T21:33:11.150+0000] {standard_task_runner.py:84} INFO - Running: ['***', 'tasks', 'run', 'Georgy', 'query1', 'scheduled__2023-11-30T21:10:00+00:00', '--job-id', '152', '--raw', '--subdir', 'DAGS_FOLDER/test.py', '--cfg-path', '/tmp/tmpa2_ydg30']
[2023-12-04T21:33:11.151+0000] {standard_task_runner.py:85} INFO - Job 152: Subtask query1
[2023-12-04T21:33:11.195+0000] {task_command.py:415} INFO - Running <TaskInstance: Georgy.query1 scheduled__2023-11-30T21:10:00+00:00 [running]> on host 435c91f40721
[2023-12-04T21:33:11.253+0000] {taskinstance.py:1660} INFO - Exporting env vars: AIRFLOW_CTX_DAG_OWNER='Gio' AIRFLOW_CTX_DAG_ID='Georgy' AIRFLOW_CTX_TASK_ID='query1' AIRFLOW_CTX_EXECUTION_DATE='2023-11-30T21:10:00+00:00' AIRFLOW_CTX_TRY_NUMBER='1' AIRFLOW_CTX_DAG_RUN_ID='scheduled__2023-11-30T21:10:00+00:00'
[2023-12-04T21:33:11.254+0000] {sql.py:274} INFO - Executing: SELECT current_date;
[2023-12-04T21:33:11.269+0000] {taskinstance.py:1935} ERROR - Task failed with exception
Traceback (most recent call last):
  File "/home/airflow/.local/lib/python3.8/site-packages/airflow/providers/common/sql/operators/sql.py", line 275, in execute
    hook = self.get_db_hook()
  File "/home/airflow/.local/lib/python3.8/site-packages/airflow/providers/common/sql/operators/sql.py", line 186, in get_db_hook
    return self._hook
  File "/usr/local/lib/python3.8/functools.py", line 967, in __get__
    val = self.func(instance)
  File "/home/airflow/.local/lib/python3.8/site-packages/airflow/providers/common/sql/operators/sql.py", line 148, in _hook
    conn = BaseHook.get_connection(conn_id)
  File "/home/airflow/.local/lib/python3.8/site-packages/airflow/hooks/base.py", line 72, in get_connection
    conn = Connection.get_connection_from_secrets(conn_id)
  File "/home/airflow/.local/lib/python3.8/site-packages/airflow/models/connection.py", line 477, in get_connection_from_secrets
    raise AirflowNotFoundException(f"The conn_id `{conn_id}` isn't defined")
airflow.exceptions.AirflowNotFoundException: The conn_id `snowflake_default` isn't defined
[2023-12-04T21:33:11.274+0000] {taskinstance.py:1398} INFO - Marking task as UP_FOR_RETRY. dag_id=Georgy, task_id=query1, execution_date=20231130T211000, start_date=20231204T213311, end_date=20231204T213311
[2023-12-04T21:33:11.284+0000] {standard_task_runner.py:104} ERROR - Failed to execute job 152 for task query1 (The conn_id `snowflake_default` isn't defined; 62)
[2023-12-04T21:33:11.317+0000] {local_task_job_runner.py:228} INFO - Task exited with return code 1
[2023-12-04T21:33:11.343+0000] {taskinstance.py:2776} INFO - 0 downstream tasks scheduled from follow-on schedule check
[2023-12-04T21:33:53.955+0000] {taskinstance.py:1157} INFO - Dependencies all met for dep_context=non-requeueable deps ti=<TaskInstance: Georgy.query1 scheduled__2023-11-30T21:10:00+00:00 [queued]>
[2023-12-04T21:33:53.961+0000] {taskinstance.py:1157} INFO - Dependencies all met for dep_context=requeueable deps ti=<TaskInstance: Georgy.query1 scheduled__2023-11-30T21:10:00+00:00 [queued]>
[2023-12-04T21:33:53.961+0000] {taskinstance.py:1359} INFO - Starting attempt 1 of 4
[2023-12-04T21:33:53.972+0000] {taskinstance.py:1380} INFO - Executing <Task(SnowflakeOperator): query1> on 2023-11-30 21:10:00+00:00
[2023-12-04T21:33:53.976+0000] {standard_task_runner.py:57} INFO - Started process 74 to run task
[2023-12-04T21:33:53.979+0000] {standard_task_runner.py:84} INFO - Running: ['***', 'tasks', 'run', 'Georgy', 'query1', 'scheduled__2023-11-30T21:10:00+00:00', '--job-id', '153', '--raw', '--subdir', 'DAGS_FOLDER/test.py', '--cfg-path', '/tmp/tmpyhbn9wmp']
[2023-12-04T21:33:53.980+0000] {standard_task_runner.py:85} INFO - Job 153: Subtask query1
[2023-12-04T21:33:54.017+0000] {task_command.py:415} INFO - Running <TaskInstance: Georgy.query1 scheduled__2023-11-30T21:10:00+00:00 [running]> on host 435c91f40721
[2023-12-04T21:33:54.071+0000] {taskinstance.py:1660} INFO - Exporting env vars: AIRFLOW_CTX_DAG_OWNER='Gio' AIRFLOW_CTX_DAG_ID='Georgy' AIRFLOW_CTX_TASK_ID='query1' AIRFLOW_CTX_EXECUTION_DATE='2023-11-30T21:10:00+00:00' AIRFLOW_CTX_TRY_NUMBER='1' AIRFLOW_CTX_DAG_RUN_ID='scheduled__2023-11-30T21:10:00+00:00'
[2023-12-04T21:33:54.072+0000] {sql.py:274} INFO - Executing: SELECT current_date;
[2023-12-04T21:33:54.080+0000] {base.py:73} INFO - Using connection ID 'snowflake' for task execution.
[2023-12-04T21:33:54.087+0000] {base.py:73} INFO - Using connection ID 'snowflake' for task execution.
[2023-12-04T21:33:54.087+0000] {connection.py:314} INFO - Snowflake Connector for Python Version: 3.1.1, Python Version: 3.8.18, Platform: Linux-5.15.133.1-microsoft-standard-WSL2-x86_64-with-glibc2.2.5
[2023-12-04T21:33:54.088+0000] {connection.py:1050} INFO - This connection is in OCSP Fail Open Mode. TLS Certificates would be checked for validity and revocation status. Any other Certificate Revocation related exceptions or OCSP Responder failures would be disregarded in favor of connectivity.
[2023-12-04T21:33:54.088+0000] {connection.py:1068} INFO - Setting use_openssl_only mode to False
[2023-12-04T21:33:55.528+0000] {taskinstance.py:1935} ERROR - Task failed with exception
Traceback (most recent call last):
  File "/home/airflow/.local/lib/python3.8/site-packages/snowflake/connector/auth/_auth.py", line 250, in authenticate
    ret = self._rest._post_request(
  File "/home/airflow/.local/lib/python3.8/site-packages/snowflake/connector/network.py", line 730, in _post_request
    ret = self.fetch(
  File "/home/airflow/.local/lib/python3.8/site-packages/snowflake/connector/network.py", line 849, in fetch
    ret = self._request_exec_wrapper(
  File "/home/airflow/.local/lib/python3.8/site-packages/snowflake/connector/network.py", line 987, in _request_exec_wrapper
    raise e
  File "/home/airflow/.local/lib/python3.8/site-packages/snowflake/connector/network.py", line 891, in _request_exec_wrapper
    return_object = self._request_exec(
  File "/home/airflow/.local/lib/python3.8/site-packages/snowflake/connector/network.py", line 1189, in _request_exec
    raise err
  File "/home/airflow/.local/lib/python3.8/site-packages/snowflake/connector/network.py", line 1110, in _request_exec
    raise ForbiddenError
snowflake.connector.errors.ForbiddenError: HTTP 403: Forbidden

During handling of the above exception, another exception occurred:

Traceback (most recent call last):
  File "/home/airflow/.local/lib/python3.8/site-packages/airflow/providers/common/sql/operators/sql.py", line 280, in execute
    output = hook.run(
  File "/home/airflow/.local/lib/python3.8/site-packages/airflow/providers/snowflake/hooks/snowflake.py", line 409, in run
    with closing(self.get_conn()) as conn:
  File "/home/airflow/.local/lib/python3.8/site-packages/airflow/providers/snowflake/hooks/snowflake.py", line 303, in get_conn
    conn = connector.connect(**conn_config)
  File "/home/airflow/.local/lib/python3.8/site-packages/snowflake/connector/__init__.py", line 51, in Connect
    return SnowflakeConnection(**kwargs)
  File "/home/airflow/.local/lib/python3.8/site-packages/snowflake/connector/connection.py", line 353, in __init__
    self.connect(**kwargs)
  File "/home/airflow/.local/lib/python3.8/site-packages/snowflake/connector/connection.py", line 625, in connect
    self.__open_connection()
  File "/home/airflow/.local/lib/python3.8/site-packages/snowflake/connector/connection.py", line 898, in __open_connection
    self.authenticate_with_retry(self.auth_class)
  File "/home/airflow/.local/lib/python3.8/site-packages/snowflake/connector/connection.py", line 1167, in authenticate_with_retry
    self._authenticate(auth_instance)
  File "/home/airflow/.local/lib/python3.8/site-packages/snowflake/connector/connection.py", line 1193, in _authenticate
    auth.authenticate(
  File "/home/airflow/.local/lib/python3.8/site-packages/snowflake/connector/auth/_auth.py", line 259, in authenticate
    raise err.__class__(
snowflake.connector.errors.ForbiddenError: 250001 (08001): None: Failed to connect to DB. Verify the account name is correct: iy34150.snowflakecomputing.com:443. HTTP 403: Forbidden
[2023-12-04T21:33:55.535+0000] {taskinstance.py:1398} INFO - Marking task as UP_FOR_RETRY. dag_id=Georgy, task_id=query1, execution_date=20231130T211000, start_date=20231204T213353, end_date=20231204T213355
[2023-12-04T21:33:55.549+0000] {standard_task_runner.py:104} ERROR - Failed to execute job 153 for task query1 (250001 (08001): None: Failed to connect to DB. Verify the account name is correct: iy34150.snowflakecomputing.com:443. HTTP 403: Forbidden; 74)
[2023-12-04T21:33:55.595+0000] {local_task_job_runner.py:228} INFO - Task exited with return code 1
[2023-12-04T21:33:55.620+0000] {taskinstance.py:2776} INFO - 0 downstream tasks scheduled from follow-on schedule check
[2023-12-04T21:37:41.781+0000] {taskinstance.py:1157} INFO - Dependencies all met for dep_context=non-requeueable deps ti=<TaskInstance: Georgy.query1 scheduled__2023-11-30T21:10:00+00:00 [queued]>
[2023-12-04T21:37:41.788+0000] {taskinstance.py:1157} INFO - Dependencies all met for dep_context=requeueable deps ti=<TaskInstance: Georgy.query1 scheduled__2023-11-30T21:10:00+00:00 [queued]>
[2023-12-04T21:37:41.789+0000] {taskinstance.py:1359} INFO - Starting attempt 1 of 4
[2023-12-04T21:37:41.801+0000] {taskinstance.py:1380} INFO - Executing <Task(SnowflakeOperator): query1> on 2023-11-30 21:10:00+00:00
[2023-12-04T21:37:41.807+0000] {standard_task_runner.py:57} INFO - Started process 143 to run task
[2023-12-04T21:37:41.810+0000] {standard_task_runner.py:84} INFO - Running: ['***', 'tasks', 'run', 'Georgy', 'query1', 'scheduled__2023-11-30T21:10:00+00:00', '--job-id', '154', '--raw', '--subdir', 'DAGS_FOLDER/test.py', '--cfg-path', '/tmp/tmp7vxcd937']
[2023-12-04T21:37:41.812+0000] {standard_task_runner.py:85} INFO - Job 154: Subtask query1
[2023-12-04T21:37:41.855+0000] {task_command.py:415} INFO - Running <TaskInstance: Georgy.query1 scheduled__2023-11-30T21:10:00+00:00 [running]> on host 435c91f40721
[2023-12-04T21:37:41.914+0000] {taskinstance.py:1660} INFO - Exporting env vars: AIRFLOW_CTX_DAG_OWNER='Gio' AIRFLOW_CTX_DAG_ID='Georgy' AIRFLOW_CTX_TASK_ID='query1' AIRFLOW_CTX_EXECUTION_DATE='2023-11-30T21:10:00+00:00' AIRFLOW_CTX_TRY_NUMBER='1' AIRFLOW_CTX_DAG_RUN_ID='scheduled__2023-11-30T21:10:00+00:00'
[2023-12-04T21:37:41.915+0000] {sql.py:274} INFO - Executing: SELECT current_date;
[2023-12-04T21:37:41.924+0000] {base.py:73} INFO - Using connection ID 'snowflake' for task execution.
[2023-12-04T21:37:41.931+0000] {base.py:73} INFO - Using connection ID 'snowflake' for task execution.
[2023-12-04T21:37:41.932+0000] {connection.py:314} INFO - Snowflake Connector for Python Version: 3.1.1, Python Version: 3.8.18, Platform: Linux-5.15.133.1-microsoft-standard-WSL2-x86_64-with-glibc2.2.5
[2023-12-04T21:37:41.933+0000] {connection.py:1050} INFO - This connection is in OCSP Fail Open Mode. TLS Certificates would be checked for validity and revocation status. Any other Certificate Revocation related exceptions or OCSP Responder failures would be disregarded in favor of connectivity.
[2023-12-04T21:37:41.933+0000] {connection.py:1068} INFO - Setting use_openssl_only mode to False
[2023-12-04T21:37:43.181+0000] {taskinstance.py:1935} ERROR - Task failed with exception
Traceback (most recent call last):
  File "/home/airflow/.local/lib/python3.8/site-packages/snowflake/connector/auth/_auth.py", line 250, in authenticate
    ret = self._rest._post_request(
  File "/home/airflow/.local/lib/python3.8/site-packages/snowflake/connector/network.py", line 730, in _post_request
    ret = self.fetch(
  File "/home/airflow/.local/lib/python3.8/site-packages/snowflake/connector/network.py", line 849, in fetch
    ret = self._request_exec_wrapper(
  File "/home/airflow/.local/lib/python3.8/site-packages/snowflake/connector/network.py", line 987, in _request_exec_wrapper
    raise e
  File "/home/airflow/.local/lib/python3.8/site-packages/snowflake/connector/network.py", line 891, in _request_exec_wrapper
    return_object = self._request_exec(
  File "/home/airflow/.local/lib/python3.8/site-packages/snowflake/connector/network.py", line 1189, in _request_exec
    raise err
  File "/home/airflow/.local/lib/python3.8/site-packages/snowflake/connector/network.py", line 1110, in _request_exec
    raise ForbiddenError
snowflake.connector.errors.ForbiddenError: HTTP 403: Forbidden

During handling of the above exception, another exception occurred:

Traceback (most recent call last):
  File "/home/airflow/.local/lib/python3.8/site-packages/airflow/providers/common/sql/operators/sql.py", line 280, in execute
    output = hook.run(
  File "/home/airflow/.local/lib/python3.8/site-packages/airflow/providers/snowflake/hooks/snowflake.py", line 409, in run
    with closing(self.get_conn()) as conn:
  File "/home/airflow/.local/lib/python3.8/site-packages/airflow/providers/snowflake/hooks/snowflake.py", line 303, in get_conn
    conn = connector.connect(**conn_config)
  File "/home/airflow/.local/lib/python3.8/site-packages/snowflake/connector/__init__.py", line 51, in Connect
    return SnowflakeConnection(**kwargs)
  File "/home/airflow/.local/lib/python3.8/site-packages/snowflake/connector/connection.py", line 353, in __init__
    self.connect(**kwargs)
  File "/home/airflow/.local/lib/python3.8/site-packages/snowflake/connector/connection.py", line 625, in connect
    self.__open_connection()
  File "/home/airflow/.local/lib/python3.8/site-packages/snowflake/connector/connection.py", line 898, in __open_connection
    self.authenticate_with_retry(self.auth_class)
  File "/home/airflow/.local/lib/python3.8/site-packages/snowflake/connector/connection.py", line 1167, in authenticate_with_retry
    self._authenticate(auth_instance)
  File "/home/airflow/.local/lib/python3.8/site-packages/snowflake/connector/connection.py", line 1193, in _authenticate
    auth.authenticate(
  File "/home/airflow/.local/lib/python3.8/site-packages/snowflake/connector/auth/_auth.py", line 259, in authenticate
    raise err.__class__(
snowflake.connector.errors.ForbiddenError: 250001 (08001): None: Failed to connect to DB. Verify the account name is correct: iy34150.snowflakecomputing.com:443. HTTP 403: Forbidden
[2023-12-04T21:37:43.188+0000] {taskinstance.py:1398} INFO - Marking task as UP_FOR_RETRY. dag_id=Georgy, task_id=query1, execution_date=20231130T211000, start_date=20231204T213741, end_date=20231204T213743
[2023-12-04T21:37:43.199+0000] {standard_task_runner.py:104} ERROR - Failed to execute job 154 for task query1 (250001 (08001): None: Failed to connect to DB. Verify the account name is correct: iy34150.snowflakecomputing.com:443. HTTP 403: Forbidden; 143)
[2023-12-04T21:37:43.228+0000] {local_task_job_runner.py:228} INFO - Task exited with return code 1
[2023-12-04T21:37:43.247+0000] {taskinstance.py:2776} INFO - 0 downstream tasks scheduled from follow-on schedule check
[2023-12-04T22:12:09.496+0000] {taskinstance.py:1157} INFO - Dependencies all met for dep_context=non-requeueable deps ti=<TaskInstance: Georgy.query1 scheduled__2023-11-30T21:10:00+00:00 [queued]>
[2023-12-04T22:12:09.502+0000] {taskinstance.py:1157} INFO - Dependencies all met for dep_context=requeueable deps ti=<TaskInstance: Georgy.query1 scheduled__2023-11-30T21:10:00+00:00 [queued]>
[2023-12-04T22:12:09.502+0000] {taskinstance.py:1359} INFO - Starting attempt 1 of 4
[2023-12-04T22:12:09.513+0000] {taskinstance.py:1380} INFO - Executing <Task(PythonOperator): query1> on 2023-11-30 21:10:00+00:00
[2023-12-04T22:12:09.517+0000] {standard_task_runner.py:57} INFO - Started process 670 to run task
[2023-12-04T22:12:09.521+0000] {standard_task_runner.py:84} INFO - Running: ['***', 'tasks', 'run', 'Georgy', 'query1', 'scheduled__2023-11-30T21:10:00+00:00', '--job-id', '155', '--raw', '--subdir', 'DAGS_FOLDER/test.py', '--cfg-path', '/tmp/tmpb3tcmplw']
[2023-12-04T22:12:09.521+0000] {standard_task_runner.py:85} INFO - Job 155: Subtask query1
[2023-12-04T22:12:09.557+0000] {task_command.py:415} INFO - Running <TaskInstance: Georgy.query1 scheduled__2023-11-30T21:10:00+00:00 [running]> on host 435c91f40721
[2023-12-04T22:12:09.608+0000] {taskinstance.py:1660} INFO - Exporting env vars: AIRFLOW_CTX_DAG_OWNER='Gio' AIRFLOW_CTX_DAG_ID='Georgy' AIRFLOW_CTX_TASK_ID='query1' AIRFLOW_CTX_EXECUTION_DATE='2023-11-30T21:10:00+00:00' AIRFLOW_CTX_TRY_NUMBER='1' AIRFLOW_CTX_DAG_RUN_ID='scheduled__2023-11-30T21:10:00+00:00'
[2023-12-04T22:12:09.618+0000] {base.py:73} INFO - Using connection ID 'snowflake' for task execution.
[2023-12-04T22:12:09.618+0000] {connection.py:314} INFO - Snowflake Connector for Python Version: 3.1.1, Python Version: 3.8.18, Platform: Linux-5.15.133.1-microsoft-standard-WSL2-x86_64-with-glibc2.2.5
[2023-12-04T22:12:09.619+0000] {connection.py:1050} INFO - This connection is in OCSP Fail Open Mode. TLS Certificates would be checked for validity and revocation status. Any other Certificate Revocation related exceptions or OCSP Responder failures would be disregarded in favor of connectivity.
[2023-12-04T22:12:09.619+0000] {connection.py:1068} INFO - Setting use_openssl_only mode to False
[2023-12-04T22:12:10.941+0000] {taskinstance.py:1935} ERROR - Task failed with exception
Traceback (most recent call last):
  File "/home/airflow/.local/lib/python3.8/site-packages/snowflake/connector/auth/_auth.py", line 250, in authenticate
    ret = self._rest._post_request(
  File "/home/airflow/.local/lib/python3.8/site-packages/snowflake/connector/network.py", line 730, in _post_request
    ret = self.fetch(
  File "/home/airflow/.local/lib/python3.8/site-packages/snowflake/connector/network.py", line 849, in fetch
    ret = self._request_exec_wrapper(
  File "/home/airflow/.local/lib/python3.8/site-packages/snowflake/connector/network.py", line 987, in _request_exec_wrapper
    raise e
  File "/home/airflow/.local/lib/python3.8/site-packages/snowflake/connector/network.py", line 891, in _request_exec_wrapper
    return_object = self._request_exec(
  File "/home/airflow/.local/lib/python3.8/site-packages/snowflake/connector/network.py", line 1189, in _request_exec
    raise err
  File "/home/airflow/.local/lib/python3.8/site-packages/snowflake/connector/network.py", line 1110, in _request_exec
    raise ForbiddenError
snowflake.connector.errors.ForbiddenError: HTTP 403: Forbidden

During handling of the above exception, another exception occurred:

Traceback (most recent call last):
  File "/home/airflow/.local/lib/python3.8/site-packages/airflow/operators/python.py", line 192, in execute
    return_value = self.execute_callable()
  File "/home/airflow/.local/lib/python3.8/site-packages/airflow/operators/python.py", line 209, in execute_callable
    return self.python_callable(*self.op_args, **self.op_kwargs)
  File "/opt/airflow/dags/test.py", line 25, in execute_query
    conn = hook.get_conn()
  File "/home/airflow/.local/lib/python3.8/site-packages/airflow/providers/snowflake/hooks/snowflake.py", line 303, in get_conn
    conn = connector.connect(**conn_config)
  File "/home/airflow/.local/lib/python3.8/site-packages/snowflake/connector/__init__.py", line 51, in Connect
    return SnowflakeConnection(**kwargs)
  File "/home/airflow/.local/lib/python3.8/site-packages/snowflake/connector/connection.py", line 353, in __init__
    self.connect(**kwargs)
  File "/home/airflow/.local/lib/python3.8/site-packages/snowflake/connector/connection.py", line 625, in connect
    self.__open_connection()
  File "/home/airflow/.local/lib/python3.8/site-packages/snowflake/connector/connection.py", line 898, in __open_connection
    self.authenticate_with_retry(self.auth_class)
  File "/home/airflow/.local/lib/python3.8/site-packages/snowflake/connector/connection.py", line 1167, in authenticate_with_retry
    self._authenticate(auth_instance)
  File "/home/airflow/.local/lib/python3.8/site-packages/snowflake/connector/connection.py", line 1193, in _authenticate
    auth.authenticate(
  File "/home/airflow/.local/lib/python3.8/site-packages/snowflake/connector/auth/_auth.py", line 259, in authenticate
    raise err.__class__(
snowflake.connector.errors.ForbiddenError: 250001 (08001): None: Failed to connect to DB. Verify the account name is correct: iy34150.snowflakecomputing.com:443. HTTP 403: Forbidden
[2023-12-04T22:12:10.948+0000] {taskinstance.py:1398} INFO - Marking task as UP_FOR_RETRY. dag_id=Georgy, task_id=query1, execution_date=20231130T211000, start_date=20231204T221209, end_date=20231204T221210
[2023-12-04T22:12:10.958+0000] {standard_task_runner.py:104} ERROR - Failed to execute job 155 for task query1 (250001 (08001): None: Failed to connect to DB. Verify the account name is correct: iy34150.snowflakecomputing.com:443. HTTP 403: Forbidden; 670)
[2023-12-04T22:12:10.977+0000] {local_task_job_runner.py:228} INFO - Task exited with return code 1
[2023-12-04T22:12:10.994+0000] {taskinstance.py:2776} INFO - 0 downstream tasks scheduled from follow-on schedule check
[2023-12-04T22:19:10.986+0000] {taskinstance.py:1157} INFO - Dependencies all met for dep_context=non-requeueable deps ti=<TaskInstance: Georgy.query1 scheduled__2023-11-30T21:10:00+00:00 [queued]>
[2023-12-04T22:19:10.993+0000] {taskinstance.py:1157} INFO - Dependencies all met for dep_context=requeueable deps ti=<TaskInstance: Georgy.query1 scheduled__2023-11-30T21:10:00+00:00 [queued]>
[2023-12-04T22:19:10.993+0000] {taskinstance.py:1359} INFO - Starting attempt 1 of 4
[2023-12-04T22:19:11.004+0000] {taskinstance.py:1380} INFO - Executing <Task(PythonOperator): query1> on 2023-11-30 21:10:00+00:00
[2023-12-04T22:19:11.008+0000] {standard_task_runner.py:57} INFO - Started process 788 to run task
[2023-12-04T22:19:11.010+0000] {standard_task_runner.py:84} INFO - Running: ['***', 'tasks', 'run', 'Georgy', 'query1', 'scheduled__2023-11-30T21:10:00+00:00', '--job-id', '156', '--raw', '--subdir', 'DAGS_FOLDER/test.py', '--cfg-path', '/tmp/tmp_hje0u03']
[2023-12-04T22:19:11.011+0000] {standard_task_runner.py:85} INFO - Job 156: Subtask query1
[2023-12-04T22:19:11.044+0000] {task_command.py:415} INFO - Running <TaskInstance: Georgy.query1 scheduled__2023-11-30T21:10:00+00:00 [running]> on host 435c91f40721
[2023-12-04T22:19:11.094+0000] {taskinstance.py:1660} INFO - Exporting env vars: AIRFLOW_CTX_DAG_OWNER='Gio' AIRFLOW_CTX_DAG_ID='Georgy' AIRFLOW_CTX_TASK_ID='query1' AIRFLOW_CTX_EXECUTION_DATE='2023-11-30T21:10:00+00:00' AIRFLOW_CTX_TRY_NUMBER='1' AIRFLOW_CTX_DAG_RUN_ID='scheduled__2023-11-30T21:10:00+00:00'
[2023-12-04T22:19:11.103+0000] {base.py:73} INFO - Using connection ID 'snowflake' for task execution.
[2023-12-04T22:19:11.104+0000] {connection.py:314} INFO - Snowflake Connector for Python Version: 3.1.1, Python Version: 3.8.18, Platform: Linux-5.15.133.1-microsoft-standard-WSL2-x86_64-with-glibc2.2.5
[2023-12-04T22:19:11.105+0000] {connection.py:1050} INFO - This connection is in OCSP Fail Open Mode. TLS Certificates would be checked for validity and revocation status. Any other Certificate Revocation related exceptions or OCSP Responder failures would be disregarded in favor of connectivity.
[2023-12-04T22:19:11.105+0000] {connection.py:1068} INFO - Setting use_openssl_only mode to False
[2023-12-04T22:19:12.124+0000] {connection.py:547} WARNING - Certificate did not match expected hostname: iy34150.europe-west4.snowflakecomputing.com. Certificate: {'subject': ((('commonName', '*.prod3.us-west-2.snowflakecomputing.com'),),), 'subjectAltName': [('DNS', '*.prod3.us-west-2.snowflakecomputing.com'), ('DNS', '*.us-west-2.snowflakecomputing.com'), ('DNS', '*.global.snowflakecomputing.com'), ('DNS', '*.snowflakecomputing.com'), ('DNS', '*.prod3.us-west-2.aws.snowflakecomputing.com')]}
[2023-12-04T22:19:12.126+0000] {connectionpool.py:812} WARNING - Retrying (Retry(total=0, connect=None, read=None, redirect=None, status=None)) after connection broken by 'SSLError(CertificateError("hostname 'iy34150.europe-west4.snowflakecomputing.com' doesn't match either of '*.prod3.us-west-2.snowflakecomputing.com', '*.us-west-2.snowflakecomputing.com', '*.global.snowflakecomputing.com', '*.snowflakecomputing.com', '*.prod3.us-west-2.aws.snowflakecomputing.com'"))': /session/v1/login-request?request_id=a1d59733-6f5e-46c4-bac6-b199e766bcc9&databaseName=tasks&schemaName=public&warehouse=compute_wh&roleName=accountadmin&request_guid=2dfa6868-792f-450f-94f4-9fc13db171e9
[2023-12-04T22:19:12.839+0000] {connection.py:547} WARNING - Certificate did not match expected hostname: iy34150.europe-west4.snowflakecomputing.com. Certificate: {'subject': ((('commonName', '*.prod3.us-west-2.snowflakecomputing.com'),),), 'subjectAltName': [('DNS', '*.prod3.us-west-2.snowflakecomputing.com'), ('DNS', '*.us-west-2.snowflakecomputing.com'), ('DNS', '*.global.snowflakecomputing.com'), ('DNS', '*.snowflakecomputing.com'), ('DNS', '*.prod3.us-west-2.aws.snowflakecomputing.com')]}
[2023-12-04T22:19:12.844+0000] {network.py:1037} ERROR - Failed to get the response. Hanging? method: post, url: https://iy34150.europe-west4.snowflakecomputing.com:443/session/v1/login-request?request_id=a1d59733-6f5e-46c4-bac6-b199e766bcc9&databaseName=tasks&schemaName=public&warehouse=compute_wh&roleName=accountadmin&request_guid=2dfa6868-792f-450f-94f4-9fc13db171e9, headers:{'Content-Type': 'application/json', 'accept': 'application/snowflake', 'User-Agent': 'PythonConnector/3.1.1 (Linux-5.15.133.1-microsoft-standard-WSL2-x86_64-with-glibc2.2.5) CPython/3.8.18', 'Content-Encoding': 'gzip'}, data: {"data": {"CLIENT_APP_ID": "PythonConnector", "CLIENT_APP_VERSION": "3.1.1", "SVN_REVISION": null, "ACCOUNT_NAME": "iy34150", "LOGIN_NAME": "MEDVED", "CLIENT_ENVIRONMENT": {"APPLICATION": "AIRFLOW", "OS": "Linux", "OS_VERSION": "Linux-5.15.133.1-microsoft-standard-WSL2-x86_64-with-glibc2.2.5", "PYTHON_VERSION": "3.8.18", "PYTHON_RUNTIME": "CPython", "PYTHON_COMPILER": "GCC 10.2.1 20210110", "OCSP_MODE": "FAIL_OPEN", "TRACING": 20, "LOGIN_TIMEOUT": 120, "NETWORK_TIMEOUT": null}, "PASSWORD": "**** "SESSION_PARAMETERS": {"CLIENT_PREFETCH_THREADS": 4}}}
[2023-12-04T22:19:16.578+0000] {connection.py:547} WARNING - Certificate did not match expected hostname: iy34150.europe-west4.snowflakecomputing.com. Certificate: {'subject': ((('commonName', '*.prod3.us-west-2.snowflakecomputing.com'),),), 'subjectAltName': [('DNS', '*.prod3.us-west-2.snowflakecomputing.com'), ('DNS', '*.us-west-2.snowflakecomputing.com'), ('DNS', '*.global.snowflakecomputing.com'), ('DNS', '*.snowflakecomputing.com'), ('DNS', '*.prod3.us-west-2.aws.snowflakecomputing.com')]}
[2023-12-04T22:19:16.578+0000] {connectionpool.py:812} WARNING - Retrying (Retry(total=0, connect=None, read=None, redirect=None, status=None)) after connection broken by 'SSLError(CertificateError("hostname 'iy34150.europe-west4.snowflakecomputing.com' doesn't match either of '*.prod3.us-west-2.snowflakecomputing.com', '*.us-west-2.snowflakecomputing.com', '*.global.snowflakecomputing.com', '*.snowflakecomputing.com', '*.prod3.us-west-2.aws.snowflakecomputing.com'"))': /session/v1/login-request?request_id=b7b81a54-4a7a-47cd-a002-77c334fb1e6a&databaseName=tasks&schemaName=public&warehouse=compute_wh&roleName=accountadmin&request_guid=375218c2-4492-47e4-823d-e90ea38d455e
[2023-12-04T22:19:17.312+0000] {connection.py:547} WARNING - Certificate did not match expected hostname: iy34150.europe-west4.snowflakecomputing.com. Certificate: {'subject': ((('commonName', '*.prod3.us-west-2.snowflakecomputing.com'),),), 'subjectAltName': [('DNS', '*.prod3.us-west-2.snowflakecomputing.com'), ('DNS', '*.us-west-2.snowflakecomputing.com'), ('DNS', '*.global.snowflakecomputing.com'), ('DNS', '*.snowflakecomputing.com'), ('DNS', '*.prod3.us-west-2.aws.snowflakecomputing.com')]}
[2023-12-04T22:19:17.315+0000] {network.py:1037} ERROR - Failed to get the response. Hanging? method: post, url: https://iy34150.europe-west4.snowflakecomputing.com:443/session/v1/login-request?request_id=b7b81a54-4a7a-47cd-a002-77c334fb1e6a&databaseName=tasks&schemaName=public&warehouse=compute_wh&roleName=accountadmin&request_guid=375218c2-4492-47e4-823d-e90ea38d455e, headers:{'Content-Type': 'application/json', 'accept': 'application/snowflake', 'User-Agent': 'PythonConnector/3.1.1 (Linux-5.15.133.1-microsoft-standard-WSL2-x86_64-with-glibc2.2.5) CPython/3.8.18', 'Content-Encoding': 'gzip'}, data: {"data": {"CLIENT_APP_ID": "PythonConnector", "CLIENT_APP_VERSION": "3.1.1", "SVN_REVISION": null, "ACCOUNT_NAME": "iy34150", "LOGIN_NAME": "MEDVED", "CLIENT_ENVIRONMENT": {"APPLICATION": "AIRFLOW", "OS": "Linux", "OS_VERSION": "Linux-5.15.133.1-microsoft-standard-WSL2-x86_64-with-glibc2.2.5", "PYTHON_VERSION": "3.8.18", "PYTHON_RUNTIME": "CPython", "PYTHON_COMPILER": "GCC 10.2.1 20210110", "OCSP_MODE": "FAIL_OPEN", "TRACING": 20, "LOGIN_TIMEOUT": 120, "NETWORK_TIMEOUT": null}, "PASSWORD": "**** "SESSION_PARAMETERS": {"CLIENT_PREFETCH_THREADS": 4}}}
[2023-12-04T22:19:17.319+0000] {taskinstance.py:1935} ERROR - Task failed with exception
Traceback (most recent call last):
  File "/home/airflow/.local/lib/python3.8/site-packages/snowflake/connector/connection.py", line 1193, in _authenticate
    auth.authenticate(
  File "/home/airflow/.local/lib/python3.8/site-packages/snowflake/connector/auth/_auth.py", line 250, in authenticate
    ret = self._rest._post_request(
  File "/home/airflow/.local/lib/python3.8/site-packages/snowflake/connector/network.py", line 730, in _post_request
    ret = self.fetch(
  File "/home/airflow/.local/lib/python3.8/site-packages/snowflake/connector/network.py", line 849, in fetch
    ret = self._request_exec_wrapper(
  File "/home/airflow/.local/lib/python3.8/site-packages/snowflake/connector/network.py", line 987, in _request_exec_wrapper
    raise e
  File "/home/airflow/.local/lib/python3.8/site-packages/snowflake/connector/network.py", line 902, in _request_exec_wrapper
    self._handle_unknown_error(method, full_url, headers, data, conn)
  File "/home/airflow/.local/lib/python3.8/site-packages/snowflake/connector/network.py", line 1042, in _handle_unknown_error
    Error.errorhandler_wrapper(
  File "/home/airflow/.local/lib/python3.8/site-packages/snowflake/connector/errors.py", line 290, in errorhandler_wrapper
    handed_over = Error.hand_to_other_handler(
  File "/home/airflow/.local/lib/python3.8/site-packages/snowflake/connector/errors.py", line 348, in hand_to_other_handler
    connection.errorhandler(connection, cursor, error_class, error_value)
  File "/home/airflow/.local/lib/python3.8/site-packages/snowflake/connector/errors.py", line 221, in default_errorhandler
    raise error_class(
snowflake.connector.errors.OperationalError: 250003: 250003: Failed to get the response. Hanging? method: post, url: https://iy34150.europe-west4.snowflakecomputing.com:443/session/v1/login-request?request_id=a1d59733-6f5e-46c4-bac6-b199e766bcc9&databaseName=tasks&schemaName=public&warehouse=compute_wh&roleName=accountadmin&request_guid=2dfa6868-792f-450f-94f4-9fc13db171e9

The above exception was the direct cause of the following exception:

Traceback (most recent call last):
  File "/home/airflow/.local/lib/python3.8/site-packages/airflow/operators/python.py", line 192, in execute
    return_value = self.execute_callable()
  File "/home/airflow/.local/lib/python3.8/site-packages/airflow/operators/python.py", line 209, in execute_callable
    return self.python_callable(*self.op_args, **self.op_kwargs)
  File "/opt/airflow/dags/test.py", line 25, in execute_query
    conn = hook.get_conn()
  File "/home/airflow/.local/lib/python3.8/site-packages/airflow/providers/snowflake/hooks/snowflake.py", line 303, in get_conn
    conn = connector.connect(**conn_config)
  File "/home/airflow/.local/lib/python3.8/site-packages/snowflake/connector/__init__.py", line 51, in Connect
    return SnowflakeConnection(**kwargs)
  File "/home/airflow/.local/lib/python3.8/site-packages/snowflake/connector/connection.py", line 353, in __init__
    self.connect(**kwargs)
  File "/home/airflow/.local/lib/python3.8/site-packages/snowflake/connector/connection.py", line 625, in connect
    self.__open_connection()
  File "/home/airflow/.local/lib/python3.8/site-packages/snowflake/connector/connection.py", line 898, in __open_connection
    self.authenticate_with_retry(self.auth_class)
  File "/home/airflow/.local/lib/python3.8/site-packages/snowflake/connector/connection.py", line 1167, in authenticate_with_retry
    self._authenticate(auth_instance)
  File "/home/airflow/.local/lib/python3.8/site-packages/snowflake/connector/connection.py", line 1238, in _authenticate
    raise auth_op from e
  File "/home/airflow/.local/lib/python3.8/site-packages/snowflake/connector/connection.py", line 1215, in _authenticate
    auth_instance.handle_timeout(
  File "/home/airflow/.local/lib/python3.8/site-packages/snowflake/connector/auth/by_plugin.py", line 219, in handle_timeout
    raise error
snowflake.connector.errors.OperationalError: 250001: 250001: Could not connect to Snowflake backend after 1 attempt(s).Aborting
[2023-12-04T22:19:17.326+0000] {taskinstance.py:1398} INFO - Marking task as UP_FOR_RETRY. dag_id=Georgy, task_id=query1, execution_date=20231130T211000, start_date=20231204T221910, end_date=20231204T221917
[2023-12-04T22:19:17.337+0000] {standard_task_runner.py:104} ERROR - Failed to execute job 156 for task query1 (250001: 250001: Could not connect to Snowflake backend after 1 attempt(s).Aborting; 788)
[2023-12-04T22:19:17.347+0000] {local_task_job_runner.py:228} INFO - Task exited with return code 1
[2023-12-04T22:19:17.368+0000] {taskinstance.py:2776} INFO - 0 downstream tasks scheduled from follow-on schedule check
[2023-12-04T22:21:08.710+0000] {taskinstance.py:1157} INFO - Dependencies all met for dep_context=non-requeueable deps ti=<TaskInstance: Georgy.query1 scheduled__2023-11-30T21:10:00+00:00 [queued]>
[2023-12-04T22:21:08.717+0000] {taskinstance.py:1157} INFO - Dependencies all met for dep_context=requeueable deps ti=<TaskInstance: Georgy.query1 scheduled__2023-11-30T21:10:00+00:00 [queued]>
[2023-12-04T22:21:08.718+0000] {taskinstance.py:1359} INFO - Starting attempt 1 of 4
[2023-12-04T22:21:08.729+0000] {taskinstance.py:1380} INFO - Executing <Task(PythonOperator): query1> on 2023-11-30 21:10:00+00:00
[2023-12-04T22:21:08.734+0000] {standard_task_runner.py:57} INFO - Started process 818 to run task
[2023-12-04T22:21:08.736+0000] {standard_task_runner.py:84} INFO - Running: ['***', 'tasks', 'run', 'Georgy', 'query1', 'scheduled__2023-11-30T21:10:00+00:00', '--job-id', '157', '--raw', '--subdir', 'DAGS_FOLDER/test.py', '--cfg-path', '/tmp/tmpode490mf']
[2023-12-04T22:21:08.736+0000] {standard_task_runner.py:85} INFO - Job 157: Subtask query1
[2023-12-04T22:21:08.777+0000] {task_command.py:415} INFO - Running <TaskInstance: Georgy.query1 scheduled__2023-11-30T21:10:00+00:00 [running]> on host 435c91f40721
[2023-12-04T22:21:08.833+0000] {taskinstance.py:1660} INFO - Exporting env vars: AIRFLOW_CTX_DAG_OWNER='Gio' AIRFLOW_CTX_DAG_ID='Georgy' AIRFLOW_CTX_TASK_ID='query1' AIRFLOW_CTX_EXECUTION_DATE='2023-11-30T21:10:00+00:00' AIRFLOW_CTX_TRY_NUMBER='1' AIRFLOW_CTX_DAG_RUN_ID='scheduled__2023-11-30T21:10:00+00:00'
[2023-12-04T22:21:08.843+0000] {base.py:73} INFO - Using connection ID 'snowflake' for task execution.
[2023-12-04T22:21:08.844+0000] {connection.py:314} INFO - Snowflake Connector for Python Version: 3.1.1, Python Version: 3.8.18, Platform: Linux-5.15.133.1-microsoft-standard-WSL2-x86_64-with-glibc2.2.5
[2023-12-04T22:21:08.845+0000] {connection.py:1050} INFO - This connection is in OCSP Fail Open Mode. TLS Certificates would be checked for validity and revocation status. Any other Certificate Revocation related exceptions or OCSP Responder failures would be disregarded in favor of connectivity.
[2023-12-04T22:21:08.846+0000] {connection.py:1068} INFO - Setting use_openssl_only mode to False
[2023-12-04T22:21:09.775+0000] {connection.py:547} WARNING - Certificate did not match expected hostname: iy34150.europe-west4.snowflakecomputing.com. Certificate: {'subject': ((('commonName', '*.prod3.us-west-2.snowflakecomputing.com'),),), 'subjectAltName': [('DNS', '*.prod3.us-west-2.snowflakecomputing.com'), ('DNS', '*.us-west-2.snowflakecomputing.com'), ('DNS', '*.global.snowflakecomputing.com'), ('DNS', '*.snowflakecomputing.com'), ('DNS', '*.prod3.us-west-2.aws.snowflakecomputing.com')]}
[2023-12-04T22:21:09.777+0000] {connectionpool.py:812} WARNING - Retrying (Retry(total=0, connect=None, read=None, redirect=None, status=None)) after connection broken by 'SSLError(CertificateError("hostname 'iy34150.europe-west4.snowflakecomputing.com' doesn't match either of '*.prod3.us-west-2.snowflakecomputing.com', '*.us-west-2.snowflakecomputing.com', '*.global.snowflakecomputing.com', '*.snowflakecomputing.com', '*.prod3.us-west-2.aws.snowflakecomputing.com'"))': /session/v1/login-request?request_id=2ce39c17-7d14-4c8f-90ef-b7a462abe594&databaseName=tasks&schemaName=public&warehouse=compute_wh&roleName=accountadmin&request_guid=22933ee1-5cfa-4595-bd08-7f21e1183753
[2023-12-04T22:21:10.496+0000] {connection.py:547} WARNING - Certificate did not match expected hostname: iy34150.europe-west4.snowflakecomputing.com. Certificate: {'subject': ((('commonName', '*.prod3.us-west-2.snowflakecomputing.com'),),), 'subjectAltName': [('DNS', '*.prod3.us-west-2.snowflakecomputing.com'), ('DNS', '*.us-west-2.snowflakecomputing.com'), ('DNS', '*.global.snowflakecomputing.com'), ('DNS', '*.snowflakecomputing.com'), ('DNS', '*.prod3.us-west-2.aws.snowflakecomputing.com')]}
[2023-12-04T22:21:10.500+0000] {network.py:1037} ERROR - Failed to get the response. Hanging? method: post, url: https://iy34150.europe-west4.snowflakecomputing.com:443/session/v1/login-request?request_id=2ce39c17-7d14-4c8f-90ef-b7a462abe594&databaseName=tasks&schemaName=public&warehouse=compute_wh&roleName=accountadmin&request_guid=22933ee1-5cfa-4595-bd08-7f21e1183753, headers:{'Content-Type': 'application/json', 'accept': 'application/snowflake', 'User-Agent': 'PythonConnector/3.1.1 (Linux-5.15.133.1-microsoft-standard-WSL2-x86_64-with-glibc2.2.5) CPython/3.8.18', 'Content-Encoding': 'gzip'}, data: {"data": {"CLIENT_APP_ID": "PythonConnector", "CLIENT_APP_VERSION": "3.1.1", "SVN_REVISION": null, "ACCOUNT_NAME": "iy34150", "LOGIN_NAME": "Medved", "CLIENT_ENVIRONMENT": {"APPLICATION": "AIRFLOW", "OS": "Linux", "OS_VERSION": "Linux-5.15.133.1-microsoft-standard-WSL2-x86_64-with-glibc2.2.5", "PYTHON_VERSION": "3.8.18", "PYTHON_RUNTIME": "CPython", "PYTHON_COMPILER": "GCC 10.2.1 20210110", "OCSP_MODE": "FAIL_OPEN", "TRACING": 20, "LOGIN_TIMEOUT": 120, "NETWORK_TIMEOUT": null}, "PASSWORD": "**** "SESSION_PARAMETERS": {"CLIENT_PREFETCH_THREADS": 4}}}
[2023-12-04T22:21:12.220+0000] {connection.py:547} WARNING - Certificate did not match expected hostname: iy34150.europe-west4.snowflakecomputing.com. Certificate: {'subject': ((('commonName', '*.prod3.us-west-2.snowflakecomputing.com'),),), 'subjectAltName': [('DNS', '*.prod3.us-west-2.snowflakecomputing.com'), ('DNS', '*.us-west-2.snowflakecomputing.com'), ('DNS', '*.global.snowflakecomputing.com'), ('DNS', '*.snowflakecomputing.com'), ('DNS', '*.prod3.us-west-2.aws.snowflakecomputing.com')]}
[2023-12-04T22:21:12.221+0000] {connectionpool.py:812} WARNING - Retrying (Retry(total=0, connect=None, read=None, redirect=None, status=None)) after connection broken by 'SSLError(CertificateError("hostname 'iy34150.europe-west4.snowflakecomputing.com' doesn't match either of '*.prod3.us-west-2.snowflakecomputing.com', '*.us-west-2.snowflakecomputing.com', '*.global.snowflakecomputing.com', '*.snowflakecomputing.com', '*.prod3.us-west-2.aws.snowflakecomputing.com'"))': /session/v1/login-request?request_id=f66c9344-fb20-4c14-9df1-328aae23d35c&databaseName=tasks&schemaName=public&warehouse=compute_wh&roleName=accountadmin&request_guid=d02dd522-ec2e-4c06-9864-32cba69aee90
[2023-12-04T22:21:12.933+0000] {connection.py:547} WARNING - Certificate did not match expected hostname: iy34150.europe-west4.snowflakecomputing.com. Certificate: {'subject': ((('commonName', '*.prod3.us-west-2.snowflakecomputing.com'),),), 'subjectAltName': [('DNS', '*.prod3.us-west-2.snowflakecomputing.com'), ('DNS', '*.us-west-2.snowflakecomputing.com'), ('DNS', '*.global.snowflakecomputing.com'), ('DNS', '*.snowflakecomputing.com'), ('DNS', '*.prod3.us-west-2.aws.snowflakecomputing.com')]}
[2023-12-04T22:21:12.936+0000] {network.py:1037} ERROR - Failed to get the response. Hanging? method: post, url: https://iy34150.europe-west4.snowflakecomputing.com:443/session/v1/login-request?request_id=f66c9344-fb20-4c14-9df1-328aae23d35c&databaseName=tasks&schemaName=public&warehouse=compute_wh&roleName=accountadmin&request_guid=d02dd522-ec2e-4c06-9864-32cba69aee90, headers:{'Content-Type': 'application/json', 'accept': 'application/snowflake', 'User-Agent': 'PythonConnector/3.1.1 (Linux-5.15.133.1-microsoft-standard-WSL2-x86_64-with-glibc2.2.5) CPython/3.8.18', 'Content-Encoding': 'gzip'}, data: {"data": {"CLIENT_APP_ID": "PythonConnector", "CLIENT_APP_VERSION": "3.1.1", "SVN_REVISION": null, "ACCOUNT_NAME": "iy34150", "LOGIN_NAME": "Medved", "CLIENT_ENVIRONMENT": {"APPLICATION": "AIRFLOW", "OS": "Linux", "OS_VERSION": "Linux-5.15.133.1-microsoft-standard-WSL2-x86_64-with-glibc2.2.5", "PYTHON_VERSION": "3.8.18", "PYTHON_RUNTIME": "CPython", "PYTHON_COMPILER": "GCC 10.2.1 20210110", "OCSP_MODE": "FAIL_OPEN", "TRACING": 20, "LOGIN_TIMEOUT": 120, "NETWORK_TIMEOUT": null}, "PASSWORD": "**** "SESSION_PARAMETERS": {"CLIENT_PREFETCH_THREADS": 4}}}
[2023-12-04T22:21:12.939+0000] {taskinstance.py:1935} ERROR - Task failed with exception
Traceback (most recent call last):
  File "/home/airflow/.local/lib/python3.8/site-packages/snowflake/connector/connection.py", line 1193, in _authenticate
    auth.authenticate(
  File "/home/airflow/.local/lib/python3.8/site-packages/snowflake/connector/auth/_auth.py", line 250, in authenticate
    ret = self._rest._post_request(
  File "/home/airflow/.local/lib/python3.8/site-packages/snowflake/connector/network.py", line 730, in _post_request
    ret = self.fetch(
  File "/home/airflow/.local/lib/python3.8/site-packages/snowflake/connector/network.py", line 849, in fetch
    ret = self._request_exec_wrapper(
  File "/home/airflow/.local/lib/python3.8/site-packages/snowflake/connector/network.py", line 987, in _request_exec_wrapper
    raise e
  File "/home/airflow/.local/lib/python3.8/site-packages/snowflake/connector/network.py", line 902, in _request_exec_wrapper
    self._handle_unknown_error(method, full_url, headers, data, conn)
  File "/home/airflow/.local/lib/python3.8/site-packages/snowflake/connector/network.py", line 1042, in _handle_unknown_error
    Error.errorhandler_wrapper(
  File "/home/airflow/.local/lib/python3.8/site-packages/snowflake/connector/errors.py", line 290, in errorhandler_wrapper
    handed_over = Error.hand_to_other_handler(
  File "/home/airflow/.local/lib/python3.8/site-packages/snowflake/connector/errors.py", line 348, in hand_to_other_handler
    connection.errorhandler(connection, cursor, error_class, error_value)
  File "/home/airflow/.local/lib/python3.8/site-packages/snowflake/connector/errors.py", line 221, in default_errorhandler
    raise error_class(
snowflake.connector.errors.OperationalError: 250003: 250003: Failed to get the response. Hanging? method: post, url: https://iy34150.europe-west4.snowflakecomputing.com:443/session/v1/login-request?request_id=2ce39c17-7d14-4c8f-90ef-b7a462abe594&databaseName=tasks&schemaName=public&warehouse=compute_wh&roleName=accountadmin&request_guid=22933ee1-5cfa-4595-bd08-7f21e1183753

The above exception was the direct cause of the following exception:

Traceback (most recent call last):
  File "/home/airflow/.local/lib/python3.8/site-packages/airflow/operators/python.py", line 192, in execute
    return_value = self.execute_callable()
  File "/home/airflow/.local/lib/python3.8/site-packages/airflow/operators/python.py", line 209, in execute_callable
    return self.python_callable(*self.op_args, **self.op_kwargs)
  File "/opt/airflow/dags/test.py", line 25, in execute_query
    conn = hook.get_conn()
  File "/home/airflow/.local/lib/python3.8/site-packages/airflow/providers/snowflake/hooks/snowflake.py", line 303, in get_conn
    conn = connector.connect(**conn_config)
  File "/home/airflow/.local/lib/python3.8/site-packages/snowflake/connector/__init__.py", line 51, in Connect
    return SnowflakeConnection(**kwargs)
  File "/home/airflow/.local/lib/python3.8/site-packages/snowflake/connector/connection.py", line 353, in __init__
    self.connect(**kwargs)
  File "/home/airflow/.local/lib/python3.8/site-packages/snowflake/connector/connection.py", line 625, in connect
    self.__open_connection()
  File "/home/airflow/.local/lib/python3.8/site-packages/snowflake/connector/connection.py", line 898, in __open_connection
    self.authenticate_with_retry(self.auth_class)
  File "/home/airflow/.local/lib/python3.8/site-packages/snowflake/connector/connection.py", line 1167, in authenticate_with_retry
    self._authenticate(auth_instance)
  File "/home/airflow/.local/lib/python3.8/site-packages/snowflake/connector/connection.py", line 1238, in _authenticate
    raise auth_op from e
  File "/home/airflow/.local/lib/python3.8/site-packages/snowflake/connector/connection.py", line 1215, in _authenticate
    auth_instance.handle_timeout(
  File "/home/airflow/.local/lib/python3.8/site-packages/snowflake/connector/auth/by_plugin.py", line 219, in handle_timeout
    raise error
snowflake.connector.errors.OperationalError: 250001: 250001: Could not connect to Snowflake backend after 1 attempt(s).Aborting
[2023-12-04T22:21:12.948+0000] {taskinstance.py:1398} INFO - Marking task as UP_FOR_RETRY. dag_id=Georgy, task_id=query1, execution_date=20231130T211000, start_date=20231204T222108, end_date=20231204T222112
[2023-12-04T22:21:12.958+0000] {standard_task_runner.py:104} ERROR - Failed to execute job 157 for task query1 (250001: 250001: Could not connect to Snowflake backend after 1 attempt(s).Aborting; 818)
[2023-12-04T22:21:13.003+0000] {local_task_job_runner.py:228} INFO - Task exited with return code 1
[2023-12-04T22:21:13.021+0000] {taskinstance.py:2776} INFO - 0 downstream tasks scheduled from follow-on schedule check
[2023-12-04T22:36:19.508+0000] {taskinstance.py:1157} INFO - Dependencies all met for dep_context=non-requeueable deps ti=<TaskInstance: Georgy.query1 scheduled__2023-11-30T21:10:00+00:00 [queued]>
[2023-12-04T22:36:19.516+0000] {taskinstance.py:1157} INFO - Dependencies all met for dep_context=requeueable deps ti=<TaskInstance: Georgy.query1 scheduled__2023-11-30T21:10:00+00:00 [queued]>
[2023-12-04T22:36:19.517+0000] {taskinstance.py:1359} INFO - Starting attempt 1 of 4
[2023-12-04T22:36:19.528+0000] {taskinstance.py:1380} INFO - Executing <Task(PythonOperator): query1> on 2023-11-30 21:10:00+00:00
[2023-12-04T22:36:19.532+0000] {standard_task_runner.py:57} INFO - Started process 1056 to run task
[2023-12-04T22:36:19.534+0000] {standard_task_runner.py:84} INFO - Running: ['***', 'tasks', 'run', 'Georgy', 'query1', 'scheduled__2023-11-30T21:10:00+00:00', '--job-id', '158', '--raw', '--subdir', 'DAGS_FOLDER/test.py', '--cfg-path', '/tmp/tmp7u233az2']
[2023-12-04T22:36:19.535+0000] {standard_task_runner.py:85} INFO - Job 158: Subtask query1
[2023-12-04T22:36:19.566+0000] {task_command.py:415} INFO - Running <TaskInstance: Georgy.query1 scheduled__2023-11-30T21:10:00+00:00 [running]> on host 435c91f40721
[2023-12-04T22:36:19.621+0000] {taskinstance.py:1660} INFO - Exporting env vars: AIRFLOW_CTX_DAG_OWNER='Gio' AIRFLOW_CTX_DAG_ID='Georgy' AIRFLOW_CTX_TASK_ID='query1' AIRFLOW_CTX_EXECUTION_DATE='2023-11-30T21:10:00+00:00' AIRFLOW_CTX_TRY_NUMBER='1' AIRFLOW_CTX_DAG_RUN_ID='scheduled__2023-11-30T21:10:00+00:00'
[2023-12-04T22:36:19.629+0000] {base.py:73} INFO - Using connection ID 'snowflake' for task execution.
[2023-12-04T22:36:19.629+0000] {connection.py:314} INFO - Snowflake Connector for Python Version: 3.1.1, Python Version: 3.8.18, Platform: Linux-5.15.133.1-microsoft-standard-WSL2-x86_64-with-glibc2.2.5
[2023-12-04T22:36:19.630+0000] {connection.py:1050} INFO - This connection is in OCSP Fail Open Mode. TLS Certificates would be checked for validity and revocation status. Any other Certificate Revocation related exceptions or OCSP Responder failures would be disregarded in favor of connectivity.
[2023-12-04T22:36:19.630+0000] {connection.py:1068} INFO - Setting use_openssl_only mode to False
[2023-12-04T22:36:20.609+0000] {connection.py:547} WARNING - Certificate did not match expected hostname: iy34150.europe-west4.snowflakecomputing.com. Certificate: {'subject': ((('commonName', '*.prod3.us-west-2.snowflakecomputing.com'),),), 'subjectAltName': [('DNS', '*.prod3.us-west-2.snowflakecomputing.com'), ('DNS', '*.us-west-2.snowflakecomputing.com'), ('DNS', '*.global.snowflakecomputing.com'), ('DNS', '*.snowflakecomputing.com'), ('DNS', '*.prod3.us-west-2.aws.snowflakecomputing.com')]}
[2023-12-04T22:36:20.611+0000] {connectionpool.py:812} WARNING - Retrying (Retry(total=0, connect=None, read=None, redirect=None, status=None)) after connection broken by 'SSLError(CertificateError("hostname 'iy34150.europe-west4.snowflakecomputing.com' doesn't match either of '*.prod3.us-west-2.snowflakecomputing.com', '*.us-west-2.snowflakecomputing.com', '*.global.snowflakecomputing.com', '*.snowflakecomputing.com', '*.prod3.us-west-2.aws.snowflakecomputing.com'"))': /session/v1/login-request?request_id=f6a2b272-89a3-4002-9503-7f954da4ab3d&databaseName=tasks&schemaName=public&warehouse=COMPUTE_WH&roleName=&request_guid=2d67f0f2-344b-48a7-8793-a8041bfec229
[2023-12-04T22:36:21.319+0000] {connection.py:547} WARNING - Certificate did not match expected hostname: iy34150.europe-west4.snowflakecomputing.com. Certificate: {'subject': ((('commonName', '*.prod3.us-west-2.snowflakecomputing.com'),),), 'subjectAltName': [('DNS', '*.prod3.us-west-2.snowflakecomputing.com'), ('DNS', '*.us-west-2.snowflakecomputing.com'), ('DNS', '*.global.snowflakecomputing.com'), ('DNS', '*.snowflakecomputing.com'), ('DNS', '*.prod3.us-west-2.aws.snowflakecomputing.com')]}
[2023-12-04T22:36:21.322+0000] {network.py:1037} ERROR - Failed to get the response. Hanging? method: post, url: https://iy34150.europe-west4.snowflakecomputing.com:443/session/v1/login-request?request_id=f6a2b272-89a3-4002-9503-7f954da4ab3d&databaseName=tasks&schemaName=public&warehouse=COMPUTE_WH&roleName=&request_guid=2d67f0f2-344b-48a7-8793-a8041bfec229, headers:{'Content-Type': 'application/json', 'accept': 'application/snowflake', 'User-Agent': 'PythonConnector/3.1.1 (Linux-5.15.133.1-microsoft-standard-WSL2-x86_64-with-glibc2.2.5) CPython/3.8.18', 'Content-Encoding': 'gzip'}, data: {"data": {"CLIENT_APP_ID": "PythonConnector", "CLIENT_APP_VERSION": "3.1.1", "SVN_REVISION": null, "ACCOUNT_NAME": "iy34150", "LOGIN_NAME": "MEDVED", "CLIENT_ENVIRONMENT": {"APPLICATION": "AIRFLOW", "OS": "Linux", "OS_VERSION": "Linux-5.15.133.1-microsoft-standard-WSL2-x86_64-with-glibc2.2.5", "PYTHON_VERSION": "3.8.18", "PYTHON_RUNTIME": "CPython", "PYTHON_COMPILER": "GCC 10.2.1 20210110", "OCSP_MODE": "FAIL_OPEN", "TRACING": 20, "LOGIN_TIMEOUT": 120, "NETWORK_TIMEOUT": null}, "PASSWORD": "**** "SESSION_PARAMETERS": {"CLIENT_PREFETCH_THREADS": 4}}}
[2023-12-04T22:36:24.069+0000] {connection.py:547} WARNING - Certificate did not match expected hostname: iy34150.europe-west4.snowflakecomputing.com. Certificate: {'subject': ((('commonName', '*.prod3.us-west-2.snowflakecomputing.com'),),), 'subjectAltName': [('DNS', '*.prod3.us-west-2.snowflakecomputing.com'), ('DNS', '*.us-west-2.snowflakecomputing.com'), ('DNS', '*.global.snowflakecomputing.com'), ('DNS', '*.snowflakecomputing.com'), ('DNS', '*.prod3.us-west-2.aws.snowflakecomputing.com')]}
[2023-12-04T22:36:24.070+0000] {connectionpool.py:812} WARNING - Retrying (Retry(total=0, connect=None, read=None, redirect=None, status=None)) after connection broken by 'SSLError(CertificateError("hostname 'iy34150.europe-west4.snowflakecomputing.com' doesn't match either of '*.prod3.us-west-2.snowflakecomputing.com', '*.us-west-2.snowflakecomputing.com', '*.global.snowflakecomputing.com', '*.snowflakecomputing.com', '*.prod3.us-west-2.aws.snowflakecomputing.com'"))': /session/v1/login-request?request_id=6279a1f7-63b9-481c-a749-345328abda2a&databaseName=tasks&schemaName=public&warehouse=COMPUTE_WH&roleName=&request_guid=4f3314cc-42fe-4e92-991d-73cf4bd42616
[2023-12-04T22:36:24.785+0000] {connection.py:547} WARNING - Certificate did not match expected hostname: iy34150.europe-west4.snowflakecomputing.com. Certificate: {'subject': ((('commonName', '*.prod3.us-west-2.snowflakecomputing.com'),),), 'subjectAltName': [('DNS', '*.prod3.us-west-2.snowflakecomputing.com'), ('DNS', '*.us-west-2.snowflakecomputing.com'), ('DNS', '*.global.snowflakecomputing.com'), ('DNS', '*.snowflakecomputing.com'), ('DNS', '*.prod3.us-west-2.aws.snowflakecomputing.com')]}
[2023-12-04T22:36:24.787+0000] {network.py:1037} ERROR - Failed to get the response. Hanging? method: post, url: https://iy34150.europe-west4.snowflakecomputing.com:443/session/v1/login-request?request_id=6279a1f7-63b9-481c-a749-345328abda2a&databaseName=tasks&schemaName=public&warehouse=COMPUTE_WH&roleName=&request_guid=4f3314cc-42fe-4e92-991d-73cf4bd42616, headers:{'Content-Type': 'application/json', 'accept': 'application/snowflake', 'User-Agent': 'PythonConnector/3.1.1 (Linux-5.15.133.1-microsoft-standard-WSL2-x86_64-with-glibc2.2.5) CPython/3.8.18', 'Content-Encoding': 'gzip'}, data: {"data": {"CLIENT_APP_ID": "PythonConnector", "CLIENT_APP_VERSION": "3.1.1", "SVN_REVISION": null, "ACCOUNT_NAME": "iy34150", "LOGIN_NAME": "MEDVED", "CLIENT_ENVIRONMENT": {"APPLICATION": "AIRFLOW", "OS": "Linux", "OS_VERSION": "Linux-5.15.133.1-microsoft-standard-WSL2-x86_64-with-glibc2.2.5", "PYTHON_VERSION": "3.8.18", "PYTHON_RUNTIME": "CPython", "PYTHON_COMPILER": "GCC 10.2.1 20210110", "OCSP_MODE": "FAIL_OPEN", "TRACING": 20, "LOGIN_TIMEOUT": 120, "NETWORK_TIMEOUT": null}, "PASSWORD": "**** "SESSION_PARAMETERS": {"CLIENT_PREFETCH_THREADS": 4}}}
[2023-12-04T22:36:24.790+0000] {taskinstance.py:1935} ERROR - Task failed with exception
Traceback (most recent call last):
  File "/home/airflow/.local/lib/python3.8/site-packages/snowflake/connector/connection.py", line 1193, in _authenticate
    auth.authenticate(
  File "/home/airflow/.local/lib/python3.8/site-packages/snowflake/connector/auth/_auth.py", line 250, in authenticate
    ret = self._rest._post_request(
  File "/home/airflow/.local/lib/python3.8/site-packages/snowflake/connector/network.py", line 730, in _post_request
    ret = self.fetch(
  File "/home/airflow/.local/lib/python3.8/site-packages/snowflake/connector/network.py", line 849, in fetch
    ret = self._request_exec_wrapper(
  File "/home/airflow/.local/lib/python3.8/site-packages/snowflake/connector/network.py", line 987, in _request_exec_wrapper
    raise e
  File "/home/airflow/.local/lib/python3.8/site-packages/snowflake/connector/network.py", line 902, in _request_exec_wrapper
    self._handle_unknown_error(method, full_url, headers, data, conn)
  File "/home/airflow/.local/lib/python3.8/site-packages/snowflake/connector/network.py", line 1042, in _handle_unknown_error
    Error.errorhandler_wrapper(
  File "/home/airflow/.local/lib/python3.8/site-packages/snowflake/connector/errors.py", line 290, in errorhandler_wrapper
    handed_over = Error.hand_to_other_handler(
  File "/home/airflow/.local/lib/python3.8/site-packages/snowflake/connector/errors.py", line 348, in hand_to_other_handler
    connection.errorhandler(connection, cursor, error_class, error_value)
  File "/home/airflow/.local/lib/python3.8/site-packages/snowflake/connector/errors.py", line 221, in default_errorhandler
    raise error_class(
snowflake.connector.errors.OperationalError: 250003: 250003: Failed to get the response. Hanging? method: post, url: https://iy34150.europe-west4.snowflakecomputing.com:443/session/v1/login-request?request_id=f6a2b272-89a3-4002-9503-7f954da4ab3d&databaseName=tasks&schemaName=public&warehouse=COMPUTE_WH&roleName=&request_guid=2d67f0f2-344b-48a7-8793-a8041bfec229

The above exception was the direct cause of the following exception:

Traceback (most recent call last):
  File "/home/airflow/.local/lib/python3.8/site-packages/airflow/operators/python.py", line 192, in execute
    return_value = self.execute_callable()
  File "/home/airflow/.local/lib/python3.8/site-packages/airflow/operators/python.py", line 209, in execute_callable
    return self.python_callable(*self.op_args, **self.op_kwargs)
  File "/opt/airflow/dags/test.py", line 25, in execute_query
    conn = hook.get_conn()
  File "/home/airflow/.local/lib/python3.8/site-packages/airflow/providers/snowflake/hooks/snowflake.py", line 303, in get_conn
    conn = connector.connect(**conn_config)
  File "/home/airflow/.local/lib/python3.8/site-packages/snowflake/connector/__init__.py", line 51, in Connect
    return SnowflakeConnection(**kwargs)
  File "/home/airflow/.local/lib/python3.8/site-packages/snowflake/connector/connection.py", line 353, in __init__
    self.connect(**kwargs)
  File "/home/airflow/.local/lib/python3.8/site-packages/snowflake/connector/connection.py", line 625, in connect
    self.__open_connection()
  File "/home/airflow/.local/lib/python3.8/site-packages/snowflake/connector/connection.py", line 898, in __open_connection
    self.authenticate_with_retry(self.auth_class)
  File "/home/airflow/.local/lib/python3.8/site-packages/snowflake/connector/connection.py", line 1167, in authenticate_with_retry
    self._authenticate(auth_instance)
  File "/home/airflow/.local/lib/python3.8/site-packages/snowflake/connector/connection.py", line 1238, in _authenticate
    raise auth_op from e
  File "/home/airflow/.local/lib/python3.8/site-packages/snowflake/connector/connection.py", line 1215, in _authenticate
    auth_instance.handle_timeout(
  File "/home/airflow/.local/lib/python3.8/site-packages/snowflake/connector/auth/by_plugin.py", line 219, in handle_timeout
    raise error
snowflake.connector.errors.OperationalError: 250001: 250001: Could not connect to Snowflake backend after 1 attempt(s).Aborting
[2023-12-04T22:36:24.797+0000] {taskinstance.py:1398} INFO - Marking task as UP_FOR_RETRY. dag_id=Georgy, task_id=query1, execution_date=20231130T211000, start_date=20231204T223619, end_date=20231204T223624
[2023-12-04T22:36:24.807+0000] {standard_task_runner.py:104} ERROR - Failed to execute job 158 for task query1 (250001: 250001: Could not connect to Snowflake backend after 1 attempt(s).Aborting; 1056)
[2023-12-04T22:36:24.829+0000] {local_task_job_runner.py:228} INFO - Task exited with return code 1
[2023-12-04T22:36:24.845+0000] {taskinstance.py:2776} INFO - 0 downstream tasks scheduled from follow-on schedule check
